Workbook

Sheet Methodology Overview
A1: THE WRR — Teaching Voter Diversity (Entropy) Data Collection
A2: Methodology Reference: WRR 2025 Voter Diversity Indicator — Teaching Pillar
A4: # | B4: Concept | C4: Description | D4: Weight in WRR
A5: 1 | B5: Voter Diversity Indicator | C5: An additional metric applied to institutions with similar vote counts. Institutions with votes coming from a WIDE RANGE of countries/territories and subject areas are deemed to have a more ROBUST reputation than those where votes originate from a narrow base. | D5: 3.33% of Overall WRR (Teaching portion of 10% Diversity weight)
A6: 2 | B6: Entropy (H) | C6: A statistical concept measuring how heterogeneous a dataset is. H = −Σ pᵢ × log(pᵢ), where pᵢ is the proportion of teaching votes from country-subject bucket i. Higher H = more diverse base. | D6: Mathematical foundation
A7: 3 | B7: Country × Subject Bucket | C7: The unit of aggregation — each combination of country/territory and subject area forms a distinct bucket. The distribution of votes across these buckets is what entropy measures. | D7: Granularity unit
A8: 4 | B8: Normalized Diversity Score | C8: Entropy values are passed through a scoring function producing a score between 0 and 100, which is then combined with Vote Counts and Pairwise pillars for the final Teaching Reputation Score. | D8: Final output
A9: 5 | B9: Rationale | C9: For universities with similar numbers of teaching votes, diversity measures answer: which has a more robust global reputation? An institution receiving votes from 30 countries across 15 subjects is considered more reputable than one with 30 votes from a single country/subject. | D9: Methodology rationale
A10: 6 | B10: Teaching vs. Research Diversity | C10: Teaching diversity is computed SEPARATELY from research diversity. Both use the same entropy approach but on different vote pools. Teaching weight = half of research weight (3.33% vs 6.67%). | D10: Pillar separation
A12: Entropy Formula (Reference)
A13: H = − Σᵢ pᵢ × log₂(pᵢ)
A14: where pᵢ = (votes in bucket i) / (total votes for the institution). Maximum entropy occurs when votes are distributed equally across all buckets; minimum (H=0) when all votes come from a single bucket.

Sheet Country List
A1: Country / Territory Reference List (38 WRR 2025 Countries)
A2: Reference list of countries represented in WRR 2025 — used for bucket assignment
A3: # | B3: Country / Territory | C3: ISO Code | D3: Region / Continent | E3: No. of Institutions in WRR
A4: 1 | B4: United States | C4: USA | D4: North America
A5: 2 | B5: United Kingdom | C5: GBR | D5: Europe
A6: 3 | B6: China | C6: CHN | D6: Asia
A7: 4 | B7: Germany | C7: DEU | D7: Europe
A8: 5 | B8: Japan | C8: JPN | D8: Asia
A9: 6 | B9: Australia | C9: AUS | D9: Oceania
A10: 7 | B10: France | C10: FRA | D10: Europe
A11: 8 | B11: Netherlands | C11: NLD | D11: Europe
A12: 9 | B12: Canada | C12: CAN | D12: North America
A13: 10 | B13: South Korea | C13: KOR | D13: Asia
A14: 11 | B14: Switzerland | C14: CHE | D14: Europe
A15: 12 | B15: Sweden | C15: SWE | D15: Europe
... A41: 38 | B41: Argentina | C41: ARG | D41: South America

Sheet Subject Areas
A1: Subject Areas Reference List (THE 11 Subject Groups)
A2: Subject areas used in the Academic Reputation Survey — basis for subject dimension of diversity
A3: # | B3: Subject Area | C3: Disciplines Covered | D3: Short Code
A4: 1 | B4: Arts & Humanities | C4: Archaeology, history, languages, literature, linguistics, philosophy, theology, religious studies, performing arts | D4: AH
A5: 2 | B5: Business & Economics | C5: Accounting, business, economics, econometrics, finance, management | D5: BE
A6: 3 | B6: Clinical & Health | C6: Medicine, dentistry, health sciences, public health, nursing, pharmacy | D6: CH
A7: 4 | B7: Computer Science | C7: Artificial intelligence, cybersecurity, data science, software engineering | D7: CS
A8: 5 | B8: Education | C8: Teaching, education policy, pedagogy, educational psychology | D8: ED
A9: 6 | B9: Engineering | C9: Chemical, civil, electrical, mechanical, general engineering, materials | D9: EN
A10: 7 | B10: Law | C10: Law studies, legal theory, jurisprudence | D10: LW
A11: 8 | B11: Life Sciences | C11: Agriculture, biological sciences, veterinary sciences, sport sciences | D11: LS
A12: 9 | B12: Physical Sciences | C12: Chemistry, physics, astronomy, geology, environmental sciences, mathematics & statistics | D12: PS
A13: 10 | B13: Psychology | C13: Clinical, educational, organizational, cognitive, social psychology | D13: PY
A14: 11 | B14: Social Sciences | C14: Communication, geography, politics & IR, sociology, anthropology | D14: SS

Sheet 1. Raw Votes Log
A1: Raw Teaching Votes Log — Source Data for Diversity Analysis
A2: Each row = one teaching vote cast by one respondent for one institution (max 15 per respondent)
A3: Vote ID | B3: University Name | C3: Respondent ID | D3: Respondent Country | E3: Respondent ISO Code | F3: Respondent Subject Area | G3: Subject Code | H3: Country×Subject Bucket | I3: Self-Vote (Y/N) | J3: Date of Vote
A4: TV-00001 | H4: =IFERROR(IF(AND(E4<>"",G4<>""),E4&"-"&G4,""),"")
A5: TV-00002 | H5: =IFERROR(IF(AND(E5<>"",G5<>""),E5&"-"&G5,""),"")
A6: TV-00003 | H6: =IFERROR(IF(AND(E6<>"",G6<>""),E6&"-"&G6,""),"")
A7: TV-00004 | H7: =IFERROR(IF(AND(E7<>"",G7<>""),E7&"-"&G7,""),"")
A8: TV-00005 | H8: =IFERROR(IF(AND(E8<>"",G8<>""),E8&"-"&G8,""),"")
A9: TV-00006 | H9: =IFERROR(IF(AND(E9<>"",G9<>""),E9&"-"&G9,""),"")
A10: TV-00007 | H10: =IFERROR(IF(AND(E10<>"",G10<>""),E10&"-"&G10,""),"")
A11: TV-00008 | H11: =IFERROR(IF(AND(E11<>"",G11<>""),E11&"-"&G11,""),"")
A12: TV-00009 | H12: =IFERROR(IF(AND(E12<>"",G12<>""),E12&"-"&G12,""),"")
A13: TV-00010 | H13: =IFERROR(IF(AND(E13<>"",G13<>""),E13&"-"&G13,""),"")
A14: TV-00011 | H14: =IFERROR(IF(AND(E14<>"",G14<>""),E14&"-"&G14,""),"")
A15: TV-00012 | H15: =IFERROR(IF(AND(E15<>"",G15<>""),E15&"-"&G15,""),"")
... A203: TV-00200 | H203: =IFERROR(IF(AND(E203<>"",G203<>""),E203&"-"&G203,""),"")

Sheet 2. Univ x Country Matrix
A1: Teaching Votes Distribution: University × Country
A2: Count of teaching votes per university, broken down by respondent country (max 15 shown; extend as needed)
A4: University Name ↓ / Country → | B4: USA | C4: GBR | D4: CHN | E4: DEU | F4: JPN | G4: AUS | H4: FRA | I4: NLD | J4: CAN | K4: KOR | L4: CHE | M4: SWE | N4: ITA | O4: ESP | P4: IND | Q4: Total Votes | R4: Unique Countries
B5: =IFERROR(COUNTIFS('1. Raw Votes Log'!B:B,A5,'1. Raw Votes Log'!E:E,"USA"),0) -> 0 | C5: =IFERROR(COUNTIFS('1. Raw Votes Log'!B:B,A5,'1. Raw Votes Log'!E:E,"GBR"),0) -> 0 | D5: =IFERROR(COUNTIFS('1. Raw Votes Log'!B:B,A5,'1. Raw Votes Log'!E:E,"CHN"),0) -> 0 | E5: =IFERROR(COUNTIFS('1. Raw Votes Log'!B:B,A5,'1. Raw Votes Log'!E:E,"DEU"),0) -> 0 | F5: =IFERROR(COUNTIFS('1. Raw Votes Log'!B:B,A5,'1. Raw Votes Log'!E:E,"JPN"),0) -> 0 | G5: =IFERROR(COUNTIFS('1. Raw Votes Log'!B:B,A5,'1. Raw Votes Log'!E:E,"AUS"),0) -> 0 | H5: =IFERROR(COUNTIFS('1. Raw Votes Log'!B:B,A5,'1. Raw Votes Log'!E:E,"FRA"),0) -> 0 | I5: =IFERROR(COUNTIFS('1. Raw Votes Log'!B:B,A5,'1. Raw Votes Log'!E:E,"NLD"),0) -> 0 | J5: =IFERROR(COUNTIFS('1. Raw Votes Log'!B:B,A5,'1. Raw Votes Log'!E:E,"CAN"),0) -> 0 | K5: =IFERROR(COUNTIFS('1. Raw Votes Log'!B:B,A5,'1. Raw Votes Log'!E:E,"KOR"),0) -> 0 | L5: =IFERROR(COUNTIFS('1. Raw Votes Log'!B:B,A5,'1. Raw Votes Log'!E:E,"CHE"),0) -> 0 | M5: =IFERROR(COUNTIFS('1. Raw Votes Log'!B:B,A5,'1. Raw Votes Log'!E:E,"SWE"),0) -> 0 | N5: =IFERROR(COUNTIFS('1. Raw Votes Log'!B:B,A5,'1. Raw Votes Log'!E:E,"ITA"),0) -> 0 | O5: =IFERROR(COUNTIFS('1. Raw Votes Log'!B:B,A5,'1. Raw Votes Log'!E:E,"ESP"),0) -> 0 | P5: =IFERROR(COUNTIFS('1. Raw Votes Log'!B:B,A5,'1. Raw Votes Log'!E:E,"IND"),0) -> 0 | Q5: =SUM(B5:P5) -> 0 | R5: =COUNTIF(B5:P5,">0") -> 0
B6: =IFERROR(COUNTIFS('1. Raw Votes Log'!B:B,A6,'1. Raw Votes Log'!E:E,"USA"),0) -> 0 | C6: =IFERROR(COUNTIFS('1. Raw Votes Log'!B:B,A6,'1. Raw Votes Log'!E:E,"GBR"),0) -> 0 | D6: =IFERROR(COUNTIFS('1. Raw Votes Log'!B:B,A6,'1. Raw Votes Log'!E:E,"CHN"),0) -> 0 | E6: =IFERROR(COUNTIFS('1. Raw Votes Log'!B:B,A6,'1. Raw Votes Log'!E:E,"DEU"),0) -> 0 | F6: =IFERROR(COUNTIFS('1. Raw Votes Log'!B:B,A6,'1. Raw Votes Log'!E:E,"JPN"),0) -> 0 | G6: =IFERROR(COUNTIFS('1. Raw Votes Log'!B:B,A6,'1. Raw Votes Log'!E:E,"AUS"),0) -> 0 | H6: =IFERROR(COUNTIFS('1. Raw Votes Log'!B:B,A6,'1. Raw Votes Log'!E:E,"FRA"),0) -> 0 | I6: =IFERROR(COUNTIFS('1. Raw Votes Log'!B:B,A6,'1. Raw Votes Log'!E:E,"NLD"),0) -> 0 | J6: =IFERROR(COUNTIFS('1. Raw Votes Log'!B:B,A6,'1. Raw Votes Log'!E:E,"CAN"),0) -> 0 | K6: =IFERROR(COUNTIFS('1. Raw Votes Log'!B:B,A6,'1. Raw Votes Log'!E:E,"KOR"),0) -> 0 | L6: =IFERROR(COUNTIFS('1. Raw Votes Log'!B:B,A6,'1. Raw Votes Log'!E:E,"CHE"),0) -> 0 | M6: =IFERROR(COUNTIFS('1. Raw Votes Log'!B:B,A6,'1. Raw Votes Log'!E:E,"SWE"),0) -> 0 | N6: =IFERROR(COUNTIFS('1. Raw Votes Log'!B:B,A6,'1. Raw Votes Log'!E:E,"ITA"),0) -> 0 | O6: =IFERROR(COUNTIFS('1. Raw Votes Log'!B:B,A6,'1. Raw Votes Log'!E:E,"ESP"),0) -> 0 | P6: =IFERROR(COUNTIFS('1. Raw Votes Log'!B:B,A6,'1. Raw Votes Log'!E:E,"IND"),0) -> 0 | Q6: =SUM(B6:P6) -> 0 | R6: =COUNTIF(B6:P6,">0") -> 0
B7: =IFERROR(COUNTIFS('1. Raw Votes Log'!B:B,A7,'1. Raw Votes Log'!E:E,"USA"),0) -> 0 | C7: =IFERROR(COUNTIFS('1. Raw Votes Log'!B:B,A7,'1. Raw Votes Log'!E:E,"GBR"),0) -> 0 | D7: =IFERROR(COUNTIFS('1. Raw Votes Log'!B:B,A7,'1. Raw Votes Log'!E:E,"CHN"),0) -> 0 | E7: =IFERROR(COUNTIFS('1. Raw Votes Log'!B:B,A7,'1. Raw Votes Log'!E:E,"DEU"),0) -> 0 | F7: =IFERROR(COUNTIFS('1. Raw Votes Log'!B:B,A7,'1. Raw Votes Log'!E:E,"JPN"),0) -> 0 | G7: =IFERROR(COUNTIFS('1. Raw Votes Log'!B:B,A7,'1. Raw Votes Log'!E:E,"AUS"),0) -> 0 | H7: =IFERROR(COUNTIFS('1. Raw Votes Log'!B:B,A7,'1. Raw Votes Log'!E:E,"FRA"),0) -> 0 | I7: =IFERROR(COUNTIFS('1. Raw Votes Log'!B:B,A7,'1. Raw Votes Log'!E:E,"NLD"),0) -> 0 | J7: =IFERROR(COUNTIFS('1. Raw Votes Log'!B:B,A7,'1. Raw Votes Log'!E:E,"CAN"),0) -> 0 | K7: =IFERROR(COUNTIFS('1. Raw Votes Log'!B:B,A7,'1. Raw Votes Log'!E:E,"KOR"),0) -> 0 | L7: =IFERROR(COUNTIFS('1. Raw Votes Log'!B:B,A7,'1. Raw Votes Log'!E:E,"CHE"),0) -> 0 | M7: =IFERROR(COUNTIFS('1. Raw Votes Log'!B:B,A7,'1. Raw Votes Log'!E:E,"SWE"),0) -> 0 | N7: =IFERROR(COUNTIFS('1. Raw Votes Log'!B:B,A7,'1. Raw Votes Log'!E:E,"ITA"),0) -> 0 | O7: =IFERROR(COUNTIFS('1. Raw Votes Log'!B:B,A7,'1. Raw Votes Log'!E:E,"ESP"),0) -> 0 | P7: =IFERROR(COUNTIFS('1. Raw Votes Log'!B:B,A7,'1. Raw Votes Log'!E:E,"IND"),0) -> 0 | Q7: =SUM(B7:P7) -> 0 | R7: =COUNTIF(B7:P7,">0") -> 0
B8: =IFERROR(COUNTIFS('1. Raw Votes Log'!B:B,A8,'1. Raw Votes Log'!E:E,"USA"),0) -> 0 | C8: =IFERROR(COUNTIFS('1. Raw Votes Log'!B:B,A8,'1. Raw Votes Log'!E:E,"GBR"),0) -> 0 | D8: =IFERROR(COUNTIFS('1. Raw Votes Log'!B:B,A8,'1. Raw Votes Log'!E:E,"CHN"),0) -> 0 | E8: =IFERROR(COUNTIFS('1. Raw Votes Log'!B:B,A8,'1. Raw Votes Log'!E:E,"DEU"),0) -> 0 | F8: =IFERROR(COUNTIFS('1. Raw Votes Log'!B:B,A8,'1. Raw Votes Log'!E:E,"JPN"),0) -> 0 | G8: =IFERROR(COUNTIFS('1. Raw Votes Log'!B:B,A8,'1. Raw Votes Log'!E:E,"AUS"),0) -> 0 | H8: =IFERROR(COUNTIFS('1. Raw Votes Log'!B:B,A8,'1. Raw Votes Log'!E:E,"FRA"),0) -> 0 | I8: =IFERROR(COUNTIFS('1. Raw Votes Log'!B:B,A8,'1. Raw Votes Log'!E:E,"NLD"),0) -> 0 | J8: =IFERROR(COUNTIFS('1. Raw Votes Log'!B:B,A8,'1. Raw Votes Log'!E:E,"CAN"),0) -> 0 | K8: =IFERROR(COUNTIFS('1. Raw Votes Log'!B:B,A8,'1. Raw Votes Log'!E:E,"KOR"),0) -> 0 | L8: =IFERROR(COUNTIFS('1. Raw Votes Log'!B:B,A8,'1. Raw Votes Log'!E:E,"CHE"),0) -> 0 | M8: =IFERROR(COUNTIFS('1. Raw Votes Log'!B:B,A8,'1. Raw Votes Log'!E:E,"SWE"),0) -> 0 | N8: =IFERROR(COUNTIFS('1. Raw Votes Log'!B:B,A8,'1. Raw Votes Log'!E:E,"ITA"),0) -> 0 | O8: =IFERROR(COUNTIFS('1. Raw Votes Log'!B:B,A8,'1. Raw Votes Log'!E:E,"ESP"),0) -> 0 | P8: =IFERROR(COUNTIFS('1. Raw Votes Log'!B:B,A8,'1. Raw Votes Log'!E:E,"IND"),0) -> 0 | Q8: =SUM(B8:P8) -> 0 | R8: =COUNTIF(B8:P8,">0") -> 0
B9: =IFERROR(COUNTIFS('1. Raw Votes Log'!B:B,A9,'1. Raw Votes Log'!E:E,"USA"),0) -> 0 | C9: =IFERROR(COUNTIFS('1. Raw Votes Log'!B:B,A9,'1. Raw Votes Log'!E:E,"GBR"),0) -> 0 | D9: =IFERROR(COUNTIFS('1. Raw Votes Log'!B:B,A9,'1. Raw Votes Log'!E:E,"CHN"),0) -> 0 | E9: =IFERROR(COUNTIFS('1. Raw Votes Log'!B:B,A9,'1. Raw Votes Log'!E:E,"DEU"),0) -> 0 | F9: =IFERROR(COUNTIFS('1. Raw Votes Log'!B:B,A9,'1. Raw Votes Log'!E:E,"JPN"),0) -> 0 | G9: =IFERROR(COUNTIFS('1. Raw Votes Log'!B:B,A9,'1. Raw Votes Log'!E:E,"AUS"),0) -> 0 | H9: =IFERROR(COUNTIFS('1. Raw Votes Log'!B:B,A9,'1. Raw Votes Log'!E:E,"FRA"),0) -> 0 | I9: =IFERROR(COUNTIFS('1. Raw Votes Log'!B:B,A9,'1. Raw Votes Log'!E:E,"NLD"),0) -> 0 | J9: =IFERROR(COUNTIFS('1. Raw Votes Log'!B:B,A9,'1. Raw Votes Log'!E:E,"CAN"),0) -> 0 | K9: =IFERROR(COUNTIFS('1. Raw Votes Log'!B:B,A9,'1. Raw Votes Log'!E:E,"KOR"),0) -> 0 | L9: =IFERROR(COUNTIFS('1. Raw Votes Log'!B:B,A9,'1. Raw Votes Log'!E:E,"CHE"),0) -> 0 | M9: =IFERROR(COUNTIFS('1. Raw Votes Log'!B:B,A9,'1. Raw Votes Log'!E:E,"SWE"),0) -> 0 | N9: =IFERROR(COUNTIFS('1. Raw Votes Log'!B:B,A9,'1. Raw Votes Log'!E:E,"ITA"),0) -> 0 | O9: =IFERROR(COUNTIFS('1. Raw Votes Log'!B:B,A9,'1. Raw Votes Log'!E:E,"ESP"),0) -> 0 | P9: =IFERROR(COUNTIFS('1. Raw Votes Log'!B:B,A9,'1. Raw Votes Log'!E:E,"IND"),0) -> 0 | Q9: =SUM(B9:P9) -> 0 | R9: =COUNTIF(B9:P9,">0") -> 0
B10: =IFERROR(COUNTIFS('1. Raw Votes Log'!B:B,A10,'1. Raw Votes Log'!E:E,"USA"),0) -> 0 | C10: =IFERROR(COUNTIFS('1. Raw Votes Log'!B:B,A10,'1. Raw Votes Log'!E:E,"GBR"),0) -> 0 | D10: =IFERROR(COUNTIFS('1. Raw Votes Log'!B:B,A10,'1. Raw Votes Log'!E:E,"CHN"),0) -> 0 | E10: =IFERROR(COUNTIFS('1. Raw Votes Log'!B:B,A10,'1. Raw Votes Log'!E:E,"DEU"),0) -> 0 | F10: =IFERROR(COUNTIFS('1. Raw Votes Log'!B:B,A10,'1. Raw Votes Log'!E:E,"JPN"),0) -> 0 | G10: =IFERROR(COUNTIFS('1. Raw Votes Log'!B:B,A10,'1. Raw Votes Log'!E:E,"AUS"),0) -> 0 | H10: =IFERROR(COUNTIFS('1. Raw Votes Log'!B:B,A10,'1. Raw Votes Log'!E:E,"FRA"),0) -> 0 | I10: =IFERROR(COUNTIFS('1. Raw Votes Log'!B:B,A10,'1. Raw Votes Log'!E:E,"NLD"),0) -> 0 | J10: =IFERROR(COUNTIFS('1. Raw Votes Log'!B:B,A10,'1. Raw Votes Log'!E:E,"CAN"),0) -> 0 | K10: =IFERROR(COUNTIFS('1. Raw Votes Log'!B:B,A10,'1. Raw Votes Log'!E:E,"KOR"),0) -> 0 | L10: =IFERROR(COUNTIFS('1. Raw Votes Log'!B:B,A10,'1. Raw Votes Log'!E:E,"CHE"),0) -> 0 | M10: =IFERROR(COUNTIFS('1. Raw Votes Log'!B:B,A10,'1. Raw Votes Log'!E:E,"SWE"),0) -> 0 | N10: =IFERROR(COUNTIFS('1. Raw Votes Log'!B:B,A10,'1. Raw Votes Log'!E:E,"ITA"),0) -> 0 | O10: =IFERROR(COUNTIFS('1. Raw Votes Log'!B:B,A10,'1. Raw Votes Log'!E:E,"ESP"),0) -> 0 | P10: =IFERROR(COUNTIFS('1. Raw Votes Log'!B:B,A10,'1. Raw Votes Log'!E:E,"IND"),0) -> 0 | Q10: =SUM(B10:P10) -> 0 | R10: =COUNTIF(B10:P10,">0") -> 0
B11: =IFERROR(COUNTIFS('1. Raw Votes Log'!B:B,A11,'1. Raw Votes Log'!E:E,"USA"),0) -> 0 | C11: =IFERROR(COUNTIFS('1. Raw Votes Log'!B:B,A11,'1. Raw Votes Log'!E:E,"GBR"),0) -> 0 | D11: =IFERROR(COUNTIFS('1. Raw Votes Log'!B:B,A11,'1. Raw Votes Log'!E:E,"CHN"),0) -> 0 | E11: =IFERROR(COUNTIFS('1. Raw Votes Log'!B:B,A11,'1. Raw Votes Log'!E:E,"DEU"),0) -> 0 | F11: =IFERROR(COUNTIFS('1. Raw Votes Log'!B:B,A11,'1. Raw Votes Log'!E:E,"JPN"),0) -> 0 | G11: =IFERROR(COUNTIFS('1. Raw Votes Log'!B:B,A11,'1. Raw Votes Log'!E:E,"AUS"),0) -> 0 | H11: =IFERROR(COUNTIFS('1. Raw Votes Log'!B:B,A11,'1. Raw Votes Log'!E:E,"FRA"),0) -> 0 | I11: =IFERROR(COUNTIFS('1. Raw Votes Log'!B:B,A11,'1. Raw Votes Log'!E:E,"NLD"),0) -> 0 | J11: =IFERROR(COUNTIFS('1. Raw Votes Log'!B:B,A11,'1. Raw Votes Log'!E:E,"CAN"),0) -> 0 | K11: =IFERROR(COUNTIFS('1. Raw Votes Log'!B:B,A11,'1. Raw Votes Log'!E:E,"KOR"),0) -> 0 | L11: =IFERROR(COUNTIFS('1. Raw Votes Log'!B:B,A11,'1. Raw Votes Log'!E:E,"CHE"),0) -> 0 | M11: =IFERROR(COUNTIFS('1. Raw Votes Log'!B:B,A11,'1. Raw Votes Log'!E:E,"SWE"),0) -> 0 | N11: =IFERROR(COUNTIFS('1. Raw Votes Log'!B:B,A11,'1. Raw Votes Log'!E:E,"ITA"),0) -> 0 | O11: =IFERROR(COUNTIFS('1. Raw Votes Log'!B:B,A11,'1. Raw Votes Log'!E:E,"ESP"),0) -> 0 | P11: =IFERROR(COUNTIFS('1. Raw Votes Log'!B:B,A11,'1. Raw Votes Log'!E:E,"IND"),0) -> 0 | Q11: =SUM(B11:P11) -> 0 | R11: =COUNTIF(B11:P11,">0") -> 0
B12: =IFERROR(COUNTIFS('1. Raw Votes Log'!B:B,A12,'1. Raw Votes Log'!E:E,"USA"),0) -> 0 | C12: =IFERROR(COUNTIFS('1. Raw Votes Log'!B:B,A12,'1. Raw Votes Log'!E:E,"GBR"),0) -> 0 | D12: =IFERROR(COUNTIFS('1. Raw Votes Log'!B:B,A12,'1. Raw Votes Log'!E:E,"CHN"),0) -> 0 | E12: =IFERROR(COUNTIFS('1. Raw Votes Log'!B:B,A12,'1. Raw Votes Log'!E:E,"DEU"),0) -> 0 | F12: =IFERROR(COUNTIFS('1. Raw Votes Log'!B:B,A12,'1. Raw Votes Log'!E:E,"JPN"),0) -> 0 | G12: =IFERROR(COUNTIFS('1. Raw Votes Log'!B:B,A12,'1. Raw Votes Log'!E:E,"AUS"),0) -> 0 | H12: =IFERROR(COUNTIFS('1. Raw Votes Log'!B:B,A12,'1. Raw Votes Log'!E:E,"FRA"),0) -> 0 | I12: =IFERROR(COUNTIFS('1. Raw Votes Log'!B:B,A12,'1. Raw Votes Log'!E:E,"NLD"),0) -> 0 | J12: =IFERROR(COUNTIFS('1. Raw Votes Log'!B:B,A12,'1. Raw Votes Log'!E:E,"CAN"),0) -> 0 | K12: =IFERROR(COUNTIFS('1. Raw Votes Log'!B:B,A12,'1. Raw Votes Log'!E:E,"KOR"),0) -> 0 | L12: =IFERROR(COUNTIFS('1. Raw Votes Log'!B:B,A12,'1. Raw Votes Log'!E:E,"CHE"),0) -> 0 | M12: =IFERROR(COUNTIFS('1. Raw Votes Log'!B:B,A12,'1. Raw Votes Log'!E:E,"SWE"),0) -> 0 | N12: =IFERROR(COUNTIFS('1. Raw Votes Log'!B:B,A12,'1. Raw Votes Log'!E:E,"ITA"),0) -> 0 | O12: =IFERROR(COUNTIFS('1. Raw Votes Log'!B:B,A12,'1. Raw Votes Log'!E:E,"ESP"),0) -> 0 | P12: =IFERROR(COUNTIFS('1. Raw Votes Log'!B:B,A12,'1. Raw Votes Log'!E:E,"IND"),0) -> 0 | Q12: =SUM(B12:P12) -> 0 | R12: =COUNTIF(B12:P12,">0") -> 0
B13: =IFERROR(COUNTIFS('1. Raw Votes Log'!B:B,A13,'1. Raw Votes Log'!E:E,"USA"),0) -> 0 | C13: =IFERROR(COUNTIFS('1. Raw Votes Log'!B:B,A13,'1. Raw Votes Log'!E:E,"GBR"),0) -> 0 | D13: =IFERROR(COUNTIFS('1. Raw Votes Log'!B:B,A13,'1. Raw Votes Log'!E:E,"CHN"),0) -> 0 | E13: =IFERROR(COUNTIFS('1. Raw Votes Log'!B:B,A13,'1. Raw Votes Log'!E:E,"DEU"),0) -> 0 | F13: =IFERROR(COUNTIFS('1. Raw Votes Log'!B:B,A13,'1. Raw Votes Log'!E:E,"JPN"),0) -> 0 | G13: =IFERROR(COUNTIFS('1. Raw Votes Log'!B:B,A13,'1. Raw Votes Log'!E:E,"AUS"),0) -> 0 | H13: =IFERROR(COUNTIFS('1. Raw Votes Log'!B:B,A13,'1. Raw Votes Log'!E:E,"FRA"),0) -> 0 | I13: =IFERROR(COUNTIFS('1. Raw Votes Log'!B:B,A13,'1. Raw Votes Log'!E:E,"NLD"),0) -> 0 | J13: =IFERROR(COUNTIFS('1. Raw Votes Log'!B:B,A13,'1. Raw Votes Log'!E:E,"CAN"),0) -> 0 | K13: =IFERROR(COUNTIFS('1. Raw Votes Log'!B:B,A13,'1. Raw Votes Log'!E:E,"KOR"),0) -> 0 | L13: =IFERROR(COUNTIFS('1. Raw Votes Log'!B:B,A13,'1. Raw Votes Log'!E:E,"CHE"),0) -> 0 | M13: =IFERROR(COUNTIFS('1. Raw Votes Log'!B:B,A13,'1. Raw Votes Log'!E:E,"SWE"),0) -> 0 | N13: =IFERROR(COUNTIFS('1. Raw Votes Log'!B:B,A13,'1. Raw Votes Log'!E:E,"ITA"),0) -> 0 | O13: =IFERROR(COUNTIFS('1. Raw Votes Log'!B:B,A13,'1. Raw Votes Log'!E:E,"ESP"),0) -> 0 | P13: =IFERROR(COUNTIFS('1. Raw Votes Log'!B:B,A13,'1. Raw Votes Log'!E:E,"IND"),0) -> 0 | Q13: =SUM(B13:P13) -> 0 | R13: =COUNTIF(B13:P13,">0") -> 0
B14: =IFERROR(COUNTIFS('1. Raw Votes Log'!B:B,A14,'1. Raw Votes Log'!E:E,"USA"),0) -> 0 | C14: =IFERROR(COUNTIFS('1. Raw Votes Log'!B:B,A14,'1. Raw Votes Log'!E:E,"GBR"),0) -> 0 | D14: =IFERROR(COUNTIFS('1. Raw Votes Log'!B:B,A14,'1. Raw Votes Log'!E:E,"CHN"),0) -> 0 | E14: =IFERROR(COUNTIFS('1. Raw Votes Log'!B:B,A14,'1. Raw Votes Log'!E:E,"DEU"),0) -> 0 | F14: =IFERROR(COUNTIFS('1. Raw Votes Log'!B:B,A14,'1. Raw Votes Log'!E:E,"JPN"),0) -> 0 | G14: =IFERROR(COUNTIFS('1. Raw Votes Log'!B:B,A14,'1. Raw Votes Log'!E:E,"AUS"),0) -> 0 | H14: =IFERROR(COUNTIFS('1. Raw Votes Log'!B:B,A14,'1. Raw Votes Log'!E:E,"FRA"),0) -> 0 | I14: =IFERROR(COUNTIFS('1. Raw Votes Log'!B:B,A14,'1. Raw Votes Log'!E:E,"NLD"),0) -> 0 | J14: =IFERROR(COUNTIFS('1. Raw Votes Log'!B:B,A14,'1. Raw Votes Log'!E:E,"CAN"),0) -> 0 | K14: =IFERROR(COUNTIFS('1. Raw Votes Log'!B:B,A14,'1. Raw Votes Log'!E:E,"KOR"),0) -> 0 | L14: =IFERROR(COUNTIFS('1. Raw Votes Log'!B:B,A14,'1. Raw Votes Log'!E:E,"CHE"),0) -> 0 | M14: =IFERROR(COUNTIFS('1. Raw Votes Log'!B:B,A14,'1. Raw Votes Log'!E:E,"SWE"),0) -> 0 | N14: =IFERROR(COUNTIFS('1. Raw Votes Log'!B:B,A14,'1. Raw Votes Log'!E:E,"ITA"),0) -> 0 | O14: =IFERROR(COUNTIFS('1. Raw Votes Log'!B:B,A14,'1. Raw Votes Log'!E:E,"ESP"),0) -> 0 | P14: =IFERROR(COUNTIFS('1. Raw Votes Log'!B:B,A14,'1. Raw Votes Log'!E:E,"IND"),0) -> 0 | Q14: =SUM(B14:P14) -> 0 | R14: =COUNTIF(B14:P14,">0") -> 0
B15: =IFERROR(COUNTIFS('1. Raw Votes Log'!B:B,A15,'1. Raw Votes Log'!E:E,"USA"),0) -> 0 | C15: =IFERROR(COUNTIFS('1. Raw Votes Log'!B:B,A15,'1. Raw Votes Log'!E:E,"GBR"),0) -> 0 | D15: =IFERROR(COUNTIFS('1. Raw Votes Log'!B:B,A15,'1. Raw Votes Log'!E:E,"CHN"),0) -> 0 | E15: =IFERROR(COUNTIFS('1. Raw Votes Log'!B:B,A15,'1. Raw Votes Log'!E:E,"DEU"),0) -> 0 | F15: =IFERROR(COUNTIFS('1. Raw Votes Log'!B:B,A15,'1. Raw Votes Log'!E:E,"JPN"),0) -> 0 | G15: =IFERROR(COUNTIFS('1. Raw Votes Log'!B:B,A15,'1. Raw Votes Log'!E:E,"AUS"),0) -> 0 | H15: =IFERROR(COUNTIFS('1. Raw Votes Log'!B:B,A15,'1. Raw Votes Log'!E:E,"FRA"),0) -> 0 | I15: =IFERROR(COUNTIFS('1. Raw Votes Log'!B:B,A15,'1. Raw Votes Log'!E:E,"NLD"),0) -> 0 | J15: =IFERROR(COUNTIFS('1. Raw Votes Log'!B:B,A15,'1. Raw Votes Log'!E:E,"CAN"),0) -> 0 | K15: =IFERROR(COUNTIFS('1. Raw Votes Log'!B:B,A15,'1. Raw Votes Log'!E:E,"KOR"),0) -> 0 | L15: =IFERROR(COUNTIFS('1. Raw Votes Log'!B:B,A15,'1. Raw Votes Log'!E:E,"CHE"),0) -> 0 | M15: =IFERROR(COUNTIFS('1. Raw Votes Log'!B:B,A15,'1. Raw Votes Log'!E:E,"SWE"),0) -> 0 | N15: =IFERROR(COUNTIFS('1. Raw Votes Log'!B:B,A15,'1. Raw Votes Log'!E:E,"ITA"),0) -> 0 | O15: =IFERROR(COUNTIFS('1. Raw Votes Log'!B:B,A15,'1. Raw Votes Log'!E:E,"ESP"),0) -> 0 | P15: =IFERROR(COUNTIFS('1. Raw Votes Log'!B:B,A15,'1. Raw Votes Log'!E:E,"IND"),0) -> 0 | Q15: =SUM(B15:P15) -> 0 | R15: =COUNTIF(B15:P15,">0") -> 0
B16: =IFERROR(COUNTIFS('1. Raw Votes Log'!B:B,A16,'1. Raw Votes Log'!E:E,"USA"),0) -> 0 | C16: =IFERROR(COUNTIFS('1. Raw Votes Log'!B:B,A16,'1. Raw Votes Log'!E:E,"GBR"),0) -> 0 | D16: =IFERROR(COUNTIFS('1. Raw Votes Log'!B:B,A16,'1. Raw Votes Log'!E:E,"CHN"),0) -> 0 | E16: =IFERROR(COUNTIFS('1. Raw Votes Log'!B:B,A16,'1. Raw Votes Log'!E:E,"DEU"),0) -> 0 | F16: =IFERROR(COUNTIFS('1. Raw Votes Log'!B:B,A16,'1. Raw Votes Log'!E:E,"JPN"),0) -> 0 | G16: =IFERROR(COUNTIFS('1. Raw Votes Log'!B:B,A16,'1. Raw Votes Log'!E:E,"AUS"),0) -> 0 | H16: =IFERROR(COUNTIFS('1. Raw Votes Log'!B:B,A16,'1. Raw Votes Log'!E:E,"FRA"),0) -> 0 | I16: =IFERROR(COUNTIFS('1. Raw Votes Log'!B:B,A16,'1. Raw Votes Log'!E:E,"NLD"),0) -> 0 | J16: =IFERROR(COUNTIFS('1. Raw Votes Log'!B:B,A16,'1. Raw Votes Log'!E:E,"CAN"),0) -> 0 | K16: =IFERROR(COUNTIFS('1. Raw Votes Log'!B:B,A16,'1. Raw Votes Log'!E:E,"KOR"),0) -> 0 | L16: =IFERROR(COUNTIFS('1. Raw Votes Log'!B:B,A16,'1. Raw Votes Log'!E:E,"CHE"),0) -> 0 | M16: =IFERROR(COUNTIFS('1. Raw Votes Log'!B:B,A16,'1. Raw Votes Log'!E:E,"SWE"),0) -> 0 | N16: =IFERROR(COUNTIFS('1. Raw Votes Log'!B:B,A16,'1. Raw Votes Log'!E:E,"ITA"),0) -> 0 | O16: =IFERROR(COUNTIFS('1. Raw Votes Log'!B:B,A16,'1. Raw Votes Log'!E:E,"ESP"),0) -> 0 | P16: =IFERROR(COUNTIFS('1. Raw Votes Log'!B:B,A16,'1. Raw Votes Log'!E:E,"IND"),0) -> 0 | Q16: =SUM(B16:P16) -> 0 | R16: =COUNTIF(B16:P16,">0") -> 0
... B34: =IFERROR(COUNTIFS('1. Raw Votes Log'!B:B,A34,'1. Raw Votes Log'!E:E,"USA"),0) -> 0 | C34: =IFERROR(COUNTIFS('1. Raw Votes Log'!B:B,A34,'1. Raw Votes Log'!E:E,"GBR"),0) -> 0 | D34: =IFERROR(COUNTIFS('1. Raw Votes Log'!B:B,A34,'1. Raw Votes Log'!E:E,"CHN"),0) -> 0 | E34: =IFERROR(COUNTIFS('1. Raw Votes Log'!B:B,A34,'1. Raw Votes Log'!E:E,"DEU"),0) -> 0 | F34: =IFERROR(COUNTIFS('1. Raw Votes Log'!B:B,A34,'1. Raw Votes Log'!E:E,"JPN"),0) -> 0 | G34: =IFERROR(COUNTIFS('1. Raw Votes Log'!B:B,A34,'1. Raw Votes Log'!E:E,"AUS"),0) -> 0 | H34: =IFERROR(COUNTIFS('1. Raw Votes Log'!B:B,A34,'1. Raw Votes Log'!E:E,"FRA"),0) -> 0 | I34: =IFERROR(COUNTIFS('1. Raw Votes Log'!B:B,A34,'1. Raw Votes Log'!E:E,"NLD"),0) -> 0 | J34: =IFERROR(COUNTIFS('1. Raw Votes Log'!B:B,A34,'1. Raw Votes Log'!E:E,"CAN"),0) -> 0 | K34: =IFERROR(COUNTIFS('1. Raw Votes Log'!B:B,A34,'1. Raw Votes Log'!E:E,"KOR"),0) -> 0 | L34: =IFERROR(COUNTIFS('1. Raw Votes Log'!B:B,A34,'1. Raw Votes Log'!E:E,"CHE"),0) -> 0 | M34: =IFERROR(COUNTIFS('1. Raw Votes Log'!B:B,A34,'1. Raw Votes Log'!E:E,"SWE"),0) -> 0 | N34: =IFERROR(COUNTIFS('1. Raw Votes Log'!B:B,A34,'1. Raw Votes Log'!E:E,"ITA"),0) -> 0 | O34: =IFERROR(COUNTIFS('1. Raw Votes Log'!B:B,A34,'1. Raw Votes Log'!E:E,"ESP"),0) -> 0 | P34: =IFERROR(COUNTIFS('1. Raw Votes Log'!B:B,A34,'1. Raw Votes Log'!E:E,"IND"),0) -> 0 | Q34: =SUM(B34:P34) -> 0 | R34: =COUNTIF(B34:P34,">0") -> 0

Sheet 3. Univ x Subject Matrix
A1: Teaching Votes Distribution: University × Subject Area
A2: Count of teaching votes per university, broken down by respondent subject area (11 THE subject groups)
A4: University Name ↓ / Subject → | B4: AH | C4: BE | D4: CH | E4: CS | F4: ED | G4: EN | H4: LW | I4: LS | J4: PS | K4: PY | L4: SS | M4: Total Votes | N4: Unique Subjects
B5: =IFERROR(COUNTIFS('1. Raw Votes Log'!B:B,A5,'1. Raw Votes Log'!G:G,"AH"),0) -> 0 | C5: =IFERROR(COUNTIFS('1. Raw Votes Log'!B:B,A5,'1. Raw Votes Log'!G:G,"BE"),0) -> 0 | D5: =IFERROR(COUNTIFS('1. Raw Votes Log'!B:B,A5,'1. Raw Votes Log'!G:G,"CH"),0) -> 0 | E5: =IFERROR(COUNTIFS('1. Raw Votes Log'!B:B,A5,'1. Raw Votes Log'!G:G,"CS"),0) -> 0 | F5: =IFERROR(COUNTIFS('1. Raw Votes Log'!B:B,A5,'1. Raw Votes Log'!G:G,"ED"),0) -> 0 | G5: =IFERROR(COUNTIFS('1. Raw Votes Log'!B:B,A5,'1. Raw Votes Log'!G:G,"EN"),0) -> 0 | H5: =IFERROR(COUNTIFS('1. Raw Votes Log'!B:B,A5,'1. Raw Votes Log'!G:G,"LW"),0) -> 0 | I5: =IFERROR(COUNTIFS('1. Raw Votes Log'!B:B,A5,'1. Raw Votes Log'!G:G,"LS"),0) -> 0 | J5: =IFERROR(COUNTIFS('1. Raw Votes Log'!B:B,A5,'1. Raw Votes Log'!G:G,"PS"),0) -> 0 | K5: =IFERROR(COUNTIFS('1. Raw Votes Log'!B:B,A5,'1. Raw Votes Log'!G:G,"PY"),0) -> 0 | L5: =IFERROR(COUNTIFS('1. Raw Votes Log'!B:B,A5,'1. Raw Votes Log'!G:G,"SS"),0) -> 0 | M5: =SUM(B5:L5) -> 0 | N5: =COUNTIF(B5:L5,">0") -> 0
B6: =IFERROR(COUNTIFS('1. Raw Votes Log'!B:B,A6,'1. Raw Votes Log'!G:G,"AH"),0) -> 0 | C6: =IFERROR(COUNTIFS('1. Raw Votes Log'!B:B,A6,'1. Raw Votes Log'!G:G,"BE"),0) -> 0 | D6: =IFERROR(COUNTIFS('1. Raw Votes Log'!B:B,A6,'1. Raw Votes Log'!G:G,"CH"),0) -> 0 | E6: =IFERROR(COUNTIFS('1. Raw Votes Log'!B:B,A6,'1. Raw Votes Log'!G:G,"CS"),0) -> 0 | F6: =IFERROR(COUNTIFS('1. Raw Votes Log'!B:B,A6,'1. Raw Votes Log'!G:G,"ED"),0) -> 0 | G6: =IFERROR(COUNTIFS('1. Raw Votes Log'!B:B,A6,'1. Raw Votes Log'!G:G,"EN"),0) -> 0 | H6: =IFERROR(COUNTIFS('1. Raw Votes Log'!B:B,A6,'1. Raw Votes Log'!G:G,"LW"),0) -> 0 | I6: =IFERROR(COUNTIFS('1. Raw Votes Log'!B:B,A6,'1. Raw Votes Log'!G:G,"LS"),0) -> 0 | J6: =IFERROR(COUNTIFS('1. Raw Votes Log'!B:B,A6,'1. Raw Votes Log'!G:G,"PS"),0) -> 0 | K6: =IFERROR(COUNTIFS('1. Raw Votes Log'!B:B,A6,'1. Raw Votes Log'!G:G,"PY"),0) -> 0 | L6: =IFERROR(COUNTIFS('1. Raw Votes Log'!B:B,A6,'1. Raw Votes Log'!G:G,"SS"),0) -> 0 | M6: =SUM(B6:L6) -> 0 | N6: =COUNTIF(B6:L6,">0") -> 0
B7: =IFERROR(COUNTIFS('1. Raw Votes Log'!B:B,A7,'1. Raw Votes Log'!G:G,"AH"),0) -> 0 | C7: =IFERROR(COUNTIFS('1. Raw Votes Log'!B:B,A7,'1. Raw Votes Log'!G:G,"BE"),0) -> 0 | D7: =IFERROR(COUNTIFS('1. Raw Votes Log'!B:B,A7,'1. Raw Votes Log'!G:G,"CH"),0) -> 0 | E7: =IFERROR(COUNTIFS('1. Raw Votes Log'!B:B,A7,'1. Raw Votes Log'!G:G,"CS"),0) -> 0 | F7: =IFERROR(COUNTIFS('1. Raw Votes Log'!B:B,A7,'1. Raw Votes Log'!G:G,"ED"),0) -> 0 | G7: =IFERROR(COUNTIFS('1. Raw Votes Log'!B:B,A7,'1. Raw Votes Log'!G:G,"EN"),0) -> 0 | H7: =IFERROR(COUNTIFS('1. Raw Votes Log'!B:B,A7,'1. Raw Votes Log'!G:G,"LW"),0) -> 0 | I7: =IFERROR(COUNTIFS('1. Raw Votes Log'!B:B,A7,'1. Raw Votes Log'!G:G,"LS"),0) -> 0 | J7: =IFERROR(COUNTIFS('1. Raw Votes Log'!B:B,A7,'1. Raw Votes Log'!G:G,"PS"),0) -> 0 | K7: =IFERROR(COUNTIFS('1. Raw Votes Log'!B:B,A7,'1. Raw Votes Log'!G:G,"PY"),0) -> 0 | L7: =IFERROR(COUNTIFS('1. Raw Votes Log'!B:B,A7,'1. Raw Votes Log'!G:G,"SS"),0) -> 0 | M7: =SUM(B7:L7) -> 0 | N7: =COUNTIF(B7:L7,">0") -> 0
B8: =IFERROR(COUNTIFS('1. Raw Votes Log'!B:B,A8,'1. Raw Votes Log'!G:G,"AH"),0) -> 0 | C8: =IFERROR(COUNTIFS('1. Raw Votes Log'!B:B,A8,'1. Raw Votes Log'!G:G,"BE"),0) -> 0 | D8: =IFERROR(COUNTIFS('1. Raw Votes Log'!B:B,A8,'1. Raw Votes Log'!G:G,"CH"),0) -> 0 | E8: =IFERROR(COUNTIFS('1. Raw Votes Log'!B:B,A8,'1. Raw Votes Log'!G:G,"CS"),0) -> 0 | F8: =IFERROR(COUNTIFS('1. Raw Votes Log'!B:B,A8,'1. Raw Votes Log'!G:G,"ED"),0) -> 0 | G8: =IFERROR(COUNTIFS('1. Raw Votes Log'!B:B,A8,'1. Raw Votes Log'!G:G,"EN"),0) -> 0 | H8: =IFERROR(COUNTIFS('1. Raw Votes Log'!B:B,A8,'1. Raw Votes Log'!G:G,"LW"),0) -> 0 | I8: =IFERROR(COUNTIFS('1. Raw Votes Log'!B:B,A8,'1. Raw Votes Log'!G:G,"LS"),0) -> 0 | J8: =IFERROR(COUNTIFS('1. Raw Votes Log'!B:B,A8,'1. Raw Votes Log'!G:G,"PS"),0) -> 0 | K8: =IFERROR(COUNTIFS('1. Raw Votes Log'!B:B,A8,'1. Raw Votes Log'!G:G,"PY"),0) -> 0 | L8: =IFERROR(COUNTIFS('1. Raw Votes Log'!B:B,A8,'1. Raw Votes Log'!G:G,"SS"),0) -> 0 | M8: =SUM(B8:L8) -> 0 | N8: =COUNTIF(B8:L8,">0") -> 0
B9: =IFERROR(COUNTIFS('1. Raw Votes Log'!B:B,A9,'1. Raw Votes Log'!G:G,"AH"),0) -> 0 | C9: =IFERROR(COUNTIFS('1. Raw Votes Log'!B:B,A9,'1. Raw Votes Log'!G:G,"BE"),0) -> 0 | D9: =IFERROR(COUNTIFS('1. Raw Votes Log'!B:B,A9,'1. Raw Votes Log'!G:G,"CH"),0) -> 0 | E9: =IFERROR(COUNTIFS('1. Raw Votes Log'!B:B,A9,'1. Raw Votes Log'!G:G,"CS"),0) -> 0 | F9: =IFERROR(COUNTIFS('1. Raw Votes Log'!B:B,A9,'1. Raw Votes Log'!G:G,"ED"),0) -> 0 | G9: =IFERROR(COUNTIFS('1. Raw Votes Log'!B:B,A9,'1. Raw Votes Log'!G:G,"EN"),0) -> 0 | H9: =IFERROR(COUNTIFS('1. Raw Votes Log'!B:B,A9,'1. Raw Votes Log'!G:G,"LW"),0) -> 0 | I9: =IFERROR(COUNTIFS('1. Raw Votes Log'!B:B,A9,'1. Raw Votes Log'!G:G,"LS"),0) -> 0 | J9: =IFERROR(COUNTIFS('1. Raw Votes Log'!B:B,A9,'1. Raw Votes Log'!G:G,"PS"),0) -> 0 | K9: =IFERROR(COUNTIFS('1. Raw Votes Log'!B:B,A9,'1. Raw Votes Log'!G:G,"PY"),0) -> 0 | L9: =IFERROR(COUNTIFS('1. Raw Votes Log'!B:B,A9,'1. Raw Votes Log'!G:G,"SS"),0) -> 0 | M9: =SUM(B9:L9) -> 0 | N9: =COUNTIF(B9:L9,">0") -> 0
B10: =IFERROR(COUNTIFS('1. Raw Votes Log'!B:B,A10,'1. Raw Votes Log'!G:G,"AH"),0) -> 0 | C10: =IFERROR(COUNTIFS('1. Raw Votes Log'!B:B,A10,'1. Raw Votes Log'!G:G,"BE"),0) -> 0 | D10: =IFERROR(COUNTIFS('1. Raw Votes Log'!B:B,A10,'1. Raw Votes Log'!G:G,"CH"),0) -> 0 | E10: =IFERROR(COUNTIFS('1. Raw Votes Log'!B:B,A10,'1. Raw Votes Log'!G:G,"CS"),0) -> 0 | F10: =IFERROR(COUNTIFS('1. Raw Votes Log'!B:B,A10,'1. Raw Votes Log'!G:G,"ED"),0) -> 0 | G10: =IFERROR(COUNTIFS('1. Raw Votes Log'!B:B,A10,'1. Raw Votes Log'!G:G,"EN"),0) -> 0 | H10: =IFERROR(COUNTIFS('1. Raw Votes Log'!B:B,A10,'1. Raw Votes Log'!G:G,"LW"),0) -> 0 | I10: =IFERROR(COUNTIFS('1. Raw Votes Log'!B:B,A10,'1. Raw Votes Log'!G:G,"LS"),0) -> 0 | J10: =IFERROR(COUNTIFS('1. Raw Votes Log'!B:B,A10,'1. Raw Votes Log'!G:G,"PS"),0) -> 0 | K10: =IFERROR(COUNTIFS('1. Raw Votes Log'!B:B,A10,'1. Raw Votes Log'!G:G,"PY"),0) -> 0 | L10: =IFERROR(COUNTIFS('1. Raw Votes Log'!B:B,A10,'1. Raw Votes Log'!G:G,"SS"),0) -> 0 | M10: =SUM(B10:L10) -> 0 | N10: =COUNTIF(B10:L10,">0") -> 0
B11: =IFERROR(COUNTIFS('1. Raw Votes Log'!B:B,A11,'1. Raw Votes Log'!G:G,"AH"),0) -> 0 | C11: =IFERROR(COUNTIFS('1. Raw Votes Log'!B:B,A11,'1. Raw Votes Log'!G:G,"BE"),0) -> 0 | D11: =IFERROR(COUNTIFS('1. Raw Votes Log'!B:B,A11,'1. Raw Votes Log'!G:G,"CH"),0) -> 0 | E11: =IFERROR(COUNTIFS('1. Raw Votes Log'!B:B,A11,'1. Raw Votes Log'!G:G,"CS"),0) -> 0 | F11: =IFERROR(COUNTIFS('1. Raw Votes Log'!B:B,A11,'1. Raw Votes Log'!G:G,"ED"),0) -> 0 | G11: =IFERROR(COUNTIFS('1. Raw Votes Log'!B:B,A11,'1. Raw Votes Log'!G:G,"EN"),0) -> 0 | H11: =IFERROR(COUNTIFS('1. Raw Votes Log'!B:B,A11,'1. Raw Votes Log'!G:G,"LW"),0) -> 0 | I11: =IFERROR(COUNTIFS('1. Raw Votes Log'!B:B,A11,'1. Raw Votes Log'!G:G,"LS"),0) -> 0 | J11: =IFERROR(COUNTIFS('1. Raw Votes Log'!B:B,A11,'1. Raw Votes Log'!G:G,"PS"),0) -> 0 | K11: =IFERROR(COUNTIFS('1. Raw Votes Log'!B:B,A11,'1. Raw Votes Log'!G:G,"PY"),0) -> 0 | L11: =IFERROR(COUNTIFS('1. Raw Votes Log'!B:B,A11,'1. Raw Votes Log'!G:G,"SS"),0) -> 0 | M11: =SUM(B11:L11) -> 0 | N11: =COUNTIF(B11:L11,">0") -> 0
B12: =IFERROR(COUNTIFS('1. Raw Votes Log'!B:B,A12,'1. Raw Votes Log'!G:G,"AH"),0) -> 0 | C12: =IFERROR(COUNTIFS('1. Raw Votes Log'!B:B,A12,'1. Raw Votes Log'!G:G,"BE"),0) -> 0 | D12: =IFERROR(COUNTIFS('1. Raw Votes Log'!B:B,A12,'1. Raw Votes Log'!G:G,"CH"),0) -> 0 | E12: =IFERROR(COUNTIFS('1. Raw Votes Log'!B:B,A12,'1. Raw Votes Log'!G:G,"CS"),0) -> 0 | F12: =IFERROR(COUNTIFS('1. Raw Votes Log'!B:B,A12,'1. Raw Votes Log'!G:G,"ED"),0) -> 0 | G12: =IFERROR(COUNTIFS('1. Raw Votes Log'!B:B,A12,'1. Raw Votes Log'!G:G,"EN"),0) -> 0 | H12: =IFERROR(COUNTIFS('1. Raw Votes Log'!B:B,A12,'1. Raw Votes Log'!G:G,"LW"),0) -> 0 | I12: =IFERROR(COUNTIFS('1. Raw Votes Log'!B:B,A12,'1. Raw Votes Log'!G:G,"LS"),0) -> 0 | J12: =IFERROR(COUNTIFS('1. Raw Votes Log'!B:B,A12,'1. Raw Votes Log'!G:G,"PS"),0) -> 0 | K12: =IFERROR(COUNTIFS('1. Raw Votes Log'!B:B,A12,'1. Raw Votes Log'!G:G,"PY"),0) -> 0 | L12: =IFERROR(COUNTIFS('1. Raw Votes Log'!B:B,A12,'1. Raw Votes Log'!G:G,"SS"),0) -> 0 | M12: =SUM(B12:L12) -> 0 | N12: =COUNTIF(B12:L12,">0") -> 0
B13: =IFERROR(COUNTIFS('1. Raw Votes Log'!B:B,A13,'1. Raw Votes Log'!G:G,"AH"),0) -> 0 | C13: =IFERROR(COUNTIFS('1. Raw Votes Log'!B:B,A13,'1. Raw Votes Log'!G:G,"BE"),0) -> 0 | D13: =IFERROR(COUNTIFS('1. Raw Votes Log'!B:B,A13,'1. Raw Votes Log'!G:G,"CH"),0) -> 0 | E13: =IFERROR(COUNTIFS('1. Raw Votes Log'!B:B,A13,'1. Raw Votes Log'!G:G,"CS"),0) -> 0 | F13: =IFERROR(COUNTIFS('1. Raw Votes Log'!B:B,A13,'1. Raw Votes Log'!G:G,"ED"),0) -> 0 | G13: =IFERROR(COUNTIFS('1. Raw Votes Log'!B:B,A13,'1. Raw Votes Log'!G:G,"EN"),0) -> 0 | H13: =IFERROR(COUNTIFS('1. Raw Votes Log'!B:B,A13,'1. Raw Votes Log'!G:G,"LW"),0) -> 0 | I13: =IFERROR(COUNTIFS('1. Raw Votes Log'!B:B,A13,'1. Raw Votes Log'!G:G,"LS"),0) -> 0 | J13: =IFERROR(COUNTIFS('1. Raw Votes Log'!B:B,A13,'1. Raw Votes Log'!G:G,"PS"),0) -> 0 | K13: =IFERROR(COUNTIFS('1. Raw Votes Log'!B:B,A13,'1. Raw Votes Log'!G:G,"PY"),0) -> 0 | L13: =IFERROR(COUNTIFS('1. Raw Votes Log'!B:B,A13,'1. Raw Votes Log'!G:G,"SS"),0) -> 0 | M13: =SUM(B13:L13) -> 0 | N13: =COUNTIF(B13:L13,">0") -> 0
B14: =IFERROR(COUNTIFS('1. Raw Votes Log'!B:B,A14,'1. Raw Votes Log'!G:G,"AH"),0) -> 0 | C14: =IFERROR(COUNTIFS('1. Raw Votes Log'!B:B,A14,'1. Raw Votes Log'!G:G,"BE"),0) -> 0 | D14: =IFERROR(COUNTIFS('1. Raw Votes Log'!B:B,A14,'1. Raw Votes Log'!G:G,"CH"),0) -> 0 | E14: =IFERROR(COUNTIFS('1. Raw Votes Log'!B:B,A14,'1. Raw Votes Log'!G:G,"CS"),0) -> 0 | F14: =IFERROR(COUNTIFS('1. Raw Votes Log'!B:B,A14,'1. Raw Votes Log'!G:G,"ED"),0) -> 0 | G14: =IFERROR(COUNTIFS('1. Raw Votes Log'!B:B,A14,'1. Raw Votes Log'!G:G,"EN"),0) -> 0 | H14: =IFERROR(COUNTIFS('1. Raw Votes Log'!B:B,A14,'1. Raw Votes Log'!G:G,"LW"),0) -> 0 | I14: =IFERROR(COUNTIFS('1. Raw Votes Log'!B:B,A14,'1. Raw Votes Log'!G:G,"LS"),0) -> 0 | J14: =IFERROR(COUNTIFS('1. Raw Votes Log'!B:B,A14,'1. Raw Votes Log'!G:G,"PS"),0) -> 0 | K14: =IFERROR(COUNTIFS('1. Raw Votes Log'!B:B,A14,'1. Raw Votes Log'!G:G,"PY"),0) -> 0 | L14: =IFERROR(COUNTIFS('1. Raw Votes Log'!B:B,A14,'1. Raw Votes Log'!G:G,"SS"),0) -> 0 | M14: =SUM(B14:L14) -> 0 | N14: =COUNTIF(B14:L14,">0") -> 0
B15: =IFERROR(COUNTIFS('1. Raw Votes Log'!B:B,A15,'1. Raw Votes Log'!G:G,"AH"),0) -> 0 | C15: =IFERROR(COUNTIFS('1. Raw Votes Log'!B:B,A15,'1. Raw Votes Log'!G:G,"BE"),0) -> 0 | D15: =IFERROR(COUNTIFS('1. Raw Votes Log'!B:B,A15,'1. Raw Votes Log'!G:G,"CH"),0) -> 0 | E15: =IFERROR(COUNTIFS('1. Raw Votes Log'!B:B,A15,'1. Raw Votes Log'!G:G,"CS"),0) -> 0 | F15: =IFERROR(COUNTIFS('1. Raw Votes Log'!B:B,A15,'1. Raw Votes Log'!G:G,"ED"),0) -> 0 | G15: =IFERROR(COUNTIFS('1. Raw Votes Log'!B:B,A15,'1. Raw Votes Log'!G:G,"EN"),0) -> 0 | H15: =IFERROR(COUNTIFS('1. Raw Votes Log'!B:B,A15,'1. Raw Votes Log'!G:G,"LW"),0) -> 0 | I15: =IFERROR(COUNTIFS('1. Raw Votes Log'!B:B,A15,'1. Raw Votes Log'!G:G,"LS"),0) -> 0 | J15: =IFERROR(COUNTIFS('1. Raw Votes Log'!B:B,A15,'1. Raw Votes Log'!G:G,"PS"),0) -> 0 | K15: =IFERROR(COUNTIFS('1. Raw Votes Log'!B:B,A15,'1. Raw Votes Log'!G:G,"PY"),0) -> 0 | L15: =IFERROR(COUNTIFS('1. Raw Votes Log'!B:B,A15,'1. Raw Votes Log'!G:G,"SS"),0) -> 0 | M15: =SUM(B15:L15) -> 0 | N15: =COUNTIF(B15:L15,">0") -> 0
B16: =IFERROR(COUNTIFS('1. Raw Votes Log'!B:B,A16,'1. Raw Votes Log'!G:G,"AH"),0) -> 0 | C16: =IFERROR(COUNTIFS('1. Raw Votes Log'!B:B,A16,'1. Raw Votes Log'!G:G,"BE"),0) -> 0 | D16: =IFERROR(COUNTIFS('1. Raw Votes Log'!B:B,A16,'1. Raw Votes Log'!G:G,"CH"),0) -> 0 | E16: =IFERROR(COUNTIFS('1. Raw Votes Log'!B:B,A16,'1. Raw Votes Log'!G:G,"CS"),0) -> 0 | F16: =IFERROR(COUNTIFS('1. Raw Votes Log'!B:B,A16,'1. Raw Votes Log'!G:G,"ED"),0) -> 0 | G16: =IFERROR(COUNTIFS('1. Raw Votes Log'!B:B,A16,'1. Raw Votes Log'!G:G,"EN"),0) -> 0 | H16: =IFERROR(COUNTIFS('1. Raw Votes Log'!B:B,A16,'1. Raw Votes Log'!G:G,"LW"),0) -> 0 | I16: =IFERROR(COUNTIFS('1. Raw Votes Log'!B:B,A16,'1. Raw Votes Log'!G:G,"LS"),0) -> 0 | J16: =IFERROR(COUNTIFS('1. Raw Votes Log'!B:B,A16,'1. Raw Votes Log'!G:G,"PS"),0) -> 0 | K16: =IFERROR(COUNTIFS('1. Raw Votes Log'!B:B,A16,'1. Raw Votes Log'!G:G,"PY"),0) -> 0 | L16: =IFERROR(COUNTIFS('1. Raw Votes Log'!B:B,A16,'1. Raw Votes Log'!G:G,"SS"),0) -> 0 | M16: =SUM(B16:L16) -> 0 | N16: =COUNTIF(B16:L16,">0") -> 0
... B34: =IFERROR(COUNTIFS('1. Raw Votes Log'!B:B,A34,'1. Raw Votes Log'!G:G,"AH"),0) -> 0 | C34: =IFERROR(COUNTIFS('1. Raw Votes Log'!B:B,A34,'1. Raw Votes Log'!G:G,"BE"),0) -> 0 | D34: =IFERROR(COUNTIFS('1. Raw Votes Log'!B:B,A34,'1. Raw Votes Log'!G:G,"CH"),0) -> 0 | E34: =IFERROR(COUNTIFS('1. Raw Votes Log'!B:B,A34,'1. Raw Votes Log'!G:G,"CS"),0) -> 0 | F34: =IFERROR(COUNTIFS('1. Raw Votes Log'!B:B,A34,'1. Raw Votes Log'!G:G,"ED"),0) -> 0 | G34: =IFERROR(COUNTIFS('1. Raw Votes Log'!B:B,A34,'1. Raw Votes Log'!G:G,"EN"),0) -> 0 | H34: =IFERROR(COUNTIFS('1. Raw Votes Log'!B:B,A34,'1. Raw Votes Log'!G:G,"LW"),0) -> 0 | I34: =IFERROR(COUNTIFS('1. Raw Votes Log'!B:B,A34,'1. Raw Votes Log'!G:G,"LS"),0) -> 0 | J34: =IFERROR(COUNTIFS('1. Raw Votes Log'!B:B,A34,'1. Raw Votes Log'!G:G,"PS"),0) -> 0 | K34: =IFERROR(COUNTIFS('1. Raw Votes Log'!B:B,A34,'1. Raw Votes Log'!G:G,"PY"),0) -> 0 | L34: =IFERROR(COUNTIFS('1. Raw Votes Log'!B:B,A34,'1. Raw Votes Log'!G:G,"SS"),0) -> 0 | M34: =SUM(B34:L34) -> 0 | N34: =COUNTIF(B34:L34,">0") -> 0

Sheet 4. CountrySubject Buckets
A1: Country × Subject Bucket Counts (per University)
A2: Detailed breakdown: bucket-level teaching vote counts for entropy calculation
A3: S.No. | B3: University Name | C3: Country (ISO) | D3: Subject Code | E3: Bucket ID (Country-Subject) | F3: Vote Count in Bucket | G3: % of University's Total Votes
A4: 1 | E4: =IF(AND(C4<>"",D4<>""),C4&"-"&D4,"") | F4: =IFERROR(COUNTIFS('1. Raw Votes Log'!B:B,B4,'1. Raw Votes Log'!E:E,C4,'1. Raw Votes Log'!G:G,D4),0) -> 0 | G4: =IFERROR(F4/COUNTIF('1. Raw Votes Log'!B:B,B4)*100,0) -> 0
A5: 2 | E5: =IF(AND(C5<>"",D5<>""),C5&"-"&D5,"") | F5: =IFERROR(COUNTIFS('1. Raw Votes Log'!B:B,B5,'1. Raw Votes Log'!E:E,C5,'1. Raw Votes Log'!G:G,D5),0) -> 0 | G5: =IFERROR(F5/COUNTIF('1. Raw Votes Log'!B:B,B5)*100,0) -> 0
A6: 3 | E6: =IF(AND(C6<>"",D6<>""),C6&"-"&D6,"") | F6: =IFERROR(COUNTIFS('1. Raw Votes Log'!B:B,B6,'1. Raw Votes Log'!E:E,C6,'1. Raw Votes Log'!G:G,D6),0) -> 0 | G6: =IFERROR(F6/COUNTIF('1. Raw Votes Log'!B:B,B6)*100,0) -> 0
A7: 4 | E7: =IF(AND(C7<>"",D7<>""),C7&"-"&D7,"") | F7: =IFERROR(COUNTIFS('1. Raw Votes Log'!B:B,B7,'1. Raw Votes Log'!E:E,C7,'1. Raw Votes Log'!G:G,D7),0) -> 0 | G7: =IFERROR(F7/COUNTIF('1. Raw Votes Log'!B:B,B7)*100,0) -> 0
A8: 5 | E8: =IF(AND(C8<>"",D8<>""),C8&"-"&D8,"") | F8: =IFERROR(COUNTIFS('1. Raw Votes Log'!B:B,B8,'1. Raw Votes Log'!E:E,C8,'1. Raw Votes Log'!G:G,D8),0) -> 0 | G8: =IFERROR(F8/COUNTIF('1. Raw Votes Log'!B:B,B8)*100,0) -> 0
A9: 6 | E9: =IF(AND(C9<>"",D9<>""),C9&"-"&D9,"") | F9: =IFERROR(COUNTIFS('1. Raw Votes Log'!B:B,B9,'1. Raw Votes Log'!E:E,C9,'1. Raw Votes Log'!G:G,D9),0) -> 0 | G9: =IFERROR(F9/COUNTIF('1. Raw Votes Log'!B:B,B9)*100,0) -> 0
A10: 7 | E10: =IF(AND(C10<>"",D10<>""),C10&"-"&D10,"") | F10: =IFERROR(COUNTIFS('1. Raw Votes Log'!B:B,B10,'1. Raw Votes Log'!E:E,C10,'1. Raw Votes Log'!G:G,D10),0) -> 0 | G10: =IFERROR(F10/COUNTIF('1. Raw Votes Log'!B:B,B10)*100,0) -> 0
A11: 8 | E11: =IF(AND(C11<>"",D11<>""),C11&"-"&D11,"") | F11: =IFERROR(COUNTIFS('1. Raw Votes Log'!B:B,B11,'1. Raw Votes Log'!E:E,C11,'1. Raw Votes Log'!G:G,D11),0) -> 0 | G11: =IFERROR(F11/COUNTIF('1. Raw Votes Log'!B:B,B11)*100,0) -> 0
A12: 9 | E12: =IF(AND(C12<>"",D12<>""),C12&"-"&D12,"") | F12: =IFERROR(COUNTIFS('1. Raw Votes Log'!B:B,B12,'1. Raw Votes Log'!E:E,C12,'1. Raw Votes Log'!G:G,D12),0) -> 0 | G12: =IFERROR(F12/COUNTIF('1. Raw Votes Log'!B:B,B12)*100,0) -> 0
A13: 10 | E13: =IF(AND(C13<>"",D13<>""),C13&"-"&D13,"") | F13: =IFERROR(COUNTIFS('1. Raw Votes Log'!B:B,B13,'1. Raw Votes Log'!E:E,C13,'1. Raw Votes Log'!G:G,D13),0) -> 0 | G13: =IFERROR(F13/COUNTIF('1. Raw Votes Log'!B:B,B13)*100,0) -> 0
A14: 11 | E14: =IF(AND(C14<>"",D14<>""),C14&"-"&D14,"") | F14: =IFERROR(COUNTIFS('1. Raw Votes Log'!B:B,B14,'1. Raw Votes Log'!E:E,C14,'1. Raw Votes Log'!G:G,D14),0) -> 0 | G14: =IFERROR(F14/COUNTIF('1. Raw Votes Log'!B:B,B14)*100,0) -> 0
A15: 12 | E15: =IF(AND(C15<>"",D15<>""),C15&"-"&D15,"") | F15: =IFERROR(COUNTIFS('1. Raw Votes Log'!B:B,B15,'1. Raw Votes Log'!E:E,C15,'1. Raw Votes Log'!G:G,D15),0) -> 0 | G15: =IFERROR(F15/COUNTIF('1. Raw Votes Log'!B:B,B15)*100,0) -> 0
... A153: 150 | E153: =IF(AND(C153<>"",D153<>""),C153&"-"&D153,"") | F153: =IFERROR(COUNTIFS('1. Raw Votes Log'!B:B,B153,'1. Raw Votes Log'!E:E,C153,'1. Raw Votes Log'!G:G,D153),0) -> 0 | G153: =IFERROR(F153/COUNTIF('1. Raw Votes Log'!B:B,B153)*100,0) -> 0

Sheet 5. Entropy Calculation
A1: Entropy Calculation — Teaching Voter Diversity
A2: H = −Σ pᵢ × log₂(pᵢ) | Higher H = more diverse base. Max H occurs when votes spread equally across all buckets.
A3: S.No. | B3: University Name | C3: Total Votes | D3: Unique Countries | E3: Unique Subjects | F3: Unique Country×Subject Buckets | G3: Entropy H (bits) | H3: Max Possible Entropy (log₂ N) | I3: Normalized Entropy (H/Hmax) | J3: Diversity Score (0–100)
A4: 1 | C4: =IFERROR(COUNTIF('1. Raw Votes Log'!B:B,B4),0) -> 0 | D4: =IFERROR(SUMPRODUCT(('1. Raw Votes Log'!B$4:B$203=B4)/COUNTIFS('1. Raw Votes Log'!B$4:B$203,B4&"",'1. Raw Votes Log'!E$4:E$203,'1. Raw Votes Log'!E$4:E$203&"")),0) -> 1 | E4: =IFERROR(SUMPRODUCT(('1. Raw Votes Log'!B$4:B$203=B4)/COUNTIFS('1. Raw Votes Log'!B$4:B$203,B4&"",'1. Raw Votes Log'!G$4:G$203,'1. Raw Votes Log'!G$4:G$203&"")),0) -> 1 | F4: =IFERROR(SUMPRODUCT(('1. Raw Votes Log'!B$4:B$203=B4)/COUNTIFS('1. Raw Votes Log'!B$4:B$203,B4&"",'1. Raw Votes Log'!H$4:H$203,'1. Raw Votes Log'!H$4:H$203&"")),0) -> 1 | G4: =IFERROR(VLOOKUP(B4,'6. Entropy Helper'!$A$4:$C$33,3,FALSE()),0) -> 0 | H4: =IF(F4>1,LOG(F4,2),0) -> 0 | I4: =IFERROR(IF(H4>0,G4/H4,0),0) -> 0 | J4: =IFERROR(IF(MAX($G$4:$G$33)>0,G4/MAX($G$4:$G$33)*100,0),0) -> 0
A5: 2 | C5: =IFERROR(COUNTIF('1. Raw Votes Log'!B:B,B5),0) -> 0 | D5: =IFERROR(SUMPRODUCT(('1. Raw Votes Log'!B$4:B$203=B5)/COUNTIFS('1. Raw Votes Log'!B$4:B$203,B5&"",'1. Raw Votes Log'!E$4:E$203,'1. Raw Votes Log'!E$4:E$203&"")),0) -> 1 | E5: =IFERROR(SUMPRODUCT(('1. Raw Votes Log'!B$4:B$203=B5)/COUNTIFS('1. Raw Votes Log'!B$4:B$203,B5&"",'1. Raw Votes Log'!G$4:G$203,'1. Raw Votes Log'!G$4:G$203&"")),0) -> 1 | F5: =IFERROR(SUMPRODUCT(('1. Raw Votes Log'!B$4:B$203=B5)/COUNTIFS('1. Raw Votes Log'!B$4:B$203,B5&"",'1. Raw Votes Log'!H$4:H$203,'1. Raw Votes Log'!H$4:H$203&"")),0) -> 1 | G5: =IFERROR(VLOOKUP(B5,'6. Entropy Helper'!$A$4:$C$33,3,FALSE()),0) -> 0 | H5: =IF(F5>1,LOG(F5,2),0) -> 0 | I5: =IFERROR(IF(H5>0,G5/H5,0),0) -> 0 | J5: =IFERROR(IF(MAX($G$4:$G$33)>0,G5/MAX($G$4:$G$33)*100,0),0) -> 0
A6: 3 | C6: =IFERROR(COUNTIF('1. Raw Votes Log'!B:B,B6),0) -> 0 | D6: =IFERROR(SUMPRODUCT(('1. Raw Votes Log'!B$4:B$203=B6)/COUNTIFS('1. Raw Votes Log'!B$4:B$203,B6&"",'1. Raw Votes Log'!E$4:E$203,'1. Raw Votes Log'!E$4:E$203&"")),0) -> 1 | E6: =IFERROR(SUMPRODUCT(('1. Raw Votes Log'!B$4:B$203=B6)/COUNTIFS('1. Raw Votes Log'!B$4:B$203,B6&"",'1. Raw Votes Log'!G$4:G$203,'1. Raw Votes Log'!G$4:G$203&"")),0) -> 1 | F6: =IFERROR(SUMPRODUCT(('1. Raw Votes Log'!B$4:B$203=B6)/COUNTIFS('1. Raw Votes Log'!B$4:B$203,B6&"",'1. Raw Votes Log'!H$4:H$203,'1. Raw Votes Log'!H$4:H$203&"")),0) -> 1 | G6: =IFERROR(VLOOKUP(B6,'6. Entropy Helper'!$A$4:$C$33,3,FALSE()),0) -> 0 | H6: =IF(F6>1,LOG(F6,2),0) -> 0 | I6: =IFERROR(IF(H6>0,G6/H6,0),0) -> 0 | J6: =IFERROR(IF(MAX($G$4:$G$33)>0,G6/MAX($G$4:$G$33)*100,0),0) -> 0
A7: 4 | C7: =IFERROR(COUNTIF('1. Raw Votes Log'!B:B,B7),0) -> 0 | D7: =IFERROR(SUMPRODUCT(('1. Raw Votes Log'!B$4:B$203=B7)/COUNTIFS('1. Raw Votes Log'!B$4:B$203,B7&"",'1. Raw Votes Log'!E$4:E$203,'1. Raw Votes Log'!E$4:E$203&"")),0) -> 1 | E7: =IFERROR(SUMPRODUCT(('1. Raw Votes Log'!B$4:B$203=B7)/COUNTIFS('1. Raw Votes Log'!B$4:B$203,B7&"",'1. Raw Votes Log'!G$4:G$203,'1. Raw Votes Log'!G$4:G$203&"")),0) -> 1 | F7: =IFERROR(SUMPRODUCT(('1. Raw Votes Log'!B$4:B$203=B7)/COUNTIFS('1. Raw Votes Log'!B$4:B$203,B7&"",'1. Raw Votes Log'!H$4:H$203,'1. Raw Votes Log'!H$4:H$203&"")),0) -> 1 | G7: =IFERROR(VLOOKUP(B7,'6. Entropy Helper'!$A$4:$C$33,3,FALSE()),0) -> 0 | H7: =IF(F7>1,LOG(F7,2),0) -> 0 | I7: =IFERROR(IF(H7>0,G7/H7,0),0) -> 0 | J7: =IFERROR(IF(MAX($G$4:$G$33)>0,G7/MAX($G$4:$G$33)*100,0),0) -> 0
A8: 5 | C8: =IFERROR(COUNTIF('1. Raw Votes Log'!B:B,B8),0) -> 0 | D8: =IFERROR(SUMPRODUCT(('1. Raw Votes Log'!B$4:B$203=B8)/COUNTIFS('1. Raw Votes Log'!B$4:B$203,B8&"",'1. Raw Votes Log'!E$4:E$203,'1. Raw Votes Log'!E$4:E$203&"")),0) -> 1 | E8: =IFERROR(SUMPRODUCT(('1. Raw Votes Log'!B$4:B$203=B8)/COUNTIFS('1. Raw Votes Log'!B$4:B$203,B8&"",'1. Raw Votes Log'!G$4:G$203,'1. Raw Votes Log'!G$4:G$203&"")),0) -> 1 | F8: =IFERROR(SUMPRODUCT(('1. Raw Votes Log'!B$4:B$203=B8)/COUNTIFS('1. Raw Votes Log'!B$4:B$203,B8&"",'1. Raw Votes Log'!H$4:H$203,'1. Raw Votes Log'!H$4:H$203&"")),0) -> 1 | G8: =IFERROR(VLOOKUP(B8,'6. Entropy Helper'!$A$4:$C$33,3,FALSE()),0) -> 0 | H8: =IF(F8>1,LOG(F8,2),0) -> 0 | I8: =IFERROR(IF(H8>0,G8/H8,0),0) -> 0 | J8: =IFERROR(IF(MAX($G$4:$G$33)>0,G8/MAX($G$4:$G$33)*100,0),0) -> 0
A9: 6 | C9: =IFERROR(COUNTIF('1. Raw Votes Log'!B:B,B9),0) -> 0 | D9: =IFERROR(SUMPRODUCT(('1. Raw Votes Log'!B$4:B$203=B9)/COUNTIFS('1. Raw Votes Log'!B$4:B$203,B9&"",'1. Raw Votes Log'!E$4:E$203,'1. Raw Votes Log'!E$4:E$203&"")),0) -> 1 | E9: =IFERROR(SUMPRODUCT(('1. Raw Votes Log'!B$4:B$203=B9)/COUNTIFS('1. Raw Votes Log'!B$4:B$203,B9&"",'1. Raw Votes Log'!G$4:G$203,'1. Raw Votes Log'!G$4:G$203&"")),0) -> 1 | F9: =IFERROR(SUMPRODUCT(('1. Raw Votes Log'!B$4:B$203=B9)/COUNTIFS('1. Raw Votes Log'!B$4:B$203,B9&"",'1. Raw Votes Log'!H$4:H$203,'1. Raw Votes Log'!H$4:H$203&"")),0) -> 1 | G9: =IFERROR(VLOOKUP(B9,'6. Entropy Helper'!$A$4:$C$33,3,FALSE()),0) -> 0 | H9: =IF(F9>1,LOG(F9,2),0) -> 0 | I9: =IFERROR(IF(H9>0,G9/H9,0),0) -> 0 | J9: =IFERROR(IF(MAX($G$4:$G$33)>0,G9/MAX($G$4:$G$33)*100,0),0) -> 0
A10: 7 | C10: =IFERROR(COUNTIF('1. Raw Votes Log'!B:B,B10),0) -> 0 | D10: =IFERROR(SUMPRODUCT(('1. Raw Votes Log'!B$4:B$203=B10)/COUNTIFS('1. Raw Votes Log'!B$4:B$203,B10&"",'1. Raw Votes Log'!E$4:E$203,'1. Raw Votes Log'!E$4:E$203&"")),0) -> 1 | E10: =IFERROR(SUMPRODUCT(('1. Raw Votes Log'!B$4:B$203=B10)/COUNTIFS('1. Raw Votes Log'!B$4:B$203,B10&"",'1. Raw Votes Log'!G$4:G$203,'1. Raw Votes Log'!G$4:G$203&"")),0) -> 1 | F10: =IFERROR(SUMPRODUCT(('1. Raw Votes Log'!B$4:B$203=B10)/COUNTIFS('1. Raw Votes Log'!B$4:B$203,B10&"",'1. Raw Votes Log'!H$4:H$203,'1. Raw Votes Log'!H$4:H$203&"")),0) -> 1 | G10: =IFERROR(VLOOKUP(B10,'6. Entropy Helper'!$A$4:$C$33,3,FALSE()),0) -> 0 | H10: =IF(F10>1,LOG(F10,2),0) -> 0 | I10: =IFERROR(IF(H10>0,G10/H10,0),0) -> 0 | J10: =IFERROR(IF(MAX($G$4:$G$33)>0,G10/MAX($G$4:$G$33)*100,0),0) -> 0
A11: 8 | C11: =IFERROR(COUNTIF('1. Raw Votes Log'!B:B,B11),0) -> 0 | D11: =IFERROR(SUMPRODUCT(('1. Raw Votes Log'!B$4:B$203=B11)/COUNTIFS('1. Raw Votes Log'!B$4:B$203,B11&"",'1. Raw Votes Log'!E$4:E$203,'1. Raw Votes Log'!E$4:E$203&"")),0) -> 1 | E11: =IFERROR(SUMPRODUCT(('1. Raw Votes Log'!B$4:B$203=B11)/COUNTIFS('1. Raw Votes Log'!B$4:B$203,B11&"",'1. Raw Votes Log'!G$4:G$203,'1. Raw Votes Log'!G$4:G$203&"")),0) -> 1 | F11: =IFERROR(SUMPRODUCT(('1. Raw Votes Log'!B$4:B$203=B11)/COUNTIFS('1. Raw Votes Log'!B$4:B$203,B11&"",'1. Raw Votes Log'!H$4:H$203,'1. Raw Votes Log'!H$4:H$203&"")),0) -> 1 | G11: =IFERROR(VLOOKUP(B11,'6. Entropy Helper'!$A$4:$C$33,3,FALSE()),0) -> 0 | H11: =IF(F11>1,LOG(F11,2),0) -> 0 | I11: =IFERROR(IF(H11>0,G11/H11,0),0) -> 0 | J11: =IFERROR(IF(MAX($G$4:$G$33)>0,G11/MAX($G$4:$G$33)*100,0),0) -> 0
A12: 9 | C12: =IFERROR(COUNTIF('1. Raw Votes Log'!B:B,B12),0) -> 0 | D12: =IFERROR(SUMPRODUCT(('1. Raw Votes Log'!B$4:B$203=B12)/COUNTIFS('1. Raw Votes Log'!B$4:B$203,B12&"",'1. Raw Votes Log'!E$4:E$203,'1. Raw Votes Log'!E$4:E$203&"")),0) -> 1 | E12: =IFERROR(SUMPRODUCT(('1. Raw Votes Log'!B$4:B$203=B12)/COUNTIFS('1. Raw Votes Log'!B$4:B$203,B12&"",'1. Raw Votes Log'!G$4:G$203,'1. Raw Votes Log'!G$4:G$203&"")),0) -> 1 | F12: =IFERROR(SUMPRODUCT(('1. Raw Votes Log'!B$4:B$203=B12)/COUNTIFS('1. Raw Votes Log'!B$4:B$203,B12&"",'1. Raw Votes Log'!H$4:H$203,'1. Raw Votes Log'!H$4:H$203&"")),0) -> 1 | G12: =IFERROR(VLOOKUP(B12,'6. Entropy Helper'!$A$4:$C$33,3,FALSE()),0) -> 0 | H12: =IF(F12>1,LOG(F12,2),0) -> 0 | I12: =IFERROR(IF(H12>0,G12/H12,0),0) -> 0 | J12: =IFERROR(IF(MAX($G$4:$G$33)>0,G12/MAX($G$4:$G$33)*100,0),0) -> 0
A13: 10 | C13: =IFERROR(COUNTIF('1. Raw Votes Log'!B:B,B13),0) -> 0 | D13: =IFERROR(SUMPRODUCT(('1. Raw Votes Log'!B$4:B$203=B13)/COUNTIFS('1. Raw Votes Log'!B$4:B$203,B13&"",'1. Raw Votes Log'!E$4:E$203,'1. Raw Votes Log'!E$4:E$203&"")),0) -> 1 | E13: =IFERROR(SUMPRODUCT(('1. Raw Votes Log'!B$4:B$203=B13)/COUNTIFS('1. Raw Votes Log'!B$4:B$203,B13&"",'1. Raw Votes Log'!G$4:G$203,'1. Raw Votes Log'!G$4:G$203&"")),0) -> 1 | F13: =IFERROR(SUMPRODUCT(('1. Raw Votes Log'!B$4:B$203=B13)/COUNTIFS('1. Raw Votes Log'!B$4:B$203,B13&"",'1. Raw Votes Log'!H$4:H$203,'1. Raw Votes Log'!H$4:H$203&"")),0) -> 1 | G13: =IFERROR(VLOOKUP(B13,'6. Entropy Helper'!$A$4:$C$33,3,FALSE()),0) -> 0 | H13: =IF(F13>1,LOG(F13,2),0) -> 0 | I13: =IFERROR(IF(H13>0,G13/H13,0),0) -> 0 | J13: =IFERROR(IF(MAX($G$4:$G$33)>0,G13/MAX($G$4:$G$33)*100,0),0) -> 0
A14: 11 | C14: =IFERROR(COUNTIF('1. Raw Votes Log'!B:B,B14),0) -> 0 | D14: =IFERROR(SUMPRODUCT(('1. Raw Votes Log'!B$4:B$203=B14)/COUNTIFS('1. Raw Votes Log'!B$4:B$203,B14&"",'1. Raw Votes Log'!E$4:E$203,'1. Raw Votes Log'!E$4:E$203&"")),0) -> 1 | E14: =IFERROR(SUMPRODUCT(('1. Raw Votes Log'!B$4:B$203=B14)/COUNTIFS('1. Raw Votes Log'!B$4:B$203,B14&"",'1. Raw Votes Log'!G$4:G$203,'1. Raw Votes Log'!G$4:G$203&"")),0) -> 1 | F14: =IFERROR(SUMPRODUCT(('1. Raw Votes Log'!B$4:B$203=B14)/COUNTIFS('1. Raw Votes Log'!B$4:B$203,B14&"",'1. Raw Votes Log'!H$4:H$203,'1. Raw Votes Log'!H$4:H$203&"")),0) -> 1 | G14: =IFERROR(VLOOKUP(B14,'6. Entropy Helper'!$A$4:$C$33,3,FALSE()),0) -> 0 | H14: =IF(F14>1,LOG(F14,2),0) -> 0 | I14: =IFERROR(IF(H14>0,G14/H14,0),0) -> 0 | J14: =IFERROR(IF(MAX($G$4:$G$33)>0,G14/MAX($G$4:$G$33)*100,0),0) -> 0
A15: 12 | C15: =IFERROR(COUNTIF('1. Raw Votes Log'!B:B,B15),0) -> 0 | D15: =IFERROR(SUMPRODUCT(('1. Raw Votes Log'!B$4:B$203=B15)/COUNTIFS('1. Raw Votes Log'!B$4:B$203,B15&"",'1. Raw Votes Log'!E$4:E$203,'1. Raw Votes Log'!E$4:E$203&"")),0) -> 1 | E15: =IFERROR(SUMPRODUCT(('1. Raw Votes Log'!B$4:B$203=B15)/COUNTIFS('1. Raw Votes Log'!B$4:B$203,B15&"",'1. Raw Votes Log'!G$4:G$203,'1. Raw Votes Log'!G$4:G$203&"")),0) -> 1 | F15: =IFERROR(SUMPRODUCT(('1. Raw Votes Log'!B$4:B$203=B15)/COUNTIFS('1. Raw Votes Log'!B$4:B$203,B15&"",'1. Raw Votes Log'!H$4:H$203,'1. Raw Votes Log'!H$4:H$203&"")),0) -> 1 | G15: =IFERROR(VLOOKUP(B15,'6. Entropy Helper'!$A$4:$C$33,3,FALSE()),0) -> 0 | H15: =IF(F15>1,LOG(F15,2),0) -> 0 | I15: =IFERROR(IF(H15>0,G15/H15,0),0) -> 0 | J15: =IFERROR(IF(MAX($G$4:$G$33)>0,G15/MAX($G$4:$G$33)*100,0),0) -> 0
... A33: 30 | C33: =IFERROR(COUNTIF('1. Raw Votes Log'!B:B,B33),0) -> 0 | D33: =IFERROR(SUMPRODUCT(('1. Raw Votes Log'!B$4:B$203=B33)/COUNTIFS('1. Raw Votes Log'!B$4:B$203,B33&"",'1. Raw Votes Log'!E$4:E$203,'1. Raw Votes Log'!E$4:E$203&"")),0) -> 1 | E33: =IFERROR(SUMPRODUCT(('1. Raw Votes Log'!B$4:B$203=B33)/COUNTIFS('1. Raw Votes Log'!B$4:B$203,B33&"",'1. Raw Votes Log'!G$4:G$203,'1. Raw Votes Log'!G$4:G$203&"")),0) -> 1 | F33: =IFERROR(SUMPRODUCT(('1. Raw Votes Log'!B$4:B$203=B33)/COUNTIFS('1. Raw Votes Log'!B$4:B$203,B33&"",'1. Raw Votes Log'!H$4:H$203,'1. Raw Votes Log'!H$4:H$203&"")),0) -> 1 | G33: =IFERROR(VLOOKUP(B33,'6. Entropy Helper'!$A$4:$C$33,3,FALSE()),0) -> 0 | H33: =IF(F33>1,LOG(F33,2),0) -> 0 | I33: =IFERROR(IF(H33>0,G33/H33,0),0) -> 0 | J33: =IFERROR(IF(MAX($G$4:$G$33)>0,G33/MAX($G$4:$G$33)*100,0),0) -> 0

Sheet 6. Entropy Helper
A1: Entropy Helper — Per-University H Calculation
A2: Sums p×log(p) contributions across all buckets for each university (computed from CountrySubject Buckets sheet)
A3: University Name | B3: Total Votes | C3: Entropy H (bits) | D3: Notes
B4: =IFERROR(COUNTIF('1. Raw Votes Log'!B:B,A4),0) -> 0 | C4: =IFERROR(-SUMPRODUCT(IF('4. CountrySubject Buckets'!$B$4:$B$153=A4,IF('4. CountrySubject Buckets'!$F$4:$F$153>0,('4. CountrySubject Buckets'!$F$4:$F$153/B4)*LOG(('4. CountrySubject Buckets'!$F$4:$F$153/B4),2),0),0)),0) -> 0
B5: =IFERROR(COUNTIF('1. Raw Votes Log'!B:B,A5),0) -> 0 | C5: =IFERROR(-SUMPRODUCT(IF('4. CountrySubject Buckets'!$B$4:$B$153=A5,IF('4. CountrySubject Buckets'!$F$4:$F$153>0,('4. CountrySubject Buckets'!$F$4:$F$153/B5)*LOG(('4. CountrySubject Buckets'!$F$4:$F$153/B5),2),0),0)),0) -> 0
B6: =IFERROR(COUNTIF('1. Raw Votes Log'!B:B,A6),0) -> 0 | C6: =IFERROR(-SUMPRODUCT(IF('4. CountrySubject Buckets'!$B$4:$B$153=A6,IF('4. CountrySubject Buckets'!$F$4:$F$153>0,('4. CountrySubject Buckets'!$F$4:$F$153/B6)*LOG(('4. CountrySubject Buckets'!$F$4:$F$153/B6),2),0),0)),0) -> 0
B7: =IFERROR(COUNTIF('1. Raw Votes Log'!B:B,A7),0) -> 0 | C7: =IFERROR(-SUMPRODUCT(IF('4. CountrySubject Buckets'!$B$4:$B$153=A7,IF('4. CountrySubject Buckets'!$F$4:$F$153>0,('4. CountrySubject Buckets'!$F$4:$F$153/B7)*LOG(('4. CountrySubject Buckets'!$F$4:$F$153/B7),2),0),0)),0) -> 0
B8: =IFERROR(COUNTIF('1. Raw Votes Log'!B:B,A8),0) -> 0 | C8: =IFERROR(-SUMPRODUCT(IF('4. CountrySubject Buckets'!$B$4:$B$153=A8,IF('4. CountrySubject Buckets'!$F$4:$F$153>0,('4. CountrySubject Buckets'!$F$4:$F$153/B8)*LOG(('4. CountrySubject Buckets'!$F$4:$F$153/B8),2),0),0)),0) -> 0
B9: =IFERROR(COUNTIF('1. Raw Votes Log'!B:B,A9),0) -> 0 | C9: =IFERROR(-SUMPRODUCT(IF('4. CountrySubject Buckets'!$B$4:$B$153=A9,IF('4. CountrySubject Buckets'!$F$4:$F$153>0,('4. CountrySubject Buckets'!$F$4:$F$153/B9)*LOG(('4. CountrySubject Buckets'!$F$4:$F$153/B9),2),0),0)),0) -> 0
B10: =IFERROR(COUNTIF('1. Raw Votes Log'!B:B,A10),0) -> 0 | C10: =IFERROR(-SUMPRODUCT(IF('4. CountrySubject Buckets'!$B$4:$B$153=A10,IF('4. CountrySubject Buckets'!$F$4:$F$153>0,('4. CountrySubject Buckets'!$F$4:$F$153/B10)*LOG(('4. CountrySubject Buckets'!$F$4:$F$153/B10),2),0),0)),0) -> 0
B11: =IFERROR(COUNTIF('1. Raw Votes Log'!B:B,A11),0) -> 0 | C11: =IFERROR(-SUMPRODUCT(IF('4. CountrySubject Buckets'!$B$4:$B$153=A11,IF('4. CountrySubject Buckets'!$F$4:$F$153>0,('4. CountrySubject Buckets'!$F$4:$F$153/B11)*LOG(('4. CountrySubject Buckets'!$F$4:$F$153/B11),2),0),0)),0) -> 0
B12: =IFERROR(COUNTIF('1. Raw Votes Log'!B:B,A12),0) -> 0 | C12: =IFERROR(-SUMPRODUCT(IF('4. CountrySubject Buckets'!$B$4:$B$153=A12,IF('4. CountrySubject Buckets'!$F$4:$F$153>0,('4. CountrySubject Buckets'!$F$4:$F$153/B12)*LOG(('4. CountrySubject Buckets'!$F$4:$F$153/B12),2),0),0)),0) -> 0
B13: =IFERROR(COUNTIF('1. Raw Votes Log'!B:B,A13),0) -> 0 | C13: =IFERROR(-SUMPRODUCT(IF('4. CountrySubject Buckets'!$B$4:$B$153=A13,IF('4. CountrySubject Buckets'!$F$4:$F$153>0,('4. CountrySubject Buckets'!$F$4:$F$153/B13)*LOG(('4. CountrySubject Buckets'!$F$4:$F$153/B13),2),0),0)),0) -> 0
B14: =IFERROR(COUNTIF('1. Raw Votes Log'!B:B,A14),0) -> 0 | C14: =IFERROR(-SUMPRODUCT(IF('4. CountrySubject Buckets'!$B$4:$B$153=A14,IF('4. CountrySubject Buckets'!$F$4:$F$153>0,('4. CountrySubject Buckets'!$F$4:$F$153/B14)*LOG(('4. CountrySubject Buckets'!$F$4:$F$153/B14),2),0),0)),0) -> 0
B15: =IFERROR(COUNTIF('1. Raw Votes Log'!B:B,A15),0) -> 0 | C15: =IFERROR(-SUMPRODUCT(IF('4. CountrySubject Buckets'!$B$4:$B$153=A15,IF('4. CountrySubject Buckets'!$F$4:$F$153>0,('4. CountrySubject Buckets'!$F$4:$F$153/B15)*LOG(('4. CountrySubject Buckets'!$F$4:$F$153/B15),2),0),0)),0) -> 0
... B33: =IFERROR(COUNTIF('1. Raw Votes Log'!B:B,A33),0) -> 0 | C33: =IFERROR(-SUMPRODUCT(IF('4. CountrySubject Buckets'!$B$4:$B$153=A33,IF('4. CountrySubject Buckets'!$F$4:$F$153>0,('4. CountrySubject Buckets'!$F$4:$F$153/B33)*LOG(('4. CountrySubject Buckets'!$F$4:$F$153/B33),2),0),0)),0) -> 0

Sheet 7. Diversity Dashboard
A1: Teaching Voter Diversity — Final Dashboard & Rankings
A2: Summary of diversity metrics per university with global ranking
A3: Rank | B3: University Name | C3: Total Votes | D3: Unique Countries | E3: Unique Subjects | F3: Unique Buckets | G3: Entropy H | H3: Diversity Score (0–100) | I3: Tier
A4: =IFERROR(RANK(H4,$H$4:$H$33,0),"") -> 1 | C4: =IFERROR(VLOOKUP(B4,'5. Entropy Calculation'!B:J,2,FALSE()),0) -> 0 | D4: =IFERROR(VLOOKUP(B4,'5. Entropy Calculation'!B:J,3,FALSE()),0) -> 0 | E4: =IFERROR(VLOOKUP(B4,'5. Entropy Calculation'!B:J,4,FALSE()),0) -> 0 | F4: =IFERROR(VLOOKUP(B4,'5. Entropy Calculation'!B:J,5,FALSE()),0) -> 0 | G4: =IFERROR(VLOOKUP(B4,'5. Entropy Calculation'!B:J,6,FALSE()),0) -> 0 | H4: =IFERROR(VLOOKUP(B4,'5. Entropy Calculation'!B:J,9,FALSE()),0) -> 0 | I4: =IF(H4>=80,"Very High",IF(H4>=60,"High",IF(H4>=40,"Medium",IF(H4>=20,"Low","Very Low")))) -> Very Low
A5: =IFERROR(RANK(H5,$H$4:$H$33,0),"") -> 1 | C5: =IFERROR(VLOOKUP(B5,'5. Entropy Calculation'!B:J,2,FALSE()),0) -> 0 | D5: =IFERROR(VLOOKUP(B5,'5. Entropy Calculation'!B:J,3,FALSE()),0) -> 0 | E5: =IFERROR(VLOOKUP(B5,'5. Entropy Calculation'!B:J,4,FALSE()),0) -> 0 | F5: =IFERROR(VLOOKUP(B5,'5. Entropy Calculation'!B:J,5,FALSE()),0) -> 0 | G5: =IFERROR(VLOOKUP(B5,'5. Entropy Calculation'!B:J,6,FALSE()),0) -> 0 | H5: =IFERROR(VLOOKUP(B5,'5. Entropy Calculation'!B:J,9,FALSE()),0) -> 0 | I5: =IF(H5>=80,"Very High",IF(H5>=60,"High",IF(H5>=40,"Medium",IF(H5>=20,"Low","Very Low")))) -> Very Low
A6: =IFERROR(RANK(H6,$H$4:$H$33,0),"") -> 1 | C6: =IFERROR(VLOOKUP(B6,'5. Entropy Calculation'!B:J,2,FALSE()),0) -> 0 | D6: =IFERROR(VLOOKUP(B6,'5. Entropy Calculation'!B:J,3,FALSE()),0) -> 0 | E6: =IFERROR(VLOOKUP(B6,'5. Entropy Calculation'!B:J,4,FALSE()),0) -> 0 | F6: =IFERROR(VLOOKUP(B6,'5. Entropy Calculation'!B:J,5,FALSE()),0) -> 0 | G6: =IFERROR(VLOOKUP(B6,'5. Entropy Calculation'!B:J,6,FALSE()),0) -> 0 | H6: =IFERROR(VLOOKUP(B6,'5. Entropy Calculation'!B:J,9,FALSE()),0) -> 0 | I6: =IF(H6>=80,"Very High",IF(H6>=60,"High",IF(H6>=40,"Medium",IF(H6>=20,"Low","Very Low")))) -> Very Low
A7: =IFERROR(RANK(H7,$H$4:$H$33,0),"") -> 1 | C7: =IFERROR(VLOOKUP(B7,'5. Entropy Calculation'!B:J,2,FALSE()),0) -> 0 | D7: =IFERROR(VLOOKUP(B7,'5. Entropy Calculation'!B:J,3,FALSE()),0) -> 0 | E7: =IFERROR(VLOOKUP(B7,'5. Entropy Calculation'!B:J,4,FALSE()),0) -> 0 | F7: =IFERROR(VLOOKUP(B7,'5. Entropy Calculation'!B:J,5,FALSE()),0) -> 0 | G7: =IFERROR(VLOOKUP(B7,'5. Entropy Calculation'!B:J,6,FALSE()),0) -> 0 | H7: =IFERROR(VLOOKUP(B7,'5. Entropy Calculation'!B:J,9,FALSE()),0) -> 0 | I7: =IF(H7>=80,"Very High",IF(H7>=60,"High",IF(H7>=40,"Medium",IF(H7>=20,"Low","Very Low")))) -> Very Low
