Workbook

Sheet Methodology Overview
A1: THE WRR — Subject Diversity Data Collection Formats
A2: Voter Diversity Indicator: Subject-Area Dimension (WRR 2025 Methodology)
A4: # | B4: Concept | C4: Description | D4: Relevance
A5: 1 | B5: Subject Diversity | C5: Measures how broadly an institution's reputation votes are spread ACROSS the 11 THE subject areas. An institution recognized across many disciplines has a more robust reputation than one recognized only in a narrow field. | D5: Core component of Voter Diversity pillar (10% of WRR)
A6: 2 | B6: THE's 11 Subject Groups | C6: Arts & Humanities; Business & Economics; Clinical & Health; Computer Science; Education; Engineering; Law; Life Sciences; Physical Sciences; Psychology; Social Sciences | D6: Standard classification used in Academic Reputation Survey
A7: 3 | B7: Entropy on Subject Dimension | C7: H_subj = −Σ pⱼ × log₂(pⱼ), where pⱼ = proportion of votes from subject area j. Maximum H_subj = log₂(11) ≈ 3.459 bits when votes are evenly distributed across all 11 subjects. | D7: Mathematical measure of subject heterogeneity
A8: 4 | B8: Subject × Country Interaction | C8: Full voter diversity uses COMBINED country × subject buckets. This workbook isolates the SUBJECT dimension for detailed analysis while remaining compatible with the full entropy framework. | D8: Analytical decomposition
A9: 5 | B9: Research vs Teaching | C9: Subject diversity is computed separately for research votes and teaching votes, then weighted: Research Diversity × 6.67% + Teaching Diversity × 3.33% = 10% total diversity weight. | D9: Pillar separation
A10: 6 | B10: Normalized Score | C10: Subject entropy is normalized to 0–100 scale for comparability. Institutions with maximum spread across all 11 subjects score highest. | D10: Output format
A11: 7 | B11: Super-Brand Consideration | C11: Elite institutions often receive votes across all subjects (broad recognition), while specialist institutions may score high in only 1–3 areas. Subject diversity captures this difference. | D11: Interpretation context
A13: Entropy Formula
A14: H_subj = − Σⱼ₌₁¹¹ pⱼ × log₂(pⱼ) | Max H = log₂(11) ≈ 3.459 bits | Normalized = H / H_max × 100

Sheet Subject Areas Reference
A1: THE 11 Subject Areas — Reference Classification
A2: Standard subject groupings used in the Global Academic Reputation Survey
A3: # | B3: Code | C3: Subject Area | D3: Disciplines Covered | E3: Example Departments | F3: Survey Weight
A4: 1 | B4: AH | C4: Arts & Humanities | D4: Archaeology, architecture, history, languages & linguistics, literature, music, performing arts, philosophy, theology, religious studies, art & design | E4: Dept. of English, History, Philosophy, Fine Arts | F4: Equal
A5: 2 | B5: BE | C5: Business & Economics | D5: Accounting & finance, business & management, economics & econometrics, marketing, operations research | E5: Business School, Dept. of Economics, MBA Programme | F5: Equal
A6: 3 | B6: CH | C6: Clinical & Health | D6: Medicine, dentistry, health sciences, health professions, public health, nursing, pharmacy, veterinary medicine (clinical) | E6: Medical College, School of Public Health, Nursing School | F6: Equal
A7: 4 | B7: CS | C7: Computer Science | D7: AI & machine learning, cybersecurity, data science, information systems, software engineering, HCI | E7: Dept. of CS, School of Computing, IT Department | F7: Equal
A8: 5 | B8: ED | C8: Education | D8: Teaching & learning, education policy, pedagogy, educational psychology, curriculum studies, special education | E8: School of Education, Dept. of Teacher Training | F8: Equal
A9: 6 | B9: EN | C9: Engineering | D9: Chemical, civil, electrical & electronic, mechanical, materials, aerospace, general engineering, mining & mineral | E9: School of Engineering, Dept. of Mechanical/Civil/EEE | F9: Equal
A10: 7 | B10: LW | C10: Law | D10: Corporate law, criminal law, international law, constitutional law, legal theory, jurisprudence, human rights law | E10: Law School, Faculty of Law | F10: Equal
A11: 8 | B11: LS | C11: Life Sciences | D11: Agriculture & forestry, biological sciences, ecology, sport science, veterinary science (non-clinical), food science | E11: Dept. of Biology, Agriculture, Zoology, Botany | F11: Equal
A12: 9 | B12: PS | C12: Physical Sciences | D12: Chemistry, physics, astronomy, geology & earth sciences, environmental sciences, mathematics & statistics, ocean sciences | E12: Dept. of Physics, Chemistry, Mathematics, Earth Sciences | F12: Equal
A13: 10 | B13: PY | C13: Psychology | D13: Clinical psychology, educational psychology, organizational psychology, cognitive science, social psychology, neuroscience | E13: Dept. of Psychology, School of Behavioural Sciences | F13: Equal
A14: 11 | B14: SS | C14: Social Sciences | D14: Communication & media, geography, politics & international studies, sociology, anthropology, development studies, gender studies | E14: Dept. of Sociology, Political Science, Anthropology | F14: Equal

Sheet 1. Research Votes Log
A1: Raw Research Votes Log — Source Data for Subject Diversity Analysis
A2: Each row = one research vote (up to 15 per respondent). Captures respondent's subject area for subject diversity.
A3: Vote ID | B3: University Name | C3: Respondent ID | D3: Respondent Country (ISO) | E3: Subject Code | F3: Subject Area (Full Name) | G3: Self-Vote (Y/N) | H3: Date
A4: RV-00001 | F4: =IFERROR(VLOOKUP(E4,'Subject Areas Reference'!$B$4:$C$14,2,FALSE()),"")
A5: RV-00002 | F5: =IFERROR(VLOOKUP(E5,'Subject Areas Reference'!$B$4:$C$14,2,FALSE()),"")
A6: RV-00003 | F6: =IFERROR(VLOOKUP(E6,'Subject Areas Reference'!$B$4:$C$14,2,FALSE()),"")
A7: RV-00004 | F7: =IFERROR(VLOOKUP(E7,'Subject Areas Reference'!$B$4:$C$14,2,FALSE()),"")
A8: RV-00005 | F8: =IFERROR(VLOOKUP(E8,'Subject Areas Reference'!$B$4:$C$14,2,FALSE()),"")
A9: RV-00006 | F9: =IFERROR(VLOOKUP(E9,'Subject Areas Reference'!$B$4:$C$14,2,FALSE()),"")
A10: RV-00007 | F10: =IFERROR(VLOOKUP(E10,'Subject Areas Reference'!$B$4:$C$14,2,FALSE()),"")
A11: RV-00008 | F11: =IFERROR(VLOOKUP(E11,'Subject Areas Reference'!$B$4:$C$14,2,FALSE()),"")
A12: RV-00009 | F12: =IFERROR(VLOOKUP(E12,'Subject Areas Reference'!$B$4:$C$14,2,FALSE()),"")
A13: RV-00010 | F13: =IFERROR(VLOOKUP(E13,'Subject Areas Reference'!$B$4:$C$14,2,FALSE()),"")
A14: RV-00011 | F14: =IFERROR(VLOOKUP(E14,'Subject Areas Reference'!$B$4:$C$14,2,FALSE()),"")
A15: RV-00012 | F15: =IFERROR(VLOOKUP(E15,'Subject Areas Reference'!$B$4:$C$14,2,FALSE()),"")
... A203: RV-00200 | F203: =IFERROR(VLOOKUP(E203,'Subject Areas Reference'!$B$4:$C$14,2,FALSE()),"")

Sheet 2. Teaching Votes Log
A1: Raw Teaching Votes Log — Source Data for Subject Diversity Analysis
A2: Each row = one teaching vote (up to 15 per respondent). Captures respondent's subject area for teaching subject diversity.
A3: Vote ID | B3: University Name | C3: Respondent ID | D3: Respondent Country (ISO) | E3: Subject Code | F3: Subject Area (Full Name) | G3: Self-Vote (Y/N) | H3: Date
A4: TV-00001 | F4: =IFERROR(VLOOKUP(E4,'Subject Areas Reference'!$B$4:$C$14,2,FALSE()),"")
A5: TV-00002 | F5: =IFERROR(VLOOKUP(E5,'Subject Areas Reference'!$B$4:$C$14,2,FALSE()),"")
A6: TV-00003 | F6: =IFERROR(VLOOKUP(E6,'Subject Areas Reference'!$B$4:$C$14,2,FALSE()),"")
A7: TV-00004 | F7: =IFERROR(VLOOKUP(E7,'Subject Areas Reference'!$B$4:$C$14,2,FALSE()),"")
A8: TV-00005 | F8: =IFERROR(VLOOKUP(E8,'Subject Areas Reference'!$B$4:$C$14,2,FALSE()),"")
A9: TV-00006 | F9: =IFERROR(VLOOKUP(E9,'Subject Areas Reference'!$B$4:$C$14,2,FALSE()),"")
A10: TV-00007 | F10: =IFERROR(VLOOKUP(E10,'Subject Areas Reference'!$B$4:$C$14,2,FALSE()),"")
A11: TV-00008 | F11: =IFERROR(VLOOKUP(E11,'Subject Areas Reference'!$B$4:$C$14,2,FALSE()),"")
A12: TV-00009 | F12: =IFERROR(VLOOKUP(E12,'Subject Areas Reference'!$B$4:$C$14,2,FALSE()),"")
A13: TV-00010 | F13: =IFERROR(VLOOKUP(E13,'Subject Areas Reference'!$B$4:$C$14,2,FALSE()),"")
A14: TV-00011 | F14: =IFERROR(VLOOKUP(E14,'Subject Areas Reference'!$B$4:$C$14,2,FALSE()),"")
A15: TV-00012 | F15: =IFERROR(VLOOKUP(E15,'Subject Areas Reference'!$B$4:$C$14,2,FALSE()),"")
... A203: TV-00200 | F203: =IFERROR(VLOOKUP(E203,'Subject Areas Reference'!$B$4:$C$14,2,FALSE()),"")

Sheet 3. Research Subject Matrix
A1: Research Votes: University × Subject Area Distribution
A2: Auto-populated from Research Votes Log — count of research votes per university per subject area
A4: University ↓ / Subject → | B4: AH | C4: BE | D4: CH | E4: CS | F4: ED | G4: EN | H4: LW | I4: LS | J4: PS | K4: PY | L4: SS | M4: Total Votes | N4: Unique Subjects | O4: Coverage %
B5: =IFERROR(COUNTIFS('1. Research Votes Log'!B:B,$A5,'1. Research Votes Log'!E:E,"AH"),0) -> 0 | C5: =IFERROR(COUNTIFS('1. Research Votes Log'!B:B,$A5,'1. Research Votes Log'!E:E,"BE"),0) -> 0 | D5: =IFERROR(COUNTIFS('1. Research Votes Log'!B:B,$A5,'1. Research Votes Log'!E:E,"CH"),0) -> 0 | E5: =IFERROR(COUNTIFS('1. Research Votes Log'!B:B,$A5,'1. Research Votes Log'!E:E,"CS"),0) -> 0 | F5: =IFERROR(COUNTIFS('1. Research Votes Log'!B:B,$A5,'1. Research Votes Log'!E:E,"ED"),0) -> 0 | G5: =IFERROR(COUNTIFS('1. Research Votes Log'!B:B,$A5,'1. Research Votes Log'!E:E,"EN"),0) -> 0 | H5: =IFERROR(COUNTIFS('1. Research Votes Log'!B:B,$A5,'1. Research Votes Log'!E:E,"LW"),0) -> 0 | I5: =IFERROR(COUNTIFS('1. Research Votes Log'!B:B,$A5,'1. Research Votes Log'!E:E,"LS"),0) -> 0 | J5: =IFERROR(COUNTIFS('1. Research Votes Log'!B:B,$A5,'1. Research Votes Log'!E:E,"PS"),0) -> 0 | K5: =IFERROR(COUNTIFS('1. Research Votes Log'!B:B,$A5,'1. Research Votes Log'!E:E,"PY"),0) -> 0 | L5: =IFERROR(COUNTIFS('1. Research Votes Log'!B:B,$A5,'1. Research Votes Log'!E:E,"SS"),0) -> 0 | M5: =SUM(B5:L5) -> 0 | N5: =COUNTIF(B5:L5,">0") -> 0 | O5: =IFERROR(N5/11*100,0) -> 0
B6: =IFERROR(COUNTIFS('1. Research Votes Log'!B:B,$A6,'1. Research Votes Log'!E:E,"AH"),0) -> 0 | C6: =IFERROR(COUNTIFS('1. Research Votes Log'!B:B,$A6,'1. Research Votes Log'!E:E,"BE"),0) -> 0 | D6: =IFERROR(COUNTIFS('1. Research Votes Log'!B:B,$A6,'1. Research Votes Log'!E:E,"CH"),0) -> 0 | E6: =IFERROR(COUNTIFS('1. Research Votes Log'!B:B,$A6,'1. Research Votes Log'!E:E,"CS"),0) -> 0 | F6: =IFERROR(COUNTIFS('1. Research Votes Log'!B:B,$A6,'1. Research Votes Log'!E:E,"ED"),0) -> 0 | G6: =IFERROR(COUNTIFS('1. Research Votes Log'!B:B,$A6,'1. Research Votes Log'!E:E,"EN"),0) -> 0 | H6: =IFERROR(COUNTIFS('1. Research Votes Log'!B:B,$A6,'1. Research Votes Log'!E:E,"LW"),0) -> 0 | I6: =IFERROR(COUNTIFS('1. Research Votes Log'!B:B,$A6,'1. Research Votes Log'!E:E,"LS"),0) -> 0 | J6: =IFERROR(COUNTIFS('1. Research Votes Log'!B:B,$A6,'1. Research Votes Log'!E:E,"PS"),0) -> 0 | K6: =IFERROR(COUNTIFS('1. Research Votes Log'!B:B,$A6,'1. Research Votes Log'!E:E,"PY"),0) -> 0 | L6: =IFERROR(COUNTIFS('1. Research Votes Log'!B:B,$A6,'1. Research Votes Log'!E:E,"SS"),0) -> 0 | M6: =SUM(B6:L6) -> 0 | N6: =COUNTIF(B6:L6,">0") -> 0 | O6: =IFERROR(N6/11*100,0) -> 0
B7: =IFERROR(COUNTIFS('1. Research Votes Log'!B:B,$A7,'1. Research Votes Log'!E:E,"AH"),0) -> 0 | C7: =IFERROR(COUNTIFS('1. Research Votes Log'!B:B,$A7,'1. Research Votes Log'!E:E,"BE"),0) -> 0 | D7: =IFERROR(COUNTIFS('1. Research Votes Log'!B:B,$A7,'1. Research Votes Log'!E:E,"CH"),0) -> 0 | E7: =IFERROR(COUNTIFS('1. Research Votes Log'!B:B,$A7,'1. Research Votes Log'!E:E,"CS"),0) -> 0 | F7: =IFERROR(COUNTIFS('1. Research Votes Log'!B:B,$A7,'1. Research Votes Log'!E:E,"ED"),0) -> 0 | G7: =IFERROR(COUNTIFS('1. Research Votes Log'!B:B,$A7,'1. Research Votes Log'!E:E,"EN"),0) -> 0 | H7: =IFERROR(COUNTIFS('1. Research Votes Log'!B:B,$A7,'1. Research Votes Log'!E:E,"LW"),0) -> 0 | I7: =IFERROR(COUNTIFS('1. Research Votes Log'!B:B,$A7,'1. Research Votes Log'!E:E,"LS"),0) -> 0 | J7: =IFERROR(COUNTIFS('1. Research Votes Log'!B:B,$A7,'1. Research Votes Log'!E:E,"PS"),0) -> 0 | K7: =IFERROR(COUNTIFS('1. Research Votes Log'!B:B,$A7,'1. Research Votes Log'!E:E,"PY"),0) -> 0 | L7: =IFERROR(COUNTIFS('1. Research Votes Log'!B:B,$A7,'1. Research Votes Log'!E:E,"SS"),0) -> 0 | M7: =SUM(B7:L7) -> 0 | N7: =COUNTIF(B7:L7,">0") -> 0 | O7: =IFERROR(N7/11*100,0) -> 0
B8: =IFERROR(COUNTIFS('1. Research Votes Log'!B:B,$A8,'1. Research Votes Log'!E:E,"AH"),0) -> 0 | C8: =IFERROR(COUNTIFS('1. Research Votes Log'!B:B,$A8,'1. Research Votes Log'!E:E,"BE"),0) -> 0 | D8: =IFERROR(COUNTIFS('1. Research Votes Log'!B:B,$A8,'1. Research Votes Log'!E:E,"CH"),0) -> 0 | E8: =IFERROR(COUNTIFS('1. Research Votes Log'!B:B,$A8,'1. Research Votes Log'!E:E,"CS"),0) -> 0 | F8: =IFERROR(COUNTIFS('1. Research Votes Log'!B:B,$A8,'1. Research Votes Log'!E:E,"ED"),0) -> 0 | G8: =IFERROR(COUNTIFS('1. Research Votes Log'!B:B,$A8,'1. Research Votes Log'!E:E,"EN"),0) -> 0 | H8: =IFERROR(COUNTIFS('1. Research Votes Log'!B:B,$A8,'1. Research Votes Log'!E:E,"LW"),0) -> 0 | I8: =IFERROR(COUNTIFS('1. Research Votes Log'!B:B,$A8,'1. Research Votes Log'!E:E,"LS"),0) -> 0 | J8: =IFERROR(COUNTIFS('1. Research Votes Log'!B:B,$A8,'1. Research Votes Log'!E:E,"PS"),0) -> 0 | K8: =IFERROR(COUNTIFS('1. Research Votes Log'!B:B,$A8,'1. Research Votes Log'!E:E,"PY"),0) -> 0 | L8: =IFERROR(COUNTIFS('1. Research Votes Log'!B:B,$A8,'1. Research Votes Log'!E:E,"SS"),0) -> 0 | M8: =SUM(B8:L8) -> 0 | N8: =COUNTIF(B8:L8,">0") -> 0 | O8: =IFERROR(N8/11*100,0) -> 0
B9: =IFERROR(COUNTIFS('1. Research Votes Log'!B:B,$A9,'1. Research Votes Log'!E:E,"AH"),0) -> 0 | C9: =IFERROR(COUNTIFS('1. Research Votes Log'!B:B,$A9,'1. Research Votes Log'!E:E,"BE"),0) -> 0 | D9: =IFERROR(COUNTIFS('1. Research Votes Log'!B:B,$A9,'1. Research Votes Log'!E:E,"CH"),0) -> 0 | E9: =IFERROR(COUNTIFS('1. Research Votes Log'!B:B,$A9,'1. Research Votes Log'!E:E,"CS"),0) -> 0 | F9: =IFERROR(COUNTIFS('1. Research Votes Log'!B:B,$A9,'1. Research Votes Log'!E:E,"ED"),0) -> 0 | G9: =IFERROR(COUNTIFS('1. Research Votes Log'!B:B,$A9,'1. Research Votes Log'!E:E,"EN"),0) -> 0 | H9: =IFERROR(COUNTIFS('1. Research Votes Log'!B:B,$A9,'1. Research Votes Log'!E:E,"LW"),0) -> 0 | I9: =IFERROR(COUNTIFS('1. Research Votes Log'!B:B,$A9,'1. Research Votes Log'!E:E,"LS"),0) -> 0 | J9: =IFERROR(COUNTIFS('1. Research Votes Log'!B:B,$A9,'1. Research Votes Log'!E:E,"PS"),0) -> 0 | K9: =IFERROR(COUNTIFS('1. Research Votes Log'!B:B,$A9,'1. Research Votes Log'!E:E,"PY"),0) -> 0 | L9: =IFERROR(COUNTIFS('1. Research Votes Log'!B:B,$A9,'1. Research Votes Log'!E:E,"SS"),0) -> 0 | M9: =SUM(B9:L9) -> 0 | N9: =COUNTIF(B9:L9,">0") -> 0 | O9: =IFERROR(N9/11*100,0) -> 0
B10: =IFERROR(COUNTIFS('1. Research Votes Log'!B:B,$A10,'1. Research Votes Log'!E:E,"AH"),0) -> 0 | C10: =IFERROR(COUNTIFS('1. Research Votes Log'!B:B,$A10,'1. Research Votes Log'!E:E,"BE"),0) -> 0 | D10: =IFERROR(COUNTIFS('1. Research Votes Log'!B:B,$A10,'1. Research Votes Log'!E:E,"CH"),0) -> 0 | E10: =IFERROR(COUNTIFS('1. Research Votes Log'!B:B,$A10,'1. Research Votes Log'!E:E,"CS"),0) -> 0 | F10: =IFERROR(COUNTIFS('1. Research Votes Log'!B:B,$A10,'1. Research Votes Log'!E:E,"ED"),0) -> 0 | G10: =IFERROR(COUNTIFS('1. Research Votes Log'!B:B,$A10,'1. Research Votes Log'!E:E,"EN"),0) -> 0 | H10: =IFERROR(COUNTIFS('1. Research Votes Log'!B:B,$A10,'1. Research Votes Log'!E:E,"LW"),0) -> 0 | I10: =IFERROR(COUNTIFS('1. Research Votes Log'!B:B,$A10,'1. Research Votes Log'!E:E,"LS"),0) -> 0 | J10: =IFERROR(COUNTIFS('1. Research Votes Log'!B:B,$A10,'1. Research Votes Log'!E:E,"PS"),0) -> 0 | K10: =IFERROR(COUNTIFS('1. Research Votes Log'!B:B,$A10,'1. Research Votes Log'!E:E,"PY"),0) -> 0 | L10: =IFERROR(COUNTIFS('1. Research Votes Log'!B:B,$A10,'1. Research Votes Log'!E:E,"SS"),0) -> 0 | M10: =SUM(B10:L10) -> 0 | N10: =COUNTIF(B10:L10,">0") -> 0 | O10: =IFERROR(N10/11*100,0) -> 0
B11: =IFERROR(COUNTIFS('1. Research Votes Log'!B:B,$A11,'1. Research Votes Log'!E:E,"AH"),0) -> 0 | C11: =IFERROR(COUNTIFS('1. Research Votes Log'!B:B,$A11,'1. Research Votes Log'!E:E,"BE"),0) -> 0 | D11: =IFERROR(COUNTIFS('1. Research Votes Log'!B:B,$A11,'1. Research Votes Log'!E:E,"CH"),0) -> 0 | E11: =IFERROR(COUNTIFS('1. Research Votes Log'!B:B,$A11,'1. Research Votes Log'!E:E,"CS"),0) -> 0 | F11: =IFERROR(COUNTIFS('1. Research Votes Log'!B:B,$A11,'1. Research Votes Log'!E:E,"ED"),0) -> 0 | G11: =IFERROR(COUNTIFS('1. Research Votes Log'!B:B,$A11,'1. Research Votes Log'!E:E,"EN"),0) -> 0 | H11: =IFERROR(COUNTIFS('1. Research Votes Log'!B:B,$A11,'1. Research Votes Log'!E:E,"LW"),0) -> 0 | I11: =IFERROR(COUNTIFS('1. Research Votes Log'!B:B,$A11,'1. Research Votes Log'!E:E,"LS"),0) -> 0 | J11: =IFERROR(COUNTIFS('1. Research Votes Log'!B:B,$A11,'1. Research Votes Log'!E:E,"PS"),0) -> 0 | K11: =IFERROR(COUNTIFS('1. Research Votes Log'!B:B,$A11,'1. Research Votes Log'!E:E,"PY"),0) -> 0 | L11: =IFERROR(COUNTIFS('1. Research Votes Log'!B:B,$A11,'1. Research Votes Log'!E:E,"SS"),0) -> 0 | M11: =SUM(B11:L11) -> 0 | N11: =COUNTIF(B11:L11,">0") -> 0 | O11: =IFERROR(N11/11*100,0) -> 0
B12: =IFERROR(COUNTIFS('1. Research Votes Log'!B:B,$A12,'1. Research Votes Log'!E:E,"AH"),0) -> 0 | C12: =IFERROR(COUNTIFS('1. Research Votes Log'!B:B,$A12,'1. Research Votes Log'!E:E,"BE"),0) -> 0 | D12: =IFERROR(COUNTIFS('1. Research Votes Log'!B:B,$A12,'1. Research Votes Log'!E:E,"CH"),0) -> 0 | E12: =IFERROR(COUNTIFS('1. Research Votes Log'!B:B,$A12,'1. Research Votes Log'!E:E,"CS"),0) -> 0 | F12: =IFERROR(COUNTIFS('1. Research Votes Log'!B:B,$A12,'1. Research Votes Log'!E:E,"ED"),0) -> 0 | G12: =IFERROR(COUNTIFS('1. Research Votes Log'!B:B,$A12,'1. Research Votes Log'!E:E,"EN"),0) -> 0 | H12: =IFERROR(COUNTIFS('1. Research Votes Log'!B:B,$A12,'1. Research Votes Log'!E:E,"LW"),0) -> 0 | I12: =IFERROR(COUNTIFS('1. Research Votes Log'!B:B,$A12,'1. Research Votes Log'!E:E,"LS"),0) -> 0 | J12: =IFERROR(COUNTIFS('1. Research Votes Log'!B:B,$A12,'1. Research Votes Log'!E:E,"PS"),0) -> 0 | K12: =IFERROR(COUNTIFS('1. Research Votes Log'!B:B,$A12,'1. Research Votes Log'!E:E,"PY"),0) -> 0 | L12: =IFERROR(COUNTIFS('1. Research Votes Log'!B:B,$A12,'1. Research Votes Log'!E:E,"SS"),0) -> 0 | M12: =SUM(B12:L12) -> 0 | N12: =COUNTIF(B12:L12,">0") -> 0 | O12: =IFERROR(N12/11*100,0) -> 0
B13: =IFERROR(COUNTIFS('1. Research Votes Log'!B:B,$A13,'1. Research Votes Log'!E:E,"AH"),0) -> 0 | C13: =IFERROR(COUNTIFS('1. Research Votes Log'!B:B,$A13,'1. Research Votes Log'!E:E,"BE"),0) -> 0 | D13: =IFERROR(COUNTIFS('1. Research Votes Log'!B:B,$A13,'1. Research Votes Log'!E:E,"CH"),0) -> 0 | E13: =IFERROR(COUNTIFS('1. Research Votes Log'!B:B,$A13,'1. Research Votes Log'!E:E,"CS"),0) -> 0 | F13: =IFERROR(COUNTIFS('1. Research Votes Log'!B:B,$A13,'1. Research Votes Log'!E:E,"ED"),0) -> 0 | G13: =IFERROR(COUNTIFS('1. Research Votes Log'!B:B,$A13,'1. Research Votes Log'!E:E,"EN"),0) -> 0 | H13: =IFERROR(COUNTIFS('1. Research Votes Log'!B:B,$A13,'1. Research Votes Log'!E:E,"LW"),0) -> 0 | I13: =IFERROR(COUNTIFS('1. Research Votes Log'!B:B,$A13,'1. Research Votes Log'!E:E,"LS"),0) -> 0 | J13: =IFERROR(COUNTIFS('1. Research Votes Log'!B:B,$A13,'1. Research Votes Log'!E:E,"PS"),0) -> 0 | K13: =IFERROR(COUNTIFS('1. Research Votes Log'!B:B,$A13,'1. Research Votes Log'!E:E,"PY"),0) -> 0 | L13: =IFERROR(COUNTIFS('1. Research Votes Log'!B:B,$A13,'1. Research Votes Log'!E:E,"SS"),0) -> 0 | M13: =SUM(B13:L13) -> 0 | N13: =COUNTIF(B13:L13,">0") -> 0 | O13: =IFERROR(N13/11*100,0) -> 0
B14: =IFERROR(COUNTIFS('1. Research Votes Log'!B:B,$A14,'1. Research Votes Log'!E:E,"AH"),0) -> 0 | C14: =IFERROR(COUNTIFS('1. Research Votes Log'!B:B,$A14,'1. Research Votes Log'!E:E,"BE"),0) -> 0 | D14: =IFERROR(COUNTIFS('1. Research Votes Log'!B:B,$A14,'1. Research Votes Log'!E:E,"CH"),0) -> 0 | E14: =IFERROR(COUNTIFS('1. Research Votes Log'!B:B,$A14,'1. Research Votes Log'!E:E,"CS"),0) -> 0 | F14: =IFERROR(COUNTIFS('1. Research Votes Log'!B:B,$A14,'1. Research Votes Log'!E:E,"ED"),0) -> 0 | G14: =IFERROR(COUNTIFS('1. Research Votes Log'!B:B,$A14,'1. Research Votes Log'!E:E,"EN"),0) -> 0 | H14: =IFERROR(COUNTIFS('1. Research Votes Log'!B:B,$A14,'1. Research Votes Log'!E:E,"LW"),0) -> 0 | I14: =IFERROR(COUNTIFS('1. Research Votes Log'!B:B,$A14,'1. Research Votes Log'!E:E,"LS"),0) -> 0 | J14: =IFERROR(COUNTIFS('1. Research Votes Log'!B:B,$A14,'1. Research Votes Log'!E:E,"PS"),0) -> 0 | K14: =IFERROR(COUNTIFS('1. Research Votes Log'!B:B,$A14,'1. Research Votes Log'!E:E,"PY"),0) -> 0 | L14: =IFERROR(COUNTIFS('1. Research Votes Log'!B:B,$A14,'1. Research Votes Log'!E:E,"SS"),0) -> 0 | M14: =SUM(B14:L14) -> 0 | N14: =COUNTIF(B14:L14,">0") -> 0 | O14: =IFERROR(N14/11*100,0) -> 0
B15: =IFERROR(COUNTIFS('1. Research Votes Log'!B:B,$A15,'1. Research Votes Log'!E:E,"AH"),0) -> 0 | C15: =IFERROR(COUNTIFS('1. Research Votes Log'!B:B,$A15,'1. Research Votes Log'!E:E,"BE"),0) -> 0 | D15: =IFERROR(COUNTIFS('1. Research Votes Log'!B:B,$A15,'1. Research Votes Log'!E:E,"CH"),0) -> 0 | E15: =IFERROR(COUNTIFS('1. Research Votes Log'!B:B,$A15,'1. Research Votes Log'!E:E,"CS"),0) -> 0 | F15: =IFERROR(COUNTIFS('1. Research Votes Log'!B:B,$A15,'1. Research Votes Log'!E:E,"ED"),0) -> 0 | G15: =IFERROR(COUNTIFS('1. Research Votes Log'!B:B,$A15,'1. Research Votes Log'!E:E,"EN"),0) -> 0 | H15: =IFERROR(COUNTIFS('1. Research Votes Log'!B:B,$A15,'1. Research Votes Log'!E:E,"LW"),0) -> 0 | I15: =IFERROR(COUNTIFS('1. Research Votes Log'!B:B,$A15,'1. Research Votes Log'!E:E,"LS"),0) -> 0 | J15: =IFERROR(COUNTIFS('1. Research Votes Log'!B:B,$A15,'1. Research Votes Log'!E:E,"PS"),0) -> 0 | K15: =IFERROR(COUNTIFS('1. Research Votes Log'!B:B,$A15,'1. Research Votes Log'!E:E,"PY"),0) -> 0 | L15: =IFERROR(COUNTIFS('1. Research Votes Log'!B:B,$A15,'1. Research Votes Log'!E:E,"SS"),0) -> 0 | M15: =SUM(B15:L15) -> 0 | N15: =COUNTIF(B15:L15,">0") -> 0 | O15: =IFERROR(N15/11*100,0) -> 0
B16: =IFERROR(COUNTIFS('1. Research Votes Log'!B:B,$A16,'1. Research Votes Log'!E:E,"AH"),0) -> 0 | C16: =IFERROR(COUNTIFS('1. Research Votes Log'!B:B,$A16,'1. Research Votes Log'!E:E,"BE"),0) -> 0 | D16: =IFERROR(COUNTIFS('1. Research Votes Log'!B:B,$A16,'1. Research Votes Log'!E:E,"CH"),0) -> 0 | E16: =IFERROR(COUNTIFS('1. Research Votes Log'!B:B,$A16,'1. Research Votes Log'!E:E,"CS"),0) -> 0 | F16: =IFERROR(COUNTIFS('1. Research Votes Log'!B:B,$A16,'1. Research Votes Log'!E:E,"ED"),0) -> 0 | G16: =IFERROR(COUNTIFS('1. Research Votes Log'!B:B,$A16,'1. Research Votes Log'!E:E,"EN"),0) -> 0 | H16: =IFERROR(COUNTIFS('1. Research Votes Log'!B:B,$A16,'1. Research Votes Log'!E:E,"LW"),0) -> 0 | I16: =IFERROR(COUNTIFS('1. Research Votes Log'!B:B,$A16,'1. Research Votes Log'!E:E,"LS"),0) -> 0 | J16: =IFERROR(COUNTIFS('1. Research Votes Log'!B:B,$A16,'1. Research Votes Log'!E:E,"PS"),0) -> 0 | K16: =IFERROR(COUNTIFS('1. Research Votes Log'!B:B,$A16,'1. Research Votes Log'!E:E,"PY"),0) -> 0 | L16: =IFERROR(COUNTIFS('1. Research Votes Log'!B:B,$A16,'1. Research Votes Log'!E:E,"SS"),0) -> 0 | M16: =SUM(B16:L16) -> 0 | N16: =COUNTIF(B16:L16,">0") -> 0 | O16: =IFERROR(N16/11*100,0) -> 0
... B34: =IFERROR(COUNTIFS('1. Research Votes Log'!B:B,$A34,'1. Research Votes Log'!E:E,"AH"),0) -> 0 | C34: =IFERROR(COUNTIFS('1. Research Votes Log'!B:B,$A34,'1. Research Votes Log'!E:E,"BE"),0) -> 0 | D34: =IFERROR(COUNTIFS('1. Research Votes Log'!B:B,$A34,'1. Research Votes Log'!E:E,"CH"),0) -> 0 | E34: =IFERROR(COUNTIFS('1. Research Votes Log'!B:B,$A34,'1. Research Votes Log'!E:E,"CS"),0) -> 0 | F34: =IFERROR(COUNTIFS('1. Research Votes Log'!B:B,$A34,'1. Research Votes Log'!E:E,"ED"),0) -> 0 | G34: =IFERROR(COUNTIFS('1. Research Votes Log'!B:B,$A34,'1. Research Votes Log'!E:E,"EN"),0) -> 0 | H34: =IFERROR(COUNTIFS('1. Research Votes Log'!B:B,$A34,'1. Research Votes Log'!E:E,"LW"),0) -> 0 | I34: =IFERROR(COUNTIFS('1. Research Votes Log'!B:B,$A34,'1. Research Votes Log'!E:E,"LS"),0) -> 0 | J34: =IFERROR(COUNTIFS('1. Research Votes Log'!B:B,$A34,'1. Research Votes Log'!E:E,"PS"),0) -> 0 | K34: =IFERROR(COUNTIFS('1. Research Votes Log'!B:B,$A34,'1. Research Votes Log'!E:E,"PY"),0) -> 0 | L34: =IFERROR(COUNTIFS('1. Research Votes Log'!B:B,$A34,'1. Research Votes Log'!E:E,"SS"),0) -> 0 | M34: =SUM(B34:L34) -> 0 | N34: =COUNTIF(B34:L34,">0") -> 0 | O34: =IFERROR(N34/11*100,0) -> 0

Sheet 4. Teaching Subject Matrix
A1: Teaching Votes: University × Subject Area Distribution
A2: Auto-populated from Teaching Votes Log — count of teaching votes per university per subject area
A4: University ↓ / Subject → | B4: AH | C4: BE | D4: CH | E4: CS | F4: ED | G4: EN | H4: LW | I4: LS | J4: PS | K4: PY | L4: SS | M4: Total Votes | N4: Unique Subjects | O4: Coverage %
B5: =IFERROR(COUNTIFS('2. Teaching Votes Log'!B:B,$A5,'2. Teaching Votes Log'!E:E,"AH"),0) -> 0 | C5: =IFERROR(COUNTIFS('2. Teaching Votes Log'!B:B,$A5,'2. Teaching Votes Log'!E:E,"BE"),0) -> 0 | D5: =IFERROR(COUNTIFS('2. Teaching Votes Log'!B:B,$A5,'2. Teaching Votes Log'!E:E,"CH"),0) -> 0 | E5: =IFERROR(COUNTIFS('2. Teaching Votes Log'!B:B,$A5,'2. Teaching Votes Log'!E:E,"CS"),0) -> 0 | F5: =IFERROR(COUNTIFS('2. Teaching Votes Log'!B:B,$A5,'2. Teaching Votes Log'!E:E,"ED"),0) -> 0 | G5: =IFERROR(COUNTIFS('2. Teaching Votes Log'!B:B,$A5,'2. Teaching Votes Log'!E:E,"EN"),0) -> 0 | H5: =IFERROR(COUNTIFS('2. Teaching Votes Log'!B:B,$A5,'2. Teaching Votes Log'!E:E,"LW"),0) -> 0 | I5: =IFERROR(COUNTIFS('2. Teaching Votes Log'!B:B,$A5,'2. Teaching Votes Log'!E:E,"LS"),0) -> 0 | J5: =IFERROR(COUNTIFS('2. Teaching Votes Log'!B:B,$A5,'2. Teaching Votes Log'!E:E,"PS"),0) -> 0 | K5: =IFERROR(COUNTIFS('2. Teaching Votes Log'!B:B,$A5,'2. Teaching Votes Log'!E:E,"PY"),0) -> 0 | L5: =IFERROR(COUNTIFS('2. Teaching Votes Log'!B:B,$A5,'2. Teaching Votes Log'!E:E,"SS"),0) -> 0 | M5: =SUM(B5:L5) -> 0 | N5: =COUNTIF(B5:L5,">0") -> 0 | O5: =IFERROR(N5/11*100,0) -> 0
B6: =IFERROR(COUNTIFS('2. Teaching Votes Log'!B:B,$A6,'2. Teaching Votes Log'!E:E,"AH"),0) -> 0 | C6: =IFERROR(COUNTIFS('2. Teaching Votes Log'!B:B,$A6,'2. Teaching Votes Log'!E:E,"BE"),0) -> 0 | D6: =IFERROR(COUNTIFS('2. Teaching Votes Log'!B:B,$A6,'2. Teaching Votes Log'!E:E,"CH"),0) -> 0 | E6: =IFERROR(COUNTIFS('2. Teaching Votes Log'!B:B,$A6,'2. Teaching Votes Log'!E:E,"CS"),0) -> 0 | F6: =IFERROR(COUNTIFS('2. Teaching Votes Log'!B:B,$A6,'2. Teaching Votes Log'!E:E,"ED"),0) -> 0 | G6: =IFERROR(COUNTIFS('2. Teaching Votes Log'!B:B,$A6,'2. Teaching Votes Log'!E:E,"EN"),0) -> 0 | H6: =IFERROR(COUNTIFS('2. Teaching Votes Log'!B:B,$A6,'2. Teaching Votes Log'!E:E,"LW"),0) -> 0 | I6: =IFERROR(COUNTIFS('2. Teaching Votes Log'!B:B,$A6,'2. Teaching Votes Log'!E:E,"LS"),0) -> 0 | J6: =IFERROR(COUNTIFS('2. Teaching Votes Log'!B:B,$A6,'2. Teaching Votes Log'!E:E,"PS"),0) -> 0 | K6: =IFERROR(COUNTIFS('2. Teaching Votes Log'!B:B,$A6,'2. Teaching Votes Log'!E:E,"PY"),0) -> 0 | L6: =IFERROR(COUNTIFS('2. Teaching Votes Log'!B:B,$A6,'2. Teaching Votes Log'!E:E,"SS"),0) -> 0 | M6: =SUM(B6:L6) -> 0 | N6: =COUNTIF(B6:L6,">0") -> 0 | O6: =IFERROR(N6/11*100,0) -> 0
B7: =IFERROR(COUNTIFS('2. Teaching Votes Log'!B:B,$A7,'2. Teaching Votes Log'!E:E,"AH"),0) -> 0 | C7: =IFERROR(COUNTIFS('2. Teaching Votes Log'!B:B,$A7,'2. Teaching Votes Log'!E:E,"BE"),0) -> 0 | D7: =IFERROR(COUNTIFS('2. Teaching Votes Log'!B:B,$A7,'2. Teaching Votes Log'!E:E,"CH"),0) -> 0 | E7: =IFERROR(COUNTIFS('2. Teaching Votes Log'!B:B,$A7,'2. Teaching Votes Log'!E:E,"CS"),0) -> 0 | F7: =IFERROR(COUNTIFS('2. Teaching Votes Log'!B:B,$A7,'2. Teaching Votes Log'!E:E,"ED"),0) -> 0 | G7: =IFERROR(COUNTIFS('2. Teaching Votes Log'!B:B,$A7,'2. Teaching Votes Log'!E:E,"EN"),0) -> 0 | H7: =IFERROR(COUNTIFS('2. Teaching Votes Log'!B:B,$A7,'2. Teaching Votes Log'!E:E,"LW"),0) -> 0 | I7: =IFERROR(COUNTIFS('2. Teaching Votes Log'!B:B,$A7,'2. Teaching Votes Log'!E:E,"LS"),0) -> 0 | J7: =IFERROR(COUNTIFS('2. Teaching Votes Log'!B:B,$A7,'2. Teaching Votes Log'!E:E,"PS"),0) -> 0 | K7: =IFERROR(COUNTIFS('2. Teaching Votes Log'!B:B,$A7,'2. Teaching Votes Log'!E:E,"PY"),0) -> 0 | L7: =IFERROR(COUNTIFS('2. Teaching Votes Log'!B:B,$A7,'2. Teaching Votes Log'!E:E,"SS"),0) -> 0 | M7: =SUM(B7:L7) -> 0 | N7: =COUNTIF(B7:L7,">0") -> 0 | O7: =IFERROR(N7/11*100,0) -> 0
B8: =IFERROR(COUNTIFS('2. Teaching Votes Log'!B:B,$A8,'2. Teaching Votes Log'!E:E,"AH"),0) -> 0 | C8: =IFERROR(COUNTIFS('2. Teaching Votes Log'!B:B,$A8,'2. Teaching Votes Log'!E:E,"BE"),0) -> 0 | D8: =IFERROR(COUNTIFS('2. Teaching Votes Log'!B:B,$A8,'2. Teaching Votes Log'!E:E,"CH"),0) -> 0 | E8: =IFERROR(COUNTIFS('2. Teaching Votes Log'!B:B,$A8,'2. Teaching Votes Log'!E:E,"CS"),0) -> 0 | F8: =IFERROR(COUNTIFS('2. Teaching Votes Log'!B:B,$A8,'2. Teaching Votes Log'!E:E,"ED"),0) -> 0 | G8: =IFERROR(COUNTIFS('2. Teaching Votes Log'!B:B,$A8,'2. Teaching Votes Log'!E:E,"EN"),0) -> 0 | H8: =IFERROR(COUNTIFS('2. Teaching Votes Log'!B:B,$A8,'2. Teaching Votes Log'!E:E,"LW"),0) -> 0 | I8: =IFERROR(COUNTIFS('2. Teaching Votes Log'!B:B,$A8,'2. Teaching Votes Log'!E:E,"LS"),0) -> 0 | J8: =IFERROR(COUNTIFS('2. Teaching Votes Log'!B:B,$A8,'2. Teaching Votes Log'!E:E,"PS"),0) -> 0 | K8: =IFERROR(COUNTIFS('2. Teaching Votes Log'!B:B,$A8,'2. Teaching Votes Log'!E:E,"PY"),0) -> 0 | L8: =IFERROR(COUNTIFS('2. Teaching Votes Log'!B:B,$A8,'2. Teaching Votes Log'!E:E,"SS"),0) -> 0 | M8: =SUM(B8:L8) -> 0 | N8: =COUNTIF(B8:L8,">0") -> 0 | O8: =IFERROR(N8/11*100,0) -> 0
B9: =IFERROR(COUNTIFS('2. Teaching Votes Log'!B:B,$A9,'2. Teaching Votes Log'!E:E,"AH"),0) -> 0 | C9: =IFERROR(COUNTIFS('2. Teaching Votes Log'!B:B,$A9,'2. Teaching Votes Log'!E:E,"BE"),0) -> 0 | D9: =IFERROR(COUNTIFS('2. Teaching Votes Log'!B:B,$A9,'2. Teaching Votes Log'!E:E,"CH"),0) -> 0 | E9: =IFERROR(COUNTIFS('2. Teaching Votes Log'!B:B,$A9,'2. Teaching Votes Log'!E:E,"CS"),0) -> 0 | F9: =IFERROR(COUNTIFS('2. Teaching Votes Log'!B:B,$A9,'2. Teaching Votes Log'!E:E,"ED"),0) -> 0 | G9: =IFERROR(COUNTIFS('2. Teaching Votes Log'!B:B,$A9,'2. Teaching Votes Log'!E:E,"EN"),0) -> 0 | H9: =IFERROR(COUNTIFS('2. Teaching Votes Log'!B:B,$A9,'2. Teaching Votes Log'!E:E,"LW"),0) -> 0 | I9: =IFERROR(COUNTIFS('2. Teaching Votes Log'!B:B,$A9,'2. Teaching Votes Log'!E:E,"LS"),0) -> 0 | J9: =IFERROR(COUNTIFS('2. Teaching Votes Log'!B:B,$A9,'2. Teaching Votes Log'!E:E,"PS"),0) -> 0 | K9: =IFERROR(COUNTIFS('2. Teaching Votes Log'!B:B,$A9,'2. Teaching Votes Log'!E:E,"PY"),0) -> 0 | L9: =IFERROR(COUNTIFS('2. Teaching Votes Log'!B:B,$A9,'2. Teaching Votes Log'!E:E,"SS"),0) -> 0 | M9: =SUM(B9:L9) -> 0 | N9: =COUNTIF(B9:L9,">0") -> 0 | O9: =IFERROR(N9/11*100,0) -> 0
B10: =IFERROR(COUNTIFS('2. Teaching Votes Log'!B:B,$A10,'2. Teaching Votes Log'!E:E,"AH"),0) -> 0 | C10: =IFERROR(COUNTIFS('2. Teaching Votes Log'!B:B,$A10,'2. Teaching Votes Log'!E:E,"BE"),0) -> 0 | D10: =IFERROR(COUNTIFS('2. Teaching Votes Log'!B:B,$A10,'2. Teaching Votes Log'!E:E,"CH"),0) -> 0 | E10: =IFERROR(COUNTIFS('2. Teaching Votes Log'!B:B,$A10,'2. Teaching Votes Log'!E:E,"CS"),0) -> 0 | F10: =IFERROR(COUNTIFS('2. Teaching Votes Log'!B:B,$A10,'2. Teaching Votes Log'!E:E,"ED"),0) -> 0 | G10: =IFERROR(COUNTIFS('2. Teaching Votes Log'!B:B,$A10,'2. Teaching Votes Log'!E:E,"EN"),0) -> 0 | H10: =IFERROR(COUNTIFS('2. Teaching Votes Log'!B:B,$A10,'2. Teaching Votes Log'!E:E,"LW"),0) -> 0 | I10: =IFERROR(COUNTIFS('2. Teaching Votes Log'!B:B,$A10,'2. Teaching Votes Log'!E:E,"LS"),0) -> 0 | J10: =IFERROR(COUNTIFS('2. Teaching Votes Log'!B:B,$A10,'2. Teaching Votes Log'!E:E,"PS"),0) -> 0 | K10: =IFERROR(COUNTIFS('2. Teaching Votes Log'!B:B,$A10,'2. Teaching Votes Log'!E:E,"PY"),0) -> 0 | L10: =IFERROR(COUNTIFS('2. Teaching Votes Log'!B:B,$A10,'2. Teaching Votes Log'!E:E,"SS"),0) -> 0 | M10: =SUM(B10:L10) -> 0 | N10: =COUNTIF(B10:L10,">0") -> 0 | O10: =IFERROR(N10/11*100,0) -> 0
B11: =IFERROR(COUNTIFS('2. Teaching Votes Log'!B:B,$A11,'2. Teaching Votes Log'!E:E,"AH"),0) -> 0 | C11: =IFERROR(COUNTIFS('2. Teaching Votes Log'!B:B,$A11,'2. Teaching Votes Log'!E:E,"BE"),0) -> 0 | D11: =IFERROR(COUNTIFS('2. Teaching Votes Log'!B:B,$A11,'2. Teaching Votes Log'!E:E,"CH"),0) -> 0 | E11: =IFERROR(COUNTIFS('2. Teaching Votes Log'!B:B,$A11,'2. Teaching Votes Log'!E:E,"CS"),0) -> 0 | F11: =IFERROR(COUNTIFS('2. Teaching Votes Log'!B:B,$A11,'2. Teaching Votes Log'!E:E,"ED"),0) -> 0 | G11: =IFERROR(COUNTIFS('2. Teaching Votes Log'!B:B,$A11,'2. Teaching Votes Log'!E:E,"EN"),0) -> 0 | H11: =IFERROR(COUNTIFS('2. Teaching Votes Log'!B:B,$A11,'2. Teaching Votes Log'!E:E,"LW"),0) -> 0 | I11: =IFERROR(COUNTIFS('2. Teaching Votes Log'!B:B,$A11,'2. Teaching Votes Log'!E:E,"LS"),0) -> 0 | J11: =IFERROR(COUNTIFS('2. Teaching Votes Log'!B:B,$A11,'2. Teaching Votes Log'!E:E,"PS"),0) -> 0 | K11: =IFERROR(COUNTIFS('2. Teaching Votes Log'!B:B,$A11,'2. Teaching Votes Log'!E:E,"PY"),0) -> 0 | L11: =IFERROR(COUNTIFS('2. Teaching Votes Log'!B:B,$A11,'2. Teaching Votes Log'!E:E,"SS"),0) -> 0 | M11: =SUM(B11:L11) -> 0 | N11: =COUNTIF(B11:L11,">0") -> 0 | O11: =IFERROR(N11/11*100,0) -> 0
B12: =IFERROR(COUNTIFS('2. Teaching Votes Log'!B:B,$A12,'2. Teaching Votes Log'!E:E,"AH"),0) -> 0 | C12: =IFERROR(COUNTIFS('2. Teaching Votes Log'!B:B,$A12,'2. Teaching Votes Log'!E:E,"BE"),0) -> 0 | D12: =IFERROR(COUNTIFS('2. Teaching Votes Log'!B:B,$A12,'2. Teaching Votes Log'!E:E,"CH"),0) -> 0 | E12: =IFERROR(COUNTIFS('2. Teaching Votes Log'!B:B,$A12,'2. Teaching Votes Log'!E:E,"CS"),0) -> 0 | F12: =IFERROR(COUNTIFS('2. Teaching Votes Log'!B:B,$A12,'2. Teaching Votes Log'!E:E,"ED"),0) -> 0 | G12: =IFERROR(COUNTIFS('2. Teaching Votes Log'!B:B,$A12,'2. Teaching Votes Log'!E:E,"EN"),0) -> 0 | H12: =IFERROR(COUNTIFS('2. Teaching Votes Log'!B:B,$A12,'2. Teaching Votes Log'!E:E,"LW"),0) -> 0 | I12: =IFERROR(COUNTIFS('2. Teaching Votes Log'!B:B,$A12,'2. Teaching Votes Log'!E:E,"LS"),0) -> 0 | J12: =IFERROR(COUNTIFS('2. Teaching Votes Log'!B:B,$A12,'2. Teaching Votes Log'!E:E,"PS"),0) -> 0 | K12: =IFERROR(COUNTIFS('2. Teaching Votes Log'!B:B,$A12,'2. Teaching Votes Log'!E:E,"PY"),0) -> 0 | L12: =IFERROR(COUNTIFS('2. Teaching Votes Log'!B:B,$A12,'2. Teaching Votes Log'!E:E,"SS"),0) -> 0 | M12: =SUM(B12:L12) -> 0 | N12: =COUNTIF(B12:L12,">0") -> 0 | O12: =IFERROR(N12/11*100,0) -> 0
B13: =IFERROR(COUNTIFS('2. Teaching Votes Log'!B:B,$A13,'2. Teaching Votes Log'!E:E,"AH"),0) -> 0 | C13: =IFERROR(COUNTIFS('2. Teaching Votes Log'!B:B,$A13,'2. Teaching Votes Log'!E:E,"BE"),0) -> 0 | D13: =IFERROR(COUNTIFS('2. Teaching Votes Log'!B:B,$A13,'2. Teaching Votes Log'!E:E,"CH"),0) -> 0 | E13: =IFERROR(COUNTIFS('2. Teaching Votes Log'!B:B,$A13,'2. Teaching Votes Log'!E:E,"CS"),0) -> 0 | F13: =IFERROR(COUNTIFS('2. Teaching Votes Log'!B:B,$A13,'2. Teaching Votes Log'!E:E,"ED"),0) -> 0 | G13: =IFERROR(COUNTIFS('2. Teaching Votes Log'!B:B,$A13,'2. Teaching Votes Log'!E:E,"EN"),0) -> 0 | H13: =IFERROR(COUNTIFS('2. Teaching Votes Log'!B:B,$A13,'2. Teaching Votes Log'!E:E,"LW"),0) -> 0 | I13: =IFERROR(COUNTIFS('2. Teaching Votes Log'!B:B,$A13,'2. Teaching Votes Log'!E:E,"LS"),0) -> 0 | J13: =IFERROR(COUNTIFS('2. Teaching Votes Log'!B:B,$A13,'2. Teaching Votes Log'!E:E,"PS"),0) -> 0 | K13: =IFERROR(COUNTIFS('2. Teaching Votes Log'!B:B,$A13,'2. Teaching Votes Log'!E:E,"PY"),0) -> 0 | L13: =IFERROR(COUNTIFS('2. Teaching Votes Log'!B:B,$A13,'2. Teaching Votes Log'!E:E,"SS"),0) -> 0 | M13: =SUM(B13:L13) -> 0 | N13: =COUNTIF(B13:L13,">0") -> 0 | O13: =IFERROR(N13/11*100,0) -> 0
B14: =IFERROR(COUNTIFS('2. Teaching Votes Log'!B:B,$A14,'2. Teaching Votes Log'!E:E,"AH"),0) -> 0 | C14: =IFERROR(COUNTIFS('2. Teaching Votes Log'!B:B,$A14,'2. Teaching Votes Log'!E:E,"BE"),0) -> 0 | D14: =IFERROR(COUNTIFS('2. Teaching Votes Log'!B:B,$A14,'2. Teaching Votes Log'!E:E,"CH"),0) -> 0 | E14: =IFERROR(COUNTIFS('2. Teaching Votes Log'!B:B,$A14,'2. Teaching Votes Log'!E:E,"CS"),0) -> 0 | F14: =IFERROR(COUNTIFS('2. Teaching Votes Log'!B:B,$A14,'2. Teaching Votes Log'!E:E,"ED"),0) -> 0 | G14: =IFERROR(COUNTIFS('2. Teaching Votes Log'!B:B,$A14,'2. Teaching Votes Log'!E:E,"EN"),0) -> 0 | H14: =IFERROR(COUNTIFS('2. Teaching Votes Log'!B:B,$A14,'2. Teaching Votes Log'!E:E,"LW"),0) -> 0 | I14: =IFERROR(COUNTIFS('2. Teaching Votes Log'!B:B,$A14,'2. Teaching Votes Log'!E:E,"LS"),0) -> 0 | J14: =IFERROR(COUNTIFS('2. Teaching Votes Log'!B:B,$A14,'2. Teaching Votes Log'!E:E,"PS"),0) -> 0 | K14: =IFERROR(COUNTIFS('2. Teaching Votes Log'!B:B,$A14,'2. Teaching Votes Log'!E:E,"PY"),0) -> 0 | L14: =IFERROR(COUNTIFS('2. Teaching Votes Log'!B:B,$A14,'2. Teaching Votes Log'!E:E,"SS"),0) -> 0 | M14: =SUM(B14:L14) -> 0 | N14: =COUNTIF(B14:L14,">0") -> 0 | O14: =IFERROR(N14/11*100,0) -> 0
B15: =IFERROR(COUNTIFS('2. Teaching Votes Log'!B:B,$A15,'2. Teaching Votes Log'!E:E,"AH"),0) -> 0 | C15: =IFERROR(COUNTIFS('2. Teaching Votes Log'!B:B,$A15,'2. Teaching Votes Log'!E:E,"BE"),0) -> 0 | D15: =IFERROR(COUNTIFS('2. Teaching Votes Log'!B:B,$A15,'2. Teaching Votes Log'!E:E,"CH"),0) -> 0 | E15: =IFERROR(COUNTIFS('2. Teaching Votes Log'!B:B,$A15,'2. Teaching Votes Log'!E:E,"CS"),0) -> 0 | F15: =IFERROR(COUNTIFS('2. Teaching Votes Log'!B:B,$A15,'2. Teaching Votes Log'!E:E,"ED"),0) -> 0 | G15: =IFERROR(COUNTIFS('2. Teaching Votes Log'!B:B,$A15,'2. Teaching Votes Log'!E:E,"EN"),0) -> 0 | H15: =IFERROR(COUNTIFS('2. Teaching Votes Log'!B:B,$A15,'2. Teaching Votes Log'!E:E,"LW"),0) -> 0 | I15: =IFERROR(COUNTIFS('2. Teaching Votes Log'!B:B,$A15,'2. Teaching Votes Log'!E:E,"LS"),0) -> 0 | J15: =IFERROR(COUNTIFS('2. Teaching Votes Log'!B:B,$A15,'2. Teaching Votes Log'!E:E,"PS"),0) -> 0 | K15: =IFERROR(COUNTIFS('2. Teaching Votes Log'!B:B,$A15,'2. Teaching Votes Log'!E:E,"PY"),0) -> 0 | L15: =IFERROR(COUNTIFS('2. Teaching Votes Log'!B:B,$A15,'2. Teaching Votes Log'!E:E,"SS"),0) -> 0 | M15: =SUM(B15:L15) -> 0 | N15: =COUNTIF(B15:L15,">0") -> 0 | O15: =IFERROR(N15/11*100,0) -> 0
B16: =IFERROR(COUNTIFS('2. Teaching Votes Log'!B:B,$A16,'2. Teaching Votes Log'!E:E,"AH"),0) -> 0 | C16: =IFERROR(COUNTIFS('2. Teaching Votes Log'!B:B,$A16,'2. Teaching Votes Log'!E:E,"BE"),0) -> 0 | D16: =IFERROR(COUNTIFS('2. Teaching Votes Log'!B:B,$A16,'2. Teaching Votes Log'!E:E,"CH"),0) -> 0 | E16: =IFERROR(COUNTIFS('2. Teaching Votes Log'!B:B,$A16,'2. Teaching Votes Log'!E:E,"CS"),0) -> 0 | F16: =IFERROR(COUNTIFS('2. Teaching Votes Log'!B:B,$A16,'2. Teaching Votes Log'!E:E,"ED"),0) -> 0 | G16: =IFERROR(COUNTIFS('2. Teaching Votes Log'!B:B,$A16,'2. Teaching Votes Log'!E:E,"EN"),0) -> 0 | H16: =IFERROR(COUNTIFS('2. Teaching Votes Log'!B:B,$A16,'2. Teaching Votes Log'!E:E,"LW"),0) -> 0 | I16: =IFERROR(COUNTIFS('2. Teaching Votes Log'!B:B,$A16,'2. Teaching Votes Log'!E:E,"LS"),0) -> 0 | J16: =IFERROR(COUNTIFS('2. Teaching Votes Log'!B:B,$A16,'2. Teaching Votes Log'!E:E,"PS"),0) -> 0 | K16: =IFERROR(COUNTIFS('2. Teaching Votes Log'!B:B,$A16,'2. Teaching Votes Log'!E:E,"PY"),0) -> 0 | L16: =IFERROR(COUNTIFS('2. Teaching Votes Log'!B:B,$A16,'2. Teaching Votes Log'!E:E,"SS"),0) -> 0 | M16: =SUM(B16:L16) -> 0 | N16: =COUNTIF(B16:L16,">0") -> 0 | O16: =IFERROR(N16/11*100,0) -> 0
... B34: =IFERROR(COUNTIFS('2. Teaching Votes Log'!B:B,$A34,'2. Teaching Votes Log'!E:E,"AH"),0) -> 0 | C34: =IFERROR(COUNTIFS('2. Teaching Votes Log'!B:B,$A34,'2. Teaching Votes Log'!E:E,"BE"),0) -> 0 | D34: =IFERROR(COUNTIFS('2. Teaching Votes Log'!B:B,$A34,'2. Teaching Votes Log'!E:E,"CH"),0) -> 0 | E34: =IFERROR(COUNTIFS('2. Teaching Votes Log'!B:B,$A34,'2. Teaching Votes Log'!E:E,"CS"),0) -> 0 | F34: =IFERROR(COUNTIFS('2. Teaching Votes Log'!B:B,$A34,'2. Teaching Votes Log'!E:E,"ED"),0) -> 0 | G34: =IFERROR(COUNTIFS('2. Teaching Votes Log'!B:B,$A34,'2. Teaching Votes Log'!E:E,"EN"),0) -> 0 | H34: =IFERROR(COUNTIFS('2. Teaching Votes Log'!B:B,$A34,'2. Teaching Votes Log'!E:E,"LW"),0) -> 0 | I34: =IFERROR(COUNTIFS('2. Teaching Votes Log'!B:B,$A34,'2. Teaching Votes Log'!E:E,"LS"),0) -> 0 | J34: =IFERROR(COUNTIFS('2. Teaching Votes Log'!B:B,$A34,'2. Teaching Votes Log'!E:E,"PS"),0) -> 0 | K34: =IFERROR(COUNTIFS('2. Teaching Votes Log'!B:B,$A34,'2. Teaching Votes Log'!E:E,"PY"),0) -> 0 | L34: =IFERROR(COUNTIFS('2. Teaching Votes Log'!B:B,$A34,'2. Teaching Votes Log'!E:E,"SS"),0) -> 0 | M34: =SUM(B34:L34) -> 0 | N34: =COUNTIF(B34:L34,">0") -> 0 | O34: =IFERROR(N34/11*100,0) -> 0

Sheet 5. Research Subject Entropy
A1: Research Subject Entropy — Per-University Calculation
A2: H_subj = −Σ pⱼ × log₂(pⱼ) computed from Research Subject Matrix | Max H = log₂(11) ≈ 3.459
A3: S.No. | B3: University Name | C3: Total Res. Votes | D3: Unique Subjects (of 11) | E3: Subject Entropy H (bits) | F3: Max Entropy log₂(11) | G3: Normalized Entropy (H/Hmax) | H3: Subject Diversity Score (0–100) | I3: Diversity Tier
A4: 1 | C4: =IFERROR('3. Research Subject Matrix'!M5,0) -> 0 | D4: =IFERROR('3. Research Subject Matrix'!N5,0) -> 0 | E4: =IFERROR(IF(C4>0,-SUMPRODUCT(IF('3. Research Subject Matrix'!B5:L5>0,('3. Research Subject Matrix'!B5:L5/C4)*LOG('3. Research Subject Matrix'!B5:L5/C4,2),0)),0),0) -> 0 | F4: =IF(D4>1,LOG(D4,2),0) -> 0 | G4: =IFERROR(IF(F4>0,E4/F4,0),0) -> 0 | H4: =IFERROR(IF(MAX($E$4:$E$33)>0,E4/MAX($E$4:$E$33)*100,0),0) -> 0 | I4: =IF(H4>=80,"Very High",IF(H4>=60,"High",IF(H4>=40,"Medium",IF(H4>=20,"Low","Very Low")))) -> Very Low
A5: 2 | C5: =IFERROR('3. Research Subject Matrix'!M6,0) -> 0 | D5: =IFERROR('3. Research Subject Matrix'!N6,0) -> 0 | E5: =IFERROR(IF(C5>0,-SUMPRODUCT(IF('3. Research Subject Matrix'!B6:L6>0,('3. Research Subject Matrix'!B6:L6/C5)*LOG('3. Research Subject Matrix'!B6:L6/C5,2),0)),0),0) -> 0 | F5: =IF(D5>1,LOG(D5,2),0) -> 0 | G5: =IFERROR(IF(F5>0,E5/F5,0),0) -> 0 | H5: =IFERROR(IF(MAX($E$4:$E$33)>0,E5/MAX($E$4:$E$33)*100,0),0) -> 0 | I5: =IF(H5>=80,"Very High",IF(H5>=60,"High",IF(H5>=40,"Medium",IF(H5>=20,"Low","Very Low")))) -> Very Low
A6: 3 | C6: =IFERROR('3. Research Subject Matrix'!M7,0) -> 0 | D6: =IFERROR('3. Research Subject Matrix'!N7,0) -> 0 | E6: =IFERROR(IF(C6>0,-SUMPRODUCT(IF('3. Research Subject Matrix'!B7:L7>0,('3. Research Subject Matrix'!B7:L7/C6)*LOG('3. Research Subject Matrix'!B7:L7/C6,2),0)),0),0) -> 0 | F6: =IF(D6>1,LOG(D6,2),0) -> 0 | G6: =IFERROR(IF(F6>0,E6/F6,0),0) -> 0 | H6: =IFERROR(IF(MAX($E$4:$E$33)>0,E6/MAX($E$4:$E$33)*100,0),0) -> 0 | I6: =IF(H6>=80,"Very High",IF(H6>=60,"High",IF(H6>=40,"Medium",IF(H6>=20,"Low","Very Low")))) -> Very Low
A7: 4 | C7: =IFERROR('3. Research Subject Matrix'!M8,0) -> 0 | D7: =IFERROR('3. Research Subject Matrix'!N8,0) -> 0 | E7: =IFERROR(IF(C7>0,-SUMPRODUCT(IF('3. Research Subject Matrix'!B8:L8>0,('3. Research Subject Matrix'!B8:L8/C7)*LOG('3. Research Subject Matrix'!B8:L8/C7,2),0)),0),0) -> 0 | F7: =IF(D7>1,LOG(D7,2),0) -> 0 | G7: =IFERROR(IF(F7>0,E7/F7,0),0) -> 0 | H7: =IFERROR(IF(MAX($E$4:$E$33)>0,E7/MAX($E$4:$E$33)*100,0),0) -> 0 | I7: =IF(H7>=80,"Very High",IF(H7>=60,"High",IF(H7>=40,"Medium",IF(H7>=20,"Low","Very Low")))) -> Very Low
A8: 5 | C8: =IFERROR('3. Research Subject Matrix'!M9,0) -> 0 | D8: =IFERROR('3. Research Subject Matrix'!N9,0) -> 0 | E8: =IFERROR(IF(C8>0,-SUMPRODUCT(IF('3. Research Subject Matrix'!B9:L9>0,('3. Research Subject Matrix'!B9:L9/C8)*LOG('3. Research Subject Matrix'!B9:L9/C8,2),0)),0),0) -> 0 | F8: =IF(D8>1,LOG(D8,2),0) -> 0 | G8: =IFERROR(IF(F8>0,E8/F8,0),0) -> 0 | H8: =IFERROR(IF(MAX($E$4:$E$33)>0,E8/MAX($E$4:$E$33)*100,0),0) -> 0 | I8: =IF(H8>=80,"Very High",IF(H8>=60,"High",IF(H8>=40,"Medium",IF(H8>=20,"Low","Very Low")))) -> Very Low
A9: 6 | C9: =IFERROR('3. Research Subject Matrix'!M10,0) -> 0 | D9: =IFERROR('3. Research Subject Matrix'!N10,0) -> 0 | E9: =IFERROR(IF(C9>0,-SUMPRODUCT(IF('3. Research Subject Matrix'!B10:L10>0,('3. Research Subject Matrix'!B10:L10/C9)*LOG('3. Research Subject Matrix'!B10:L10/C9,2),0)),0),0) -> 0 | F9: =IF(D9>1,LOG(D9,2),0) -> 0 | G9: =IFERROR(IF(F9>0,E9/F9,0),0) -> 0 | H9: =IFERROR(IF(MAX($E$4:$E$33)>0,E9/MAX($E$4:$E$33)*100,0),0) -> 0 | I9: =IF(H9>=80,"Very High",IF(H9>=60,"High",IF(H9>=40,"Medium",IF(H9>=20,"Low","Very Low")))) -> Very Low
A10: 7 | C10: =IFERROR('3. Research Subject Matrix'!M11,0) -> 0 | D10: =IFERROR('3. Research Subject Matrix'!N11,0) -> 0 | E10: =IFERROR(IF(C10>0,-SUMPRODUCT(IF('3. Research Subject Matrix'!B11:L11>0,('3. Research Subject Matrix'!B11:L11/C10)*LOG('3. Research Subject Matrix'!B11:L11/C10,2),0)),0),0) -> 0 | F10: =IF(D10>1,LOG(D10,2),0) -> 0 | G10: =IFERROR(IF(F10>0,E10/F10,0),0) -> 0 | H10: =IFERROR(IF(MAX($E$4:$E$33)>0,E10/MAX($E$4:$E$33)*100,0),0) -> 0 | I10: =IF(H10>=80,"Very High",IF(H10>=60,"High",IF(H10>=40,"Medium",IF(H10>=20,"Low","Very Low")))) -> Very Low
A11: 8 | C11: =IFERROR('3. Research Subject Matrix'!M12,0) -> 0 | D11: =IFERROR('3. Research Subject Matrix'!N12,0) -> 0 | E11: =IFERROR(IF(C11>0,-SUMPRODUCT(IF('3. Research Subject Matrix'!B12:L12>0,('3. Research Subject Matrix'!B12:L12/C11)*LOG('3. Research Subject Matrix'!B12:L12/C11,2),0)),0),0) -> 0 | F11: =IF(D11>1,LOG(D11,2),0) -> 0 | G11: =IFERROR(IF(F11>0,E11/F11,0),0) -> 0 | H11: =IFERROR(IF(MAX($E$4:$E$33)>0,E11/MAX($E$4:$E$33)*100,0),0) -> 0 | I11: =IF(H11>=80,"Very High",IF(H11>=60,"High",IF(H11>=40,"Medium",IF(H11>=20,"Low","Very Low")))) -> Very Low
A12: 9 | C12: =IFERROR('3. Research Subject Matrix'!M13,0) -> 0 | D12: =IFERROR('3. Research Subject Matrix'!N13,0) -> 0 | E12: =IFERROR(IF(C12>0,-SUMPRODUCT(IF('3. Research Subject Matrix'!B13:L13>0,('3. Research Subject Matrix'!B13:L13/C12)*LOG('3. Research Subject Matrix'!B13:L13/C12,2),0)),0),0) -> 0 | F12: =IF(D12>1,LOG(D12,2),0) -> 0 | G12: =IFERROR(IF(F12>0,E12/F12,0),0) -> 0 | H12: =IFERROR(IF(MAX($E$4:$E$33)>0,E12/MAX($E$4:$E$33)*100,0),0) -> 0 | I12: =IF(H12>=80,"Very High",IF(H12>=60,"High",IF(H12>=40,"Medium",IF(H12>=20,"Low","Very Low")))) -> Very Low
A13: 10 | C13: =IFERROR('3. Research Subject Matrix'!M14,0) -> 0 | D13: =IFERROR('3. Research Subject Matrix'!N14,0) -> 0 | E13: =IFERROR(IF(C13>0,-SUMPRODUCT(IF('3. Research Subject Matrix'!B14:L14>0,('3. Research Subject Matrix'!B14:L14/C13)*LOG('3. Research Subject Matrix'!B14:L14/C13,2),0)),0),0) -> 0 | F13: =IF(D13>1,LOG(D13,2),0) -> 0 | G13: =IFERROR(IF(F13>0,E13/F13,0),0) -> 0 | H13: =IFERROR(IF(MAX($E$4:$E$33)>0,E13/MAX($E$4:$E$33)*100,0),0) -> 0 | I13: =IF(H13>=80,"Very High",IF(H13>=60,"High",IF(H13>=40,"Medium",IF(H13>=20,"Low","Very Low")))) -> Very Low
A14: 11 | C14: =IFERROR('3. Research Subject Matrix'!M15,0) -> 0 | D14: =IFERROR('3. Research Subject Matrix'!N15,0) -> 0 | E14: =IFERROR(IF(C14>0,-SUMPRODUCT(IF('3. Research Subject Matrix'!B15:L15>0,('3. Research Subject Matrix'!B15:L15/C14)*LOG('3. Research Subject Matrix'!B15:L15/C14,2),0)),0),0) -> 0 | F14: =IF(D14>1,LOG(D14,2),0) -> 0 | G14: =IFERROR(IF(F14>0,E14/F14,0),0) -> 0 | H14: =IFERROR(IF(MAX($E$4:$E$33)>0,E14/MAX($E$4:$E$33)*100,0),0) -> 0 | I14: =IF(H14>=80,"Very High",IF(H14>=60,"High",IF(H14>=40,"Medium",IF(H14>=20,"Low","Very Low")))) -> Very Low
A15: 12 | C15: =IFERROR('3. Research Subject Matrix'!M16,0) -> 0 | D15: =IFERROR('3. Research Subject Matrix'!N16,0) -> 0 | E15: =IFERROR(IF(C15>0,-SUMPRODUCT(IF('3. Research Subject Matrix'!B16:L16>0,('3. Research Subject Matrix'!B16:L16/C15)*LOG('3. Research Subject Matrix'!B16:L16/C15,2),0)),0),0) -> 0 | F15: =IF(D15>1,LOG(D15,2),0) -> 0 | G15: =IFERROR(IF(F15>0,E15/F15,0),0) -> 0 | H15: =IFERROR(IF(MAX($E$4:$E$33)>0,E15/MAX($E$4:$E$33)*100,0),0) -> 0 | I15: =IF(H15>=80,"Very High",IF(H15>=60,"High",IF(H15>=40,"Medium",IF(H15>=20,"Low","Very Low")))) -> Very Low
... A33: 30 | C33: =IFERROR('3. Research Subject Matrix'!M34,0) -> 0 | D33: =IFERROR('3. Research Subject Matrix'!N34,0) -> 0 | E33: =IFERROR(IF(C33>0,-SUMPRODUCT(IF('3. Research Subject Matrix'!B34:L34>0,('3. Research Subject Matrix'!B34:L34/C33)*LOG('3. Research Subject Matrix'!B34:L34/C33,2),0)),0),0) -> 0 | F33: =IF(D33>1,LOG(D33,2),0) -> 0 | G33: =IFERROR(IF(F33>0,E33/F33,0),0) -> 0 | H33: =IFERROR(IF(MAX($E$4:$E$33)>0,E33/MAX($E$4:$E$33)*100,0),0) -> 0 | I33: =IF(H33>=80,"Very High",IF(H33>=60,"High",IF(H33>=40,"Medium",IF(H33>=20,"Low","Very Low")))) -> Very Low

Sheet 6. Teaching Subject Entropy
A1: Teaching Subject Entropy — Per-University Calculation
A2: H_subj = −Σ pⱼ × log₂(pⱼ) computed from Teaching Subject Matrix | Max H = log₂(11) ≈ 3.459
A3: S.No. | B3: University Name | C3: Total Tch. Votes | D3: Unique Subjects (of 11) | E3: Subject Entropy H (bits) | F3: Max Entropy log₂(11) | G3: Normalized Entropy (H/Hmax) | H3: Subject Diversity Score (0–100) | I3: Diversity Tier
A4: 1 | C4: =IFERROR('4. Teaching Subject Matrix'!M5,0) -> 0 | D4: =IFERROR('4. Teaching Subject Matrix'!N5,0) -> 0 | E4: =IFERROR(IF(C4>0,-SUMPRODUCT(IF('4. Teaching Subject Matrix'!B5:L5>0,('4. Teaching Subject Matrix'!B5:L5/C4)*LOG('4. Teaching Subject Matrix'!B5:L5/C4,2),0)),0),0) -> 0 | F4: =IF(D4>1,LOG(D4,2),0) -> 0 | G4: =IFERROR(IF(F4>0,E4/F4,0),0) -> 0 | H4: =IFERROR(IF(MAX($E$4:$E$33)>0,E4/MAX($E$4:$E$33)*100,0),0) -> 0 | I4: =IF(H4>=80,"Very High",IF(H4>=60,"High",IF(H4>=40,"Medium",IF(H4>=20,"Low","Very Low")))) -> Very Low
A5: 2 | C5: =IFERROR('4. Teaching Subject Matrix'!M6,0) -> 0 | D5: =IFERROR('4. Teaching Subject Matrix'!N6,0) -> 0 | E5: =IFERROR(IF(C5>0,-SUMPRODUCT(IF('4. Teaching Subject Matrix'!B6:L6>0,('4. Teaching Subject Matrix'!B6:L6/C5)*LOG('4. Teaching Subject Matrix'!B6:L6/C5,2),0)),0),0) -> 0 | F5: =IF(D5>1,LOG(D5,2),0) -> 0 | G5: =IFERROR(IF(F5>0,E5/F5,0),0) -> 0 | H5: =IFERROR(IF(MAX($E$4:$E$33)>0,E5/MAX($E$4:$E$33)*100,0),0) -> 0 | I5: =IF(H5>=80,"Very High",IF(H5>=60,"High",IF(H5>=40,"Medium",IF(H5>=20,"Low","Very Low")))) -> Very Low
A6: 3 | C6: =IFERROR('4. Teaching Subject Matrix'!M7,0) -> 0 | D6: =IFERROR('4. Teaching Subject Matrix'!N7,0) -> 0 | E6: =IFERROR(IF(C6>0,-SUMPRODUCT(IF('4. Teaching Subject Matrix'!B7:L7>0,('4. Teaching Subject Matrix'!B7:L7/C6)*LOG('4. Teaching Subject Matrix'!B7:L7/C6,2),0)),0),0) -> 0 | F6: =IF(D6>1,LOG(D6,2),0) -> 0 | G6: =IFERROR(IF(F6>0,E6/F6,0),0) -> 0 | H6: =IFERROR(IF(MAX($E$4:$E$33)>0,E6/MAX($E$4:$E$33)*100,0),0) -> 0 | I6: =IF(H6>=80,"Very High",IF(H6>=60,"High",IF(H6>=40,"Medium",IF(H6>=20,"Low","Very Low")))) -> Very Low
A7: 4 | C7: =IFERROR('4. Teaching Subject Matrix'!M8,0) -> 0 | D7: =IFERROR('4. Teaching Subject Matrix'!N8,0) -> 0 | E7: =IFERROR(IF(C7>0,-SUMPRODUCT(IF('4. Teaching Subject Matrix'!B8:L8>0,('4. Teaching Subject Matrix'!B8:L8/C7)*LOG('4. Teaching Subject Matrix'!B8:L8/C7,2),0)),0),0) -> 0 | F7: =IF(D7>1,LOG(D7,2),0) -> 0 | G7: =IFERROR(IF(F7>0,E7/F7,0),0) -> 0 | H7: =IFERROR(IF(MAX($E$4:$E$33)>0,E7/MAX($E$4:$E$33)*100,0),0) -> 0 | I7: =IF(H7>=80,"Very High",IF(H7>=60,"High",IF(H7>=40,"Medium",IF(H7>=20,"Low","Very Low")))) -> Very Low
A8: 5 | C8: =IFERROR('4. Teaching Subject Matrix'!M9,0) -> 0 | D8: =IFERROR('4. Teaching Subject Matrix'!N9,0) -> 0 | E8: =IFERROR(IF(C8>0,-SUMPRODUCT(IF('4. Teaching Subject Matrix'!B9:L9>0,('4. Teaching Subject Matrix'!B9:L9/C8)*LOG('4. Teaching Subject Matrix'!B9:L9/C8,2),0)),0),0) -> 0 | F8: =IF(D8>1,LOG(D8,2),0) -> 0 | G8: =IFERROR(IF(F8>0,E8/F8,0),0) -> 0 | H8: =IFERROR(IF(MAX($E$4:$E$33)>0,E8/MAX($E$4:$E$33)*100,0),0) -> 0 | I8: =IF(H8>=80,"Very High",IF(H8>=60,"High",IF(H8>=40,"Medium",IF(H8>=20,"Low","Very Low")))) -> Very Low
A9: 6 | C9: =IFERROR('4. Teaching Subject Matrix'!M10,0) -> 0 | D9: =IFERROR('4. Teaching Subject Matrix'!N10,0) -> 0 | E9: =IFERROR(IF(C9>0,-SUMPRODUCT(IF('4. Teaching Subject Matrix'!B10:L10>0,('4. Teaching Subject Matrix'!B10:L10/C9)*LOG('4. Teaching Subject Matrix'!B10:L10/C9,2),0)),0),0) -> 0 | F9: =IF(D9>1,LOG(D9,2),0) -> 0 | G9: =IFERROR(IF(F9>0,E9/F9,0),0) -> 0 | H9: =IFERROR(IF(MAX($E$4:$E$33)>0,E9/MAX($E$4:$E$33)*100,0),0) -> 0 | I9: =IF(H9>=80,"Very High",IF(H9>=60,"High",IF(H9>=40,"Medium",IF(H9>=20,"Low","Very Low")))) -> Very Low
A10: 7 | C10: =IFERROR('4. Teaching Subject Matrix'!M11,0) -> 0 | D10: =IFERROR('4. Teaching Subject Matrix'!N11,0) -> 0 | E10: =IFERROR(IF(C10>0,-SUMPRODUCT(IF('4. Teaching Subject Matrix'!B11:L11>0,('4. Teaching Subject Matrix'!B11:L11/C10)*LOG('4. Teaching Subject Matrix'!B11:L11/C10,2),0)),0),0) -> 0 | F10: =IF(D10>1,LOG(D10,2),0) -> 0 | G10: =IFERROR(IF(F10>0,E10/F10,0),0) -> 0 | H10: =IFERROR(IF(MAX($E$4:$E$33)>0,E10/MAX($E$4:$E$33)*100,0),0) -> 0 | I10: =IF(H10>=80,"Very High",IF(H10>=60,"High",IF(H10>=40,"Medium",IF(H10>=20,"Low","Very Low")))) -> Very Low
A11: 8 | C11: =IFERROR('4. Teaching Subject Matrix'!M12,0) -> 0 | D11: =IFERROR('4. Teaching Subject Matrix'!N12,0) -> 0 | E11: =IFERROR(IF(C11>0,-SUMPRODUCT(IF('4. Teaching Subject Matrix'!B12:L12>0,('4. Teaching Subject Matrix'!B12:L12/C11)*LOG('4. Teaching Subject Matrix'!B12:L12/C11,2),0)),0),0) -> 0 | F11: =IF(D11>1,LOG(D11,2),0) -> 0 | G11: =IFERROR(IF(F11>0,E11/F11,0),0) -> 0 | H11: =IFERROR(IF(MAX($E$4:$E$33)>0,E11/MAX($E$4:$E$33)*100,0),0) -> 0 | I11: =IF(H11>=80,"Very High",IF(H11>=60,"High",IF(H11>=40,"Medium",IF(H11>=20,"Low","Very Low")))) -> Very Low
A12: 9 | C12: =IFERROR('4. Teaching Subject Matrix'!M13,0) -> 0 | D12: =IFERROR('4. Teaching Subject Matrix'!N13,0) -> 0 | E12: =IFERROR(IF(C12>0,-SUMPRODUCT(IF('4. Teaching Subject Matrix'!B13:L13>0,('4. Teaching Subject Matrix'!B13:L13/C12)*LOG('4. Teaching Subject Matrix'!B13:L13/C12,2),0)),0),0) -> 0 | F12: =IF(D12>1,LOG(D12,2),0) -> 0 | G12: =IFERROR(IF(F12>0,E12/F12,0),0) -> 0 | H12: =IFERROR(IF(MAX($E$4:$E$33)>0,E12/MAX($E$4:$E$33)*100,0),0) -> 0 | I12: =IF(H12>=80,"Very High",IF(H12>=60,"High",IF(H12>=40,"Medium",IF(H12>=20,"Low","Very Low")))) -> Very Low
A13: 10 | C13: =IFERROR('4. Teaching Subject Matrix'!M14,0) -> 0 | D13: =IFERROR('4. Teaching Subject Matrix'!N14,0) -> 0 | E13: =IFERROR(IF(C13>0,-SUMPRODUCT(IF('4. Teaching Subject Matrix'!B14:L14>0,('4. Teaching Subject Matrix'!B14:L14/C13)*LOG('4. Teaching Subject Matrix'!B14:L14/C13,2),0)),0),0) -> 0 | F13: =IF(D13>1,LOG(D13,2),0) -> 0 | G13: =IFERROR(IF(F13>0,E13/F13,0),0) -> 0 | H13: =IFERROR(IF(MAX($E$4:$E$33)>0,E13/MAX($E$4:$E$33)*100,0),0) -> 0 | I13: =IF(H13>=80,"Very High",IF(H13>=60,"High",IF(H13>=40,"Medium",IF(H13>=20,"Low","Very Low")))) -> Very Low
A14: 11 | C14: =IFERROR('4. Teaching Subject Matrix'!M15,0) -> 0 | D14: =IFERROR('4. Teaching Subject Matrix'!N15,0) -> 0 | E14: =IFERROR(IF(C14>0,-SUMPRODUCT(IF('4. Teaching Subject Matrix'!B15:L15>0,('4. Teaching Subject Matrix'!B15:L15/C14)*LOG('4. Teaching Subject Matrix'!B15:L15/C14,2),0)),0),0) -> 0 | F14: =IF(D14>1,LOG(D14,2),0) -> 0 | G14: =IFERROR(IF(F14>0,E14/F14,0),0) -> 0 | H14: =IFERROR(IF(MAX($E$4:$E$33)>0,E14/MAX($E$4:$E$33)*100,0),0) -> 0 | I14: =IF(H14>=80,"Very High",IF(H14>=60,"High",IF(H14>=40,"Medium",IF(H14>=20,"Low","Very Low")))) -> Very Low
A15: 12 | C15: =IFERROR('4. Teaching Subject Matrix'!M16,0) -> 0 | D15: =IFERROR('4. Teaching Subject Matrix'!N16,0) -> 0 | E15: =IFERROR(IF(C15>0,-SUMPRODUCT(IF('4. Teaching Subject Matrix'!B16:L16>0,('4. Teaching Subject Matrix'!B16:L16/C15)*LOG('4. Teaching Subject Matrix'!B16:L16/C15,2),0)),0),0) -> 0 | F15: =IF(D15>1,LOG(D15,2),0) -> 0 | G15: =IFERROR(IF(F15>0,E15/F15,0),0) -> 0 | H15: =IFERROR(IF(MAX($E$4:$E$33)>0,E15/MAX($E$4:$E$33)*100,0),0) -> 0 | I15: =IF(H15>=80,"Very High",IF(H15>=60,"High",IF(H15>=40,"Medium",IF(H15>=20,"Low","Very Low")))) -> Very Low
... A33: 30 | C33: =IFERROR('4. Teaching Subject Matrix'!M34,0) -> 0 | D33: =IFERROR('4. Teaching Subject Matrix'!N34,0) -> 0 | E33: =IFERROR(IF(C33>0,-SUMPRODUCT(IF('4. Teaching Subject Matrix'!B34:L34>0,('4. Teaching Subject Matrix'!B34:L34/C33)*LOG('4. Teaching Subject Matrix'!B34:L34/C33,2),0)),0),0) -> 0 | F33: =IF(D33>1,LOG(D33,2),0) -> 0 | G33: =IFERROR(IF(F33>0,E33/F33,0),0) -> 0 | H33: =IFERROR(IF(MAX($E$4:$E$33)>0,E33/MAX($E$4:$E$33)*100,0),0) -> 0 | I33: =IF(H33>=80,"Very High",IF(H33>=60,"High",IF(H33>=40,"Medium",IF(H33>=20,"Low","Very Low")))) -> Very Low

Sheet 7. Combined Subject Diversity
A1: Combined Subject Diversity Score — Research (2/3) + Teaching (1/3)
A2: Mirrors THE's 2:1 Research:Teaching weighting for the voter diversity pillar
A3: S.No. | B3: University Name | C3: Research Subject Score | D3: Teaching Subject Score | E3: Combined Subject Diversity | F3: Overall Rank | G3: Tier
B4: Weights → | C4: =2/3 -> 0.66666667 | D4: =1/3 -> 0.33333333
A5: 1 | C5: =IFERROR(VLOOKUP(B5,'5. Research Subject Entropy'!$B$4:$H$33,7,FALSE()),0) -> 0 | D5: =IFERROR(VLOOKUP(B5,'6. Teaching Subject Entropy'!$B$4:$H$33,7,FALSE()),0) -> 0 | E5: =C5*$C$4+D5*$D$4 -> 0 | F5: =IFERROR(RANK(E5,$E$5:$E$34,0),"") -> 1 | G5: =IF(E5>=80,"Very High",IF(E5>=60,"High",IF(E5>=40,"Medium",IF(E5>=20,"Low","Very Low")))) -> Very Low
A6: 2 | C6: =IFERROR(VLOOKUP(B6,'5. Research Subject Entropy'!$B$4:$H$33,7,FALSE()),0) -> 0 | D6: =IFERROR(VLOOKUP(B6,'6. Teaching Subject Entropy'!$B$4:$H$33,7,FALSE()),0) -> 0 | E6: =C6*$C$4+D6*$D$4 -> 0 | F6: =IFERROR(RANK(E6,$E$5:$E$34,0),"") -> 1 | G6: =IF(E6>=80,"Very High",IF(E6>=60,"High",IF(E6>=40,"Medium",IF(E6>=20,"Low","Very Low")))) -> Very Low
A7: 3 | C7: =IFERROR(VLOOKUP(B7,'5. Research Subject Entropy'!$B$4:$H$33,7,FALSE()),0) -> 0 | D7: =IFERROR(VLOOKUP(B7,'6. Teaching Subject Entropy'!$B$4:$H$33,7,FALSE()),0) -> 0 | E7: =C7*$C$4+D7*$D$4 -> 0 | F7: =IFERROR(RANK(E7,$E$5:$E$34,0),"") -> 1 | G7: =IF(E7>=80,"Very High",IF(E7>=60,"High",IF(E7>=40,"Medium",IF(E7>=20,"Low","Very Low")))) -> Very Low
A8: 4 | C8: =IFERROR(VLOOKUP(B8,'5. Research Subject Entropy'!$B$4:$H$33,7,FALSE()),0) -> 0 | D8: =IFERROR(VLOOKUP(B8,'6. Teaching Subject Entropy'!$B$4:$H$33,7,FALSE()),0) -> 0 | E8: =C8*$C$4+D8*$D$4 -> 0 | F8: =IFERROR(RANK(E8,$E$5:$E$34,0),"") -> 1 | G8: =IF(E8>=80,"Very High",IF(E8>=60,"High",IF(E8>=40,"Medium",IF(E8>=20,"Low","Very Low")))) -> Very Low
A9: 5 | C9: =IFERROR(VLOOKUP(B9,'5. Research Subject Entropy'!$B$4:$H$33,7,FALSE()),0) -> 0 | D9: =IFERROR(VLOOKUP(B9,'6. Teaching Subject Entropy'!$B$4:$H$33,7,FALSE()),0) -> 0 | E9: =C9*$C$4+D9*$D$4 -> 0 | F9: =IFERROR(RANK(E9,$E$5:$E$34,0),"") -> 1 | G9: =IF(E9>=80,"Very High",IF(E9>=60,"High",IF(E9>=40,"Medium",IF(E9>=20,"Low","Very Low")))) -> Very Low
A10: 6 | C10: =IFERROR(VLOOKUP(B10,'5. Research Subject Entropy'!$B$4:$H$33,7,FALSE()),0) -> 0 | D10: =IFERROR(VLOOKUP(B10,'6. Teaching Subject Entropy'!$B$4:$H$33,7,FALSE()),0) -> 0 | E10: =C10*$C$4+D10*$D$4 -> 0 | F10: =IFERROR(RANK(E10,$E$5:$E$34,0),"") -> 1 | G10: =IF(E10>=80,"Very High",IF(E10>=60,"High",IF(E10>=40,"Medium",IF(E10>=20,"Low","Very Low")))) -> Very Low
A11: 7 | C11: =IFERROR(VLOOKUP(B11,'5. Research Subject Entropy'!$B$4:$H$33,7,FALSE()),0) -> 0 | D11: =IFERROR(VLOOKUP(B11,'6. Teaching Subject Entropy'!$B$4:$H$33,7,FALSE()),0) -> 0 | E11: =C11*$C$4+D11*$D$4 -> 0 | F11: =IFERROR(RANK(E11,$E$5:$E$34,0),"") -> 1 | G11: =IF(E11>=80,"Very High",IF(E11>=60,"High",IF(E11>=40,"Medium",IF(E11>=20,"Low","Very Low")))) -> Very Low
A12: 8 | C12: =IFERROR(VLOOKUP(B12,'5. Research Subject Entropy'!$B$4:$H$33,7,FALSE()),0) -> 0 | D12: =IFERROR(VLOOKUP(B12,'6. Teaching Subject Entropy'!$B$4:$H$33,7,FALSE()),0) -> 0 | E12: =C12*$C$4+D12*$D$4 -> 0 | F12: =IFERROR(RANK(E12,$E$5:$E$34,0),"") -> 1 | G12: =IF(E12>=80,"Very High",IF(E12>=60,"High",IF(E12>=40,"Medium",IF(E12>=20,"Low","Very Low")))) -> Very Low
A13: 9 | C13: =IFERROR(VLOOKUP(B13,'5. Research Subject Entropy'!$B$4:$H$33,7,FALSE()),0) -> 0 | D13: =IFERROR(VLOOKUP(B13,'6. Teaching Subject Entropy'!$B$4:$H$33,7,FALSE()),0) -> 0 | E13: =C13*$C$4+D13*$D$4 -> 0 | F13: =IFERROR(RANK(E13,$E$5:$E$34,0),"") -> 1 | G13: =IF(E13>=80,"Very High",IF(E13>=60,"High",IF(E13>=40,"Medium",IF(E13>=20,"Low","Very Low")))) -> Very Low
A14: 10 | C14: =IFERROR(VLOOKUP(B14,'5. Research Subject Entropy'!$B$4:$H$33,7,FALSE()),0) -> 0 | D14: =IFERROR(VLOOKUP(B14,'6. Teaching Subject Entropy'!$B$4:$H$33,7,FALSE()),0) -> 0 | E14: =C14*$C$4+D14*$D$4 -> 0 | F14: =IFERROR(RANK(E14,$E$5:$E$34,0),"") -> 1 | G14: =IF(E14>=80,"Very High",IF(E14>=60,"High",IF(E14>=40,"Medium",IF(E14>=20,"Low","Very Low")))) -> Very Low
A15: 11 | C15: =IFERROR(VLOOKUP(B15,'5. Research Subject Entropy'!$B$4:$H$33,7,FALSE()),0) -> 0 | D15: =IFERROR(VLOOKUP(B15,'6. Teaching Subject Entropy'!$B$4:$H$33,7,FALSE()),0) -> 0 | E15: =C15*$C$4+D15*$D$4 -> 0 | F15: =IFERROR(RANK(E15,$E$5:$E$34,0),"") -> 1 | G15: =IF(E15>=80,"Very High",IF(E15>=60,"High",IF(E15>=40,"Medium",IF(E15>=20,"Low","Very Low")))) -> Very Low
A16: 12 | C16: =IFERROR(VLOOKUP(B16,'5. Research Subject Entropy'!$B$4:$H$33,7,FALSE()),0) -> 0 | D16: =IFERROR(VLOOKUP(B16,'6. Teaching Subject Entropy'!$B$4:$H$33,7,FALSE()),0) -> 0 | E16: =C16*$C$4+D16*$D$4 -> 0 | F16: =IFERROR(RANK(E16,$E$5:$E$34,0),"") -> 1 | G16: =IF(E16>=80,"Very High",IF(E16>=60,"High",IF(E16>=40,"Medium",IF(E16>=20,"Low","Very Low")))) -> Very Low
