Workbook

Sheet Methodology Overview
A1: THE WRR — Geographical Diversity Data Collection Formats
A2: Methodology: WRR 2025 Voter Diversity Indicator — Geographical (Country/Territory) Dimension
A4: # | B4: Concept | C4: Description | D4: Relevance
A5: 1 | B5: Geographical Diversity in WRR | C5: In the 2025 revamped WRR, voter diversity examines HOW WIDELY an institution's reputation votes are distributed across countries/territories. An institution receiving votes from scholars in 35 countries has a more robust geographical reputation than one receiving votes from 5 countries, even if both have the same total vote count. | D5: Core component of 10% Diversity pillar
A6: 2 | B6: Entropy Approach | C6: Shannon entropy H = −Σ pᵢ × log₂(pᵢ) is computed over the country distribution of each institution's voters. Higher H = broader geographic base. The country dimension is ONE axis of the entropy calculation; the other is subject area. | D6: Mathematical foundation
A7: 3 | B7: Country/Territory Unit | C7: Each of the 160+ respondent countries/territories is a unit in the geographic distribution. THE uses UN data as a guide to ensure survey coverage is globally representative. | D7: Aggregation unit
A8: 4 | B8: Geographic Weighting | C8: Where countries are over- or under-represented in survey responses, THE's data team applies weights to ensure results reflect the global distribution of scholars. This prevents geographic bias. | D8: Bias correction
A9: 5 | B9: Self-Vote Dilution | C9: Votes where respondents rate institutions in their own country receive dilution to prevent home-country bias from inflating geographic concentration. | D9: Bias safeguard
A10: 6 | B10: Regional Concentration Index | C10: Beyond entropy, THE examines whether votes cluster in a single continent/region. High regional concentration (e.g., 90% from one continent) signals narrow geographic reputation. | D10: Supplementary metric
A11: 7 | B11: Weight in Final WRR | C11: Voter diversity (combining geographic + subject diversity) accounts for 10% of overall WRR — split 6.67% research and 3.33% teaching. Geographic diversity is one half of this pillar. | D11: ~5% effective weight
A12: 8 | B12: 2025 WRR Coverage | C12: The 2025 rankings cover 300 institutions from 38 countries, based on survey responses from scholars in 160+ countries across all continents. | D12: Scale of data
A14: Geographic Diversity Formula
A15: H_geo = − Σ (nᵢ/N) × log₂(nᵢ/N) where nᵢ = votes from country i, N = total votes. Max H_geo = log₂(K) where K = number of unique countries.

Sheet 1. Country Master List
A1: Country / Territory Master List — Global Academic Survey Coverage
A2: 160+ countries from which survey responses originate — grouped by UN region for weighting analysis
A3: # | B3: Country / Territory | C3: ISO-3 | D3: UN Region | E3: Continent | F3: No. of Respondents | G3: Weighting Factor | H3: Notes
A4: 1 | B4: United States | C4: USA | D4: Americas | E4: North America
A5: 2 | B5: United Kingdom | C5: GBR | D5: Europe & Central Asia | E5: Europe
A6: 3 | B6: China | C6: CHN | D6: East Asia & Pacific | E6: Asia
A7: 4 | B7: Germany | C7: DEU | D7: Europe & Central Asia | E7: Europe
A8: 5 | B8: Japan | C8: JPN | D8: East Asia & Pacific | E8: Asia
A9: 6 | B9: Australia | C9: AUS | D9: East Asia & Pacific | E9: Oceania
A10: 7 | B10: France | C10: FRA | D10: Europe & Central Asia | E10: Europe
A11: 8 | B11: Netherlands | C11: NLD | D11: Europe & Central Asia | E11: Europe
A12: 9 | B12: Canada | C12: CAN | D12: Americas | E12: North America
A13: 10 | B13: South Korea | C13: KOR | D13: East Asia & Pacific | E13: Asia
A14: 11 | B14: Switzerland | C14: CHE | D14: Europe & Central Asia | E14: Europe
A15: 12 | B15: Sweden | C15: SWE | D15: Europe & Central Asia | E15: Europe
... A53: 50 | B53: Vietnam | C53: VNM | D53: East Asia & Pacific | E53: Asia
A55: Summary
A56: Total Countries Listed | E56: =COUNTA(B4:B53) -> 50
A57: Total Respondents | E57: =SUM(F4:F53) -> 0
A58: Unique Continents | E58: =SUMPRODUCT((E4:E53<>"")/COUNTIF(E4:E53,E4:E53&"")) -> 7
A59: Unique UN Regions | E59: =SUMPRODUCT((D4:D53<>"")/COUNTIF(D4:D53,D4:D53&"")) -> 6

Sheet 2. Raw Votes by Country
A1: Raw Reputation Votes — With Respondent Country/Territory Data
A2: Each row = one vote cast by one respondent for one institution | Source data for geographic diversity
A3: Vote ID | B3: University Voted For | C3: Respondent ID | D3: ISO-3 Code | E3: Respondent Country | F3: UN Region | G3: Continent | H3: Vote Type (Research/Teaching) | I3: Self-Vote (Y/N) | J3: Date
A4: GV-00001 | E4: =IFERROR(VLOOKUP(D4,'1. Country Master List'!C:B,2,FALSE()),"") | F4: =IFERROR(VLOOKUP(D4,'1. Country Master List'!$C$4:$D$53,2,FALSE()),"") | G4: =IFERROR(VLOOKUP(D4,'1. Country Master List'!$C$4:$E$53,3,FALSE()),"")
A5: GV-00002 | E5: =IFERROR(VLOOKUP(D5,'1. Country Master List'!C:B,2,FALSE()),"") | F5: =IFERROR(VLOOKUP(D5,'1. Country Master List'!$C$4:$D$53,2,FALSE()),"") | G5: =IFERROR(VLOOKUP(D5,'1. Country Master List'!$C$4:$E$53,3,FALSE()),"")
A6: GV-00003 | E6: =IFERROR(VLOOKUP(D6,'1. Country Master List'!C:B,2,FALSE()),"") | F6: =IFERROR(VLOOKUP(D6,'1. Country Master List'!$C$4:$D$53,2,FALSE()),"") | G6: =IFERROR(VLOOKUP(D6,'1. Country Master List'!$C$4:$E$53,3,FALSE()),"")
A7: GV-00004 | E7: =IFERROR(VLOOKUP(D7,'1. Country Master List'!C:B,2,FALSE()),"") | F7: =IFERROR(VLOOKUP(D7,'1. Country Master List'!$C$4:$D$53,2,FALSE()),"") | G7: =IFERROR(VLOOKUP(D7,'1. Country Master List'!$C$4:$E$53,3,FALSE()),"")
A8: GV-00005 | E8: =IFERROR(VLOOKUP(D8,'1. Country Master List'!C:B,2,FALSE()),"") | F8: =IFERROR(VLOOKUP(D8,'1. Country Master List'!$C$4:$D$53,2,FALSE()),"") | G8: =IFERROR(VLOOKUP(D8,'1. Country Master List'!$C$4:$E$53,3,FALSE()),"")
A9: GV-00006 | E9: =IFERROR(VLOOKUP(D9,'1. Country Master List'!C:B,2,FALSE()),"") | F9: =IFERROR(VLOOKUP(D9,'1. Country Master List'!$C$4:$D$53,2,FALSE()),"") | G9: =IFERROR(VLOOKUP(D9,'1. Country Master List'!$C$4:$E$53,3,FALSE()),"")
A10: GV-00007 | E10: =IFERROR(VLOOKUP(D10,'1. Country Master List'!C:B,2,FALSE()),"") | F10: =IFERROR(VLOOKUP(D10,'1. Country Master List'!$C$4:$D$53,2,FALSE()),"") | G10: =IFERROR(VLOOKUP(D10,'1. Country Master List'!$C$4:$E$53,3,FALSE()),"")
A11: GV-00008 | E11: =IFERROR(VLOOKUP(D11,'1. Country Master List'!C:B,2,FALSE()),"") | F11: =IFERROR(VLOOKUP(D11,'1. Country Master List'!$C$4:$D$53,2,FALSE()),"") | G11: =IFERROR(VLOOKUP(D11,'1. Country Master List'!$C$4:$E$53,3,FALSE()),"")
A12: GV-00009 | E12: =IFERROR(VLOOKUP(D12,'1. Country Master List'!C:B,2,FALSE()),"") | F12: =IFERROR(VLOOKUP(D12,'1. Country Master List'!$C$4:$D$53,2,FALSE()),"") | G12: =IFERROR(VLOOKUP(D12,'1. Country Master List'!$C$4:$E$53,3,FALSE()),"")
A13: GV-00010 | E13: =IFERROR(VLOOKUP(D13,'1. Country Master List'!C:B,2,FALSE()),"") | F13: =IFERROR(VLOOKUP(D13,'1. Country Master List'!$C$4:$D$53,2,FALSE()),"") | G13: =IFERROR(VLOOKUP(D13,'1. Country Master List'!$C$4:$E$53,3,FALSE()),"")
A14: GV-00011 | E14: =IFERROR(VLOOKUP(D14,'1. Country Master List'!C:B,2,FALSE()),"") | F14: =IFERROR(VLOOKUP(D14,'1. Country Master List'!$C$4:$D$53,2,FALSE()),"") | G14: =IFERROR(VLOOKUP(D14,'1. Country Master List'!$C$4:$E$53,3,FALSE()),"")
A15: GV-00012 | E15: =IFERROR(VLOOKUP(D15,'1. Country Master List'!C:B,2,FALSE()),"") | F15: =IFERROR(VLOOKUP(D15,'1. Country Master List'!$C$4:$D$53,2,FALSE()),"") | G15: =IFERROR(VLOOKUP(D15,'1. Country Master List'!$C$4:$E$53,3,FALSE()),"")
... A253: GV-00250 | E253: =IFERROR(VLOOKUP(D253,'1. Country Master List'!C:B,2,FALSE()),"") | F253: =IFERROR(VLOOKUP(D253,'1. Country Master List'!$C$4:$D$53,2,FALSE()),"") | G253: =IFERROR(VLOOKUP(D253,'1. Country Master List'!$C$4:$E$53,3,FALSE()),"")

Sheet 3. Univ × Country Matrix
A1: Geographic Distribution: University × Respondent Country (Vote Count Matrix)
A2: Each cell = count of votes for that university from respondents in that country | Extend columns as needed
A4: University ↓ / Country → | B4: USA | C4: GBR | D4: CHN | E4: DEU | F4: JPN | G4: AUS | H4: FRA | I4: NLD | J4: CAN | K4: KOR | L4: CHE | M4: SWE | N4: ITA | O4: ESP | P4: IND | Q4: BRA | R4: SGP | S4: HKG | T4: ZAF | U4: RUS | V4: Total Votes | W4: Unique Countries | X4: Geo Concentration Index
B5: =IFERROR(COUNTIFS('2. Raw Votes by Country'!B:B,$A5,'2. Raw Votes by Country'!D:D,"USA"),0) -> 0 | C5: =IFERROR(COUNTIFS('2. Raw Votes by Country'!B:B,$A5,'2. Raw Votes by Country'!D:D,"GBR"),0) -> 0 | D5: =IFERROR(COUNTIFS('2. Raw Votes by Country'!B:B,$A5,'2. Raw Votes by Country'!D:D,"CHN"),0) -> 0 | E5: =IFERROR(COUNTIFS('2. Raw Votes by Country'!B:B,$A5,'2. Raw Votes by Country'!D:D,"DEU"),0) -> 0 | F5: =IFERROR(COUNTIFS('2. Raw Votes by Country'!B:B,$A5,'2. Raw Votes by Country'!D:D,"JPN"),0) -> 0 | G5: =IFERROR(COUNTIFS('2. Raw Votes by Country'!B:B,$A5,'2. Raw Votes by Country'!D:D,"AUS"),0) -> 0 | H5: =IFERROR(COUNTIFS('2. Raw Votes by Country'!B:B,$A5,'2. Raw Votes by Country'!D:D,"FRA"),0) -> 0 | I5: =IFERROR(COUNTIFS('2. Raw Votes by Country'!B:B,$A5,'2. Raw Votes by Country'!D:D,"NLD"),0) -> 0 | J5: =IFERROR(COUNTIFS('2. Raw Votes by Country'!B:B,$A5,'2. Raw Votes by Country'!D:D,"CAN"),0) -> 0 | K5: =IFERROR(COUNTIFS('2. Raw Votes by Country'!B:B,$A5,'2. Raw Votes by Country'!D:D,"KOR"),0) -> 0 | L5: =IFERROR(COUNTIFS('2. Raw Votes by Country'!B:B,$A5,'2. Raw Votes by Country'!D:D,"CHE"),0) -> 0 | M5: =IFERROR(COUNTIFS('2. Raw Votes by Country'!B:B,$A5,'2. Raw Votes by Country'!D:D,"SWE"),0) -> 0 | N5: =IFERROR(COUNTIFS('2. Raw Votes by Country'!B:B,$A5,'2. Raw Votes by Country'!D:D,"ITA"),0) -> 0 | O5: =IFERROR(COUNTIFS('2. Raw Votes by Country'!B:B,$A5,'2. Raw Votes by Country'!D:D,"ESP"),0) -> 0 | P5: =IFERROR(COUNTIFS('2. Raw Votes by Country'!B:B,$A5,'2. Raw Votes by Country'!D:D,"IND"),0) -> 0 | Q5: =IFERROR(COUNTIFS('2. Raw Votes by Country'!B:B,$A5,'2. Raw Votes by Country'!D:D,"BRA"),0) -> 0 | R5: =IFERROR(COUNTIFS('2. Raw Votes by Country'!B:B,$A5,'2. Raw Votes by Country'!D:D,"SGP"),0) -> 0 | S5: =IFERROR(COUNTIFS('2. Raw Votes by Country'!B:B,$A5,'2. Raw Votes by Country'!D:D,"HKG"),0) -> 0 | T5: =IFERROR(COUNTIFS('2. Raw Votes by Country'!B:B,$A5,'2. Raw Votes by Country'!D:D,"ZAF"),0) -> 0 | U5: =IFERROR(COUNTIFS('2. Raw Votes by Country'!B:B,$A5,'2. Raw Votes by Country'!D:D,"RUS"),0) -> 0 | V5: =SUM(B5:U5) -> 0 | W5: =COUNTIF(B5:U5,">0") -> 0 | X5: =IFERROR(MAX(B5:U5)/V5*100,0) -> 0
B6: =IFERROR(COUNTIFS('2. Raw Votes by Country'!B:B,$A6,'2. Raw Votes by Country'!D:D,"USA"),0) -> 0 | C6: =IFERROR(COUNTIFS('2. Raw Votes by Country'!B:B,$A6,'2. Raw Votes by Country'!D:D,"GBR"),0) -> 0 | D6: =IFERROR(COUNTIFS('2. Raw Votes by Country'!B:B,$A6,'2. Raw Votes by Country'!D:D,"CHN"),0) -> 0 | E6: =IFERROR(COUNTIFS('2. Raw Votes by Country'!B:B,$A6,'2. Raw Votes by Country'!D:D,"DEU"),0) -> 0 | F6: =IFERROR(COUNTIFS('2. Raw Votes by Country'!B:B,$A6,'2. Raw Votes by Country'!D:D,"JPN"),0) -> 0 | G6: =IFERROR(COUNTIFS('2. Raw Votes by Country'!B:B,$A6,'2. Raw Votes by Country'!D:D,"AUS"),0) -> 0 | H6: =IFERROR(COUNTIFS('2. Raw Votes by Country'!B:B,$A6,'2. Raw Votes by Country'!D:D,"FRA"),0) -> 0 | I6: =IFERROR(COUNTIFS('2. Raw Votes by Country'!B:B,$A6,'2. Raw Votes by Country'!D:D,"NLD"),0) -> 0 | J6: =IFERROR(COUNTIFS('2. Raw Votes by Country'!B:B,$A6,'2. Raw Votes by Country'!D:D,"CAN"),0) -> 0 | K6: =IFERROR(COUNTIFS('2. Raw Votes by Country'!B:B,$A6,'2. Raw Votes by Country'!D:D,"KOR"),0) -> 0 | L6: =IFERROR(COUNTIFS('2. Raw Votes by Country'!B:B,$A6,'2. Raw Votes by Country'!D:D,"CHE"),0) -> 0 | M6: =IFERROR(COUNTIFS('2. Raw Votes by Country'!B:B,$A6,'2. Raw Votes by Country'!D:D,"SWE"),0) -> 0 | N6: =IFERROR(COUNTIFS('2. Raw Votes by Country'!B:B,$A6,'2. Raw Votes by Country'!D:D,"ITA"),0) -> 0 | O6: =IFERROR(COUNTIFS('2. Raw Votes by Country'!B:B,$A6,'2. Raw Votes by Country'!D:D,"ESP"),0) -> 0 | P6: =IFERROR(COUNTIFS('2. Raw Votes by Country'!B:B,$A6,'2. Raw Votes by Country'!D:D,"IND"),0) -> 0 | Q6: =IFERROR(COUNTIFS('2. Raw Votes by Country'!B:B,$A6,'2. Raw Votes by Country'!D:D,"BRA"),0) -> 0 | R6: =IFERROR(COUNTIFS('2. Raw Votes by Country'!B:B,$A6,'2. Raw Votes by Country'!D:D,"SGP"),0) -> 0 | S6: =IFERROR(COUNTIFS('2. Raw Votes by Country'!B:B,$A6,'2. Raw Votes by Country'!D:D,"HKG"),0) -> 0 | T6: =IFERROR(COUNTIFS('2. Raw Votes by Country'!B:B,$A6,'2. Raw Votes by Country'!D:D,"ZAF"),0) -> 0 | U6: =IFERROR(COUNTIFS('2. Raw Votes by Country'!B:B,$A6,'2. Raw Votes by Country'!D:D,"RUS"),0) -> 0 | V6: =SUM(B6:U6) -> 0 | W6: =COUNTIF(B6:U6,">0") -> 0 | X6: =IFERROR(MAX(B6:U6)/V6*100,0) -> 0
B7: =IFERROR(COUNTIFS('2. Raw Votes by Country'!B:B,$A7,'2. Raw Votes by Country'!D:D,"USA"),0) -> 0 | C7: =IFERROR(COUNTIFS('2. Raw Votes by Country'!B:B,$A7,'2. Raw Votes by Country'!D:D,"GBR"),0) -> 0 | D7: =IFERROR(COUNTIFS('2. Raw Votes by Country'!B:B,$A7,'2. Raw Votes by Country'!D:D,"CHN"),0) -> 0 | E7: =IFERROR(COUNTIFS('2. Raw Votes by Country'!B:B,$A7,'2. Raw Votes by Country'!D:D,"DEU"),0) -> 0 | F7: =IFERROR(COUNTIFS('2. Raw Votes by Country'!B:B,$A7,'2. Raw Votes by Country'!D:D,"JPN"),0) -> 0 | G7: =IFERROR(COUNTIFS('2. Raw Votes by Country'!B:B,$A7,'2. Raw Votes by Country'!D:D,"AUS"),0) -> 0 | H7: =IFERROR(COUNTIFS('2. Raw Votes by Country'!B:B,$A7,'2. Raw Votes by Country'!D:D,"FRA"),0) -> 0 | I7: =IFERROR(COUNTIFS('2. Raw Votes by Country'!B:B,$A7,'2. Raw Votes by Country'!D:D,"NLD"),0) -> 0 | J7: =IFERROR(COUNTIFS('2. Raw Votes by Country'!B:B,$A7,'2. Raw Votes by Country'!D:D,"CAN"),0) -> 0 | K7: =IFERROR(COUNTIFS('2. Raw Votes by Country'!B:B,$A7,'2. Raw Votes by Country'!D:D,"KOR"),0) -> 0 | L7: =IFERROR(COUNTIFS('2. Raw Votes by Country'!B:B,$A7,'2. Raw Votes by Country'!D:D,"CHE"),0) -> 0 | M7: =IFERROR(COUNTIFS('2. Raw Votes by Country'!B:B,$A7,'2. Raw Votes by Country'!D:D,"SWE"),0) -> 0 | N7: =IFERROR(COUNTIFS('2. Raw Votes by Country'!B:B,$A7,'2. Raw Votes by Country'!D:D,"ITA"),0) -> 0 | O7: =IFERROR(COUNTIFS('2. Raw Votes by Country'!B:B,$A7,'2. Raw Votes by Country'!D:D,"ESP"),0) -> 0 | P7: =IFERROR(COUNTIFS('2. Raw Votes by Country'!B:B,$A7,'2. Raw Votes by Country'!D:D,"IND"),0) -> 0 | Q7: =IFERROR(COUNTIFS('2. Raw Votes by Country'!B:B,$A7,'2. Raw Votes by Country'!D:D,"BRA"),0) -> 0 | R7: =IFERROR(COUNTIFS('2. Raw Votes by Country'!B:B,$A7,'2. Raw Votes by Country'!D:D,"SGP"),0) -> 0 | S7: =IFERROR(COUNTIFS('2. Raw Votes by Country'!B:B,$A7,'2. Raw Votes by Country'!D:D,"HKG"),0) -> 0 | T7: =IFERROR(COUNTIFS('2. Raw Votes by Country'!B:B,$A7,'2. Raw Votes by Country'!D:D,"ZAF"),0) -> 0 | U7: =IFERROR(COUNTIFS('2. Raw Votes by Country'!B:B,$A7,'2. Raw Votes by Country'!D:D,"RUS"),0) -> 0 | V7: =SUM(B7:U7) -> 0 | W7: =COUNTIF(B7:U7,">0") -> 0 | X7: =IFERROR(MAX(B7:U7)/V7*100,0) -> 0
B8: =IFERROR(COUNTIFS('2. Raw Votes by Country'!B:B,$A8,'2. Raw Votes by Country'!D:D,"USA"),0) -> 0 | C8: =IFERROR(COUNTIFS('2. Raw Votes by Country'!B:B,$A8,'2. Raw Votes by Country'!D:D,"GBR"),0) -> 0 | D8: =IFERROR(COUNTIFS('2. Raw Votes by Country'!B:B,$A8,'2. Raw Votes by Country'!D:D,"CHN"),0) -> 0 | E8: =IFERROR(COUNTIFS('2. Raw Votes by Country'!B:B,$A8,'2. Raw Votes by Country'!D:D,"DEU"),0) -> 0 | F8: =IFERROR(COUNTIFS('2. Raw Votes by Country'!B:B,$A8,'2. Raw Votes by Country'!D:D,"JPN"),0) -> 0 | G8: =IFERROR(COUNTIFS('2. Raw Votes by Country'!B:B,$A8,'2. Raw Votes by Country'!D:D,"AUS"),0) -> 0 | H8: =IFERROR(COUNTIFS('2. Raw Votes by Country'!B:B,$A8,'2. Raw Votes by Country'!D:D,"FRA"),0) -> 0 | I8: =IFERROR(COUNTIFS('2. Raw Votes by Country'!B:B,$A8,'2. Raw Votes by Country'!D:D,"NLD"),0) -> 0 | J8: =IFERROR(COUNTIFS('2. Raw Votes by Country'!B:B,$A8,'2. Raw Votes by Country'!D:D,"CAN"),0) -> 0 | K8: =IFERROR(COUNTIFS('2. Raw Votes by Country'!B:B,$A8,'2. Raw Votes by Country'!D:D,"KOR"),0) -> 0 | L8: =IFERROR(COUNTIFS('2. Raw Votes by Country'!B:B,$A8,'2. Raw Votes by Country'!D:D,"CHE"),0) -> 0 | M8: =IFERROR(COUNTIFS('2. Raw Votes by Country'!B:B,$A8,'2. Raw Votes by Country'!D:D,"SWE"),0) -> 0 | N8: =IFERROR(COUNTIFS('2. Raw Votes by Country'!B:B,$A8,'2. Raw Votes by Country'!D:D,"ITA"),0) -> 0 | O8: =IFERROR(COUNTIFS('2. Raw Votes by Country'!B:B,$A8,'2. Raw Votes by Country'!D:D,"ESP"),0) -> 0 | P8: =IFERROR(COUNTIFS('2. Raw Votes by Country'!B:B,$A8,'2. Raw Votes by Country'!D:D,"IND"),0) -> 0 | Q8: =IFERROR(COUNTIFS('2. Raw Votes by Country'!B:B,$A8,'2. Raw Votes by Country'!D:D,"BRA"),0) -> 0 | R8: =IFERROR(COUNTIFS('2. Raw Votes by Country'!B:B,$A8,'2. Raw Votes by Country'!D:D,"SGP"),0) -> 0 | S8: =IFERROR(COUNTIFS('2. Raw Votes by Country'!B:B,$A8,'2. Raw Votes by Country'!D:D,"HKG"),0) -> 0 | T8: =IFERROR(COUNTIFS('2. Raw Votes by Country'!B:B,$A8,'2. Raw Votes by Country'!D:D,"ZAF"),0) -> 0 | U8: =IFERROR(COUNTIFS('2. Raw Votes by Country'!B:B,$A8,'2. Raw Votes by Country'!D:D,"RUS"),0) -> 0 | V8: =SUM(B8:U8) -> 0 | W8: =COUNTIF(B8:U8,">0") -> 0 | X8: =IFERROR(MAX(B8:U8)/V8*100,0) -> 0
B9: =IFERROR(COUNTIFS('2. Raw Votes by Country'!B:B,$A9,'2. Raw Votes by Country'!D:D,"USA"),0) -> 0 | C9: =IFERROR(COUNTIFS('2. Raw Votes by Country'!B:B,$A9,'2. Raw Votes by Country'!D:D,"GBR"),0) -> 0 | D9: =IFERROR(COUNTIFS('2. Raw Votes by Country'!B:B,$A9,'2. Raw Votes by Country'!D:D,"CHN"),0) -> 0 | E9: =IFERROR(COUNTIFS('2. Raw Votes by Country'!B:B,$A9,'2. Raw Votes by Country'!D:D,"DEU"),0) -> 0 | F9: =IFERROR(COUNTIFS('2. Raw Votes by Country'!B:B,$A9,'2. Raw Votes by Country'!D:D,"JPN"),0) -> 0 | G9: =IFERROR(COUNTIFS('2. Raw Votes by Country'!B:B,$A9,'2. Raw Votes by Country'!D:D,"AUS"),0) -> 0 | H9: =IFERROR(COUNTIFS('2. Raw Votes by Country'!B:B,$A9,'2. Raw Votes by Country'!D:D,"FRA"),0) -> 0 | I9: =IFERROR(COUNTIFS('2. Raw Votes by Country'!B:B,$A9,'2. Raw Votes by Country'!D:D,"NLD"),0) -> 0 | J9: =IFERROR(COUNTIFS('2. Raw Votes by Country'!B:B,$A9,'2. Raw Votes by Country'!D:D,"CAN"),0) -> 0 | K9: =IFERROR(COUNTIFS('2. Raw Votes by Country'!B:B,$A9,'2. Raw Votes by Country'!D:D,"KOR"),0) -> 0 | L9: =IFERROR(COUNTIFS('2. Raw Votes by Country'!B:B,$A9,'2. Raw Votes by Country'!D:D,"CHE"),0) -> 0 | M9: =IFERROR(COUNTIFS('2. Raw Votes by Country'!B:B,$A9,'2. Raw Votes by Country'!D:D,"SWE"),0) -> 0 | N9: =IFERROR(COUNTIFS('2. Raw Votes by Country'!B:B,$A9,'2. Raw Votes by Country'!D:D,"ITA"),0) -> 0 | O9: =IFERROR(COUNTIFS('2. Raw Votes by Country'!B:B,$A9,'2. Raw Votes by Country'!D:D,"ESP"),0) -> 0 | P9: =IFERROR(COUNTIFS('2. Raw Votes by Country'!B:B,$A9,'2. Raw Votes by Country'!D:D,"IND"),0) -> 0 | Q9: =IFERROR(COUNTIFS('2. Raw Votes by Country'!B:B,$A9,'2. Raw Votes by Country'!D:D,"BRA"),0) -> 0 | R9: =IFERROR(COUNTIFS('2. Raw Votes by Country'!B:B,$A9,'2. Raw Votes by Country'!D:D,"SGP"),0) -> 0 | S9: =IFERROR(COUNTIFS('2. Raw Votes by Country'!B:B,$A9,'2. Raw Votes by Country'!D:D,"HKG"),0) -> 0 | T9: =IFERROR(COUNTIFS('2. Raw Votes by Country'!B:B,$A9,'2. Raw Votes by Country'!D:D,"ZAF"),0) -> 0 | U9: =IFERROR(COUNTIFS('2. Raw Votes by Country'!B:B,$A9,'2. Raw Votes by Country'!D:D,"RUS"),0) -> 0 | V9: =SUM(B9:U9) -> 0 | W9: =COUNTIF(B9:U9,">0") -> 0 | X9: =IFERROR(MAX(B9:U9)/V9*100,0) -> 0
B10: =IFERROR(COUNTIFS('2. Raw Votes by Country'!B:B,$A10,'2. Raw Votes by Country'!D:D,"USA"),0) -> 0 | C10: =IFERROR(COUNTIFS('2. Raw Votes by Country'!B:B,$A10,'2. Raw Votes by Country'!D:D,"GBR"),0) -> 0 | D10: =IFERROR(COUNTIFS('2. Raw Votes by Country'!B:B,$A10,'2. Raw Votes by Country'!D:D,"CHN"),0) -> 0 | E10: =IFERROR(COUNTIFS('2. Raw Votes by Country'!B:B,$A10,'2. Raw Votes by Country'!D:D,"DEU"),0) -> 0 | F10: =IFERROR(COUNTIFS('2. Raw Votes by Country'!B:B,$A10,'2. Raw Votes by Country'!D:D,"JPN"),0) -> 0 | G10: =IFERROR(COUNTIFS('2. Raw Votes by Country'!B:B,$A10,'2. Raw Votes by Country'!D:D,"AUS"),0) -> 0 | H10: =IFERROR(COUNTIFS('2. Raw Votes by Country'!B:B,$A10,'2. Raw Votes by Country'!D:D,"FRA"),0) -> 0 | I10: =IFERROR(COUNTIFS('2. Raw Votes by Country'!B:B,$A10,'2. Raw Votes by Country'!D:D,"NLD"),0) -> 0 | J10: =IFERROR(COUNTIFS('2. Raw Votes by Country'!B:B,$A10,'2. Raw Votes by Country'!D:D,"CAN"),0) -> 0 | K10: =IFERROR(COUNTIFS('2. Raw Votes by Country'!B:B,$A10,'2. Raw Votes by Country'!D:D,"KOR"),0) -> 0 | L10: =IFERROR(COUNTIFS('2. Raw Votes by Country'!B:B,$A10,'2. Raw Votes by Country'!D:D,"CHE"),0) -> 0 | M10: =IFERROR(COUNTIFS('2. Raw Votes by Country'!B:B,$A10,'2. Raw Votes by Country'!D:D,"SWE"),0) -> 0 | N10: =IFERROR(COUNTIFS('2. Raw Votes by Country'!B:B,$A10,'2. Raw Votes by Country'!D:D,"ITA"),0) -> 0 | O10: =IFERROR(COUNTIFS('2. Raw Votes by Country'!B:B,$A10,'2. Raw Votes by Country'!D:D,"ESP"),0) -> 0 | P10: =IFERROR(COUNTIFS('2. Raw Votes by Country'!B:B,$A10,'2. Raw Votes by Country'!D:D,"IND"),0) -> 0 | Q10: =IFERROR(COUNTIFS('2. Raw Votes by Country'!B:B,$A10,'2. Raw Votes by Country'!D:D,"BRA"),0) -> 0 | R10: =IFERROR(COUNTIFS('2. Raw Votes by Country'!B:B,$A10,'2. Raw Votes by Country'!D:D,"SGP"),0) -> 0 | S10: =IFERROR(COUNTIFS('2. Raw Votes by Country'!B:B,$A10,'2. Raw Votes by Country'!D:D,"HKG"),0) -> 0 | T10: =IFERROR(COUNTIFS('2. Raw Votes by Country'!B:B,$A10,'2. Raw Votes by Country'!D:D,"ZAF"),0) -> 0 | U10: =IFERROR(COUNTIFS('2. Raw Votes by Country'!B:B,$A10,'2. Raw Votes by Country'!D:D,"RUS"),0) -> 0 | V10: =SUM(B10:U10) -> 0 | W10: =COUNTIF(B10:U10,">0") -> 0 | X10: =IFERROR(MAX(B10:U10)/V10*100,0) -> 0
B11: =IFERROR(COUNTIFS('2. Raw Votes by Country'!B:B,$A11,'2. Raw Votes by Country'!D:D,"USA"),0) -> 0 | C11: =IFERROR(COUNTIFS('2. Raw Votes by Country'!B:B,$A11,'2. Raw Votes by Country'!D:D,"GBR"),0) -> 0 | D11: =IFERROR(COUNTIFS('2. Raw Votes by Country'!B:B,$A11,'2. Raw Votes by Country'!D:D,"CHN"),0) -> 0 | E11: =IFERROR(COUNTIFS('2. Raw Votes by Country'!B:B,$A11,'2. Raw Votes by Country'!D:D,"DEU"),0) -> 0 | F11: =IFERROR(COUNTIFS('2. Raw Votes by Country'!B:B,$A11,'2. Raw Votes by Country'!D:D,"JPN"),0) -> 0 | G11: =IFERROR(COUNTIFS('2. Raw Votes by Country'!B:B,$A11,'2. Raw Votes by Country'!D:D,"AUS"),0) -> 0 | H11: =IFERROR(COUNTIFS('2. Raw Votes by Country'!B:B,$A11,'2. Raw Votes by Country'!D:D,"FRA"),0) -> 0 | I11: =IFERROR(COUNTIFS('2. Raw Votes by Country'!B:B,$A11,'2. Raw Votes by Country'!D:D,"NLD"),0) -> 0 | J11: =IFERROR(COUNTIFS('2. Raw Votes by Country'!B:B,$A11,'2. Raw Votes by Country'!D:D,"CAN"),0) -> 0 | K11: =IFERROR(COUNTIFS('2. Raw Votes by Country'!B:B,$A11,'2. Raw Votes by Country'!D:D,"KOR"),0) -> 0 | L11: =IFERROR(COUNTIFS('2. Raw Votes by Country'!B:B,$A11,'2. Raw Votes by Country'!D:D,"CHE"),0) -> 0 | M11: =IFERROR(COUNTIFS('2. Raw Votes by Country'!B:B,$A11,'2. Raw Votes by Country'!D:D,"SWE"),0) -> 0 | N11: =IFERROR(COUNTIFS('2. Raw Votes by Country'!B:B,$A11,'2. Raw Votes by Country'!D:D,"ITA"),0) -> 0 | O11: =IFERROR(COUNTIFS('2. Raw Votes by Country'!B:B,$A11,'2. Raw Votes by Country'!D:D,"ESP"),0) -> 0 | P11: =IFERROR(COUNTIFS('2. Raw Votes by Country'!B:B,$A11,'2. Raw Votes by Country'!D:D,"IND"),0) -> 0 | Q11: =IFERROR(COUNTIFS('2. Raw Votes by Country'!B:B,$A11,'2. Raw Votes by Country'!D:D,"BRA"),0) -> 0 | R11: =IFERROR(COUNTIFS('2. Raw Votes by Country'!B:B,$A11,'2. Raw Votes by Country'!D:D,"SGP"),0) -> 0 | S11: =IFERROR(COUNTIFS('2. Raw Votes by Country'!B:B,$A11,'2. Raw Votes by Country'!D:D,"HKG"),0) -> 0 | T11: =IFERROR(COUNTIFS('2. Raw Votes by Country'!B:B,$A11,'2. Raw Votes by Country'!D:D,"ZAF"),0) -> 0 | U11: =IFERROR(COUNTIFS('2. Raw Votes by Country'!B:B,$A11,'2. Raw Votes by Country'!D:D,"RUS"),0) -> 0 | V11: =SUM(B11:U11) -> 0 | W11: =COUNTIF(B11:U11,">0") -> 0 | X11: =IFERROR(MAX(B11:U11)/V11*100,0) -> 0
B12: =IFERROR(COUNTIFS('2. Raw Votes by Country'!B:B,$A12,'2. Raw Votes by Country'!D:D,"USA"),0) -> 0 | C12: =IFERROR(COUNTIFS('2. Raw Votes by Country'!B:B,$A12,'2. Raw Votes by Country'!D:D,"GBR"),0) -> 0 | D12: =IFERROR(COUNTIFS('2. Raw Votes by Country'!B:B,$A12,'2. Raw Votes by Country'!D:D,"CHN"),0) -> 0 | E12: =IFERROR(COUNTIFS('2. Raw Votes by Country'!B:B,$A12,'2. Raw Votes by Country'!D:D,"DEU"),0) -> 0 | F12: =IFERROR(COUNTIFS('2. Raw Votes by Country'!B:B,$A12,'2. Raw Votes by Country'!D:D,"JPN"),0) -> 0 | G12: =IFERROR(COUNTIFS('2. Raw Votes by Country'!B:B,$A12,'2. Raw Votes by Country'!D:D,"AUS"),0) -> 0 | H12: =IFERROR(COUNTIFS('2. Raw Votes by Country'!B:B,$A12,'2. Raw Votes by Country'!D:D,"FRA"),0) -> 0 | I12: =IFERROR(COUNTIFS('2. Raw Votes by Country'!B:B,$A12,'2. Raw Votes by Country'!D:D,"NLD"),0) -> 0 | J12: =IFERROR(COUNTIFS('2. Raw Votes by Country'!B:B,$A12,'2. Raw Votes by Country'!D:D,"CAN"),0) -> 0 | K12: =IFERROR(COUNTIFS('2. Raw Votes by Country'!B:B,$A12,'2. Raw Votes by Country'!D:D,"KOR"),0) -> 0 | L12: =IFERROR(COUNTIFS('2. Raw Votes by Country'!B:B,$A12,'2. Raw Votes by Country'!D:D,"CHE"),0) -> 0 | M12: =IFERROR(COUNTIFS('2. Raw Votes by Country'!B:B,$A12,'2. Raw Votes by Country'!D:D,"SWE"),0) -> 0 | N12: =IFERROR(COUNTIFS('2. Raw Votes by Country'!B:B,$A12,'2. Raw Votes by Country'!D:D,"ITA"),0) -> 0 | O12: =IFERROR(COUNTIFS('2. Raw Votes by Country'!B:B,$A12,'2. Raw Votes by Country'!D:D,"ESP"),0) -> 0 | P12: =IFERROR(COUNTIFS('2. Raw Votes by Country'!B:B,$A12,'2. Raw Votes by Country'!D:D,"IND"),0) -> 0 | Q12: =IFERROR(COUNTIFS('2. Raw Votes by Country'!B:B,$A12,'2. Raw Votes by Country'!D:D,"BRA"),0) -> 0 | R12: =IFERROR(COUNTIFS('2. Raw Votes by Country'!B:B,$A12,'2. Raw Votes by Country'!D:D,"SGP"),0) -> 0 | S12: =IFERROR(COUNTIFS('2. Raw Votes by Country'!B:B,$A12,'2. Raw Votes by Country'!D:D,"HKG"),0) -> 0 | T12: =IFERROR(COUNTIFS('2. Raw Votes by Country'!B:B,$A12,'2. Raw Votes by Country'!D:D,"ZAF"),0) -> 0 | U12: =IFERROR(COUNTIFS('2. Raw Votes by Country'!B:B,$A12,'2. Raw Votes by Country'!D:D,"RUS"),0) -> 0 | V12: =SUM(B12:U12) -> 0 | W12: =COUNTIF(B12:U12,">0") -> 0 | X12: =IFERROR(MAX(B12:U12)/V12*100,0) -> 0
B13: =IFERROR(COUNTIFS('2. Raw Votes by Country'!B:B,$A13,'2. Raw Votes by Country'!D:D,"USA"),0) -> 0 | C13: =IFERROR(COUNTIFS('2. Raw Votes by Country'!B:B,$A13,'2. Raw Votes by Country'!D:D,"GBR"),0) -> 0 | D13: =IFERROR(COUNTIFS('2. Raw Votes by Country'!B:B,$A13,'2. Raw Votes by Country'!D:D,"CHN"),0) -> 0 | E13: =IFERROR(COUNTIFS('2. Raw Votes by Country'!B:B,$A13,'2. Raw Votes by Country'!D:D,"DEU"),0) -> 0 | F13: =IFERROR(COUNTIFS('2. Raw Votes by Country'!B:B,$A13,'2. Raw Votes by Country'!D:D,"JPN"),0) -> 0 | G13: =IFERROR(COUNTIFS('2. Raw Votes by Country'!B:B,$A13,'2. Raw Votes by Country'!D:D,"AUS"),0) -> 0 | H13: =IFERROR(COUNTIFS('2. Raw Votes by Country'!B:B,$A13,'2. Raw Votes by Country'!D:D,"FRA"),0) -> 0 | I13: =IFERROR(COUNTIFS('2. Raw Votes by Country'!B:B,$A13,'2. Raw Votes by Country'!D:D,"NLD"),0) -> 0 | J13: =IFERROR(COUNTIFS('2. Raw Votes by Country'!B:B,$A13,'2. Raw Votes by Country'!D:D,"CAN"),0) -> 0 | K13: =IFERROR(COUNTIFS('2. Raw Votes by Country'!B:B,$A13,'2. Raw Votes by Country'!D:D,"KOR"),0) -> 0 | L13: =IFERROR(COUNTIFS('2. Raw Votes by Country'!B:B,$A13,'2. Raw Votes by Country'!D:D,"CHE"),0) -> 0 | M13: =IFERROR(COUNTIFS('2. Raw Votes by Country'!B:B,$A13,'2. Raw Votes by Country'!D:D,"SWE"),0) -> 0 | N13: =IFERROR(COUNTIFS('2. Raw Votes by Country'!B:B,$A13,'2. Raw Votes by Country'!D:D,"ITA"),0) -> 0 | O13: =IFERROR(COUNTIFS('2. Raw Votes by Country'!B:B,$A13,'2. Raw Votes by Country'!D:D,"ESP"),0) -> 0 | P13: =IFERROR(COUNTIFS('2. Raw Votes by Country'!B:B,$A13,'2. Raw Votes by Country'!D:D,"IND"),0) -> 0 | Q13: =IFERROR(COUNTIFS('2. Raw Votes by Country'!B:B,$A13,'2. Raw Votes by Country'!D:D,"BRA"),0) -> 0 | R13: =IFERROR(COUNTIFS('2. Raw Votes by Country'!B:B,$A13,'2. Raw Votes by Country'!D:D,"SGP"),0) -> 0 | S13: =IFERROR(COUNTIFS('2. Raw Votes by Country'!B:B,$A13,'2. Raw Votes by Country'!D:D,"HKG"),0) -> 0 | T13: =IFERROR(COUNTIFS('2. Raw Votes by Country'!B:B,$A13,'2. Raw Votes by Country'!D:D,"ZAF"),0) -> 0 | U13: =IFERROR(COUNTIFS('2. Raw Votes by Country'!B:B,$A13,'2. Raw Votes by Country'!D:D,"RUS"),0) -> 0 | V13: =SUM(B13:U13) -> 0 | W13: =COUNTIF(B13:U13,">0") -> 0 | X13: =IFERROR(MAX(B13:U13)/V13*100,0) -> 0
B14: =IFERROR(COUNTIFS('2. Raw Votes by Country'!B:B,$A14,'2. Raw Votes by Country'!D:D,"USA"),0) -> 0 | C14: =IFERROR(COUNTIFS('2. Raw Votes by Country'!B:B,$A14,'2. Raw Votes by Country'!D:D,"GBR"),0) -> 0 | D14: =IFERROR(COUNTIFS('2. Raw Votes by Country'!B:B,$A14,'2. Raw Votes by Country'!D:D,"CHN"),0) -> 0 | E14: =IFERROR(COUNTIFS('2. Raw Votes by Country'!B:B,$A14,'2. Raw Votes by Country'!D:D,"DEU"),0) -> 0 | F14: =IFERROR(COUNTIFS('2. Raw Votes by Country'!B:B,$A14,'2. Raw Votes by Country'!D:D,"JPN"),0) -> 0 | G14: =IFERROR(COUNTIFS('2. Raw Votes by Country'!B:B,$A14,'2. Raw Votes by Country'!D:D,"AUS"),0) -> 0 | H14: =IFERROR(COUNTIFS('2. Raw Votes by Country'!B:B,$A14,'2. Raw Votes by Country'!D:D,"FRA"),0) -> 0 | I14: =IFERROR(COUNTIFS('2. Raw Votes by Country'!B:B,$A14,'2. Raw Votes by Country'!D:D,"NLD"),0) -> 0 | J14: =IFERROR(COUNTIFS('2. Raw Votes by Country'!B:B,$A14,'2. Raw Votes by Country'!D:D,"CAN"),0) -> 0 | K14: =IFERROR(COUNTIFS('2. Raw Votes by Country'!B:B,$A14,'2. Raw Votes by Country'!D:D,"KOR"),0) -> 0 | L14: =IFERROR(COUNTIFS('2. Raw Votes by Country'!B:B,$A14,'2. Raw Votes by Country'!D:D,"CHE"),0) -> 0 | M14: =IFERROR(COUNTIFS('2. Raw Votes by Country'!B:B,$A14,'2. Raw Votes by Country'!D:D,"SWE"),0) -> 0 | N14: =IFERROR(COUNTIFS('2. Raw Votes by Country'!B:B,$A14,'2. Raw Votes by Country'!D:D,"ITA"),0) -> 0 | O14: =IFERROR(COUNTIFS('2. Raw Votes by Country'!B:B,$A14,'2. Raw Votes by Country'!D:D,"ESP"),0) -> 0 | P14: =IFERROR(COUNTIFS('2. Raw Votes by Country'!B:B,$A14,'2. Raw Votes by Country'!D:D,"IND"),0) -> 0 | Q14: =IFERROR(COUNTIFS('2. Raw Votes by Country'!B:B,$A14,'2. Raw Votes by Country'!D:D,"BRA"),0) -> 0 | R14: =IFERROR(COUNTIFS('2. Raw Votes by Country'!B:B,$A14,'2. Raw Votes by Country'!D:D,"SGP"),0) -> 0 | S14: =IFERROR(COUNTIFS('2. Raw Votes by Country'!B:B,$A14,'2. Raw Votes by Country'!D:D,"HKG"),0) -> 0 | T14: =IFERROR(COUNTIFS('2. Raw Votes by Country'!B:B,$A14,'2. Raw Votes by Country'!D:D,"ZAF"),0) -> 0 | U14: =IFERROR(COUNTIFS('2. Raw Votes by Country'!B:B,$A14,'2. Raw Votes by Country'!D:D,"RUS"),0) -> 0 | V14: =SUM(B14:U14) -> 0 | W14: =COUNTIF(B14:U14,">0") -> 0 | X14: =IFERROR(MAX(B14:U14)/V14*100,0) -> 0
B15: =IFERROR(COUNTIFS('2. Raw Votes by Country'!B:B,$A15,'2. Raw Votes by Country'!D:D,"USA"),0) -> 0 | C15: =IFERROR(COUNTIFS('2. Raw Votes by Country'!B:B,$A15,'2. Raw Votes by Country'!D:D,"GBR"),0) -> 0 | D15: =IFERROR(COUNTIFS('2. Raw Votes by Country'!B:B,$A15,'2. Raw Votes by Country'!D:D,"CHN"),0) -> 0 | E15: =IFERROR(COUNTIFS('2. Raw Votes by Country'!B:B,$A15,'2. Raw Votes by Country'!D:D,"DEU"),0) -> 0 | F15: =IFERROR(COUNTIFS('2. Raw Votes by Country'!B:B,$A15,'2. Raw Votes by Country'!D:D,"JPN"),0) -> 0 | G15: =IFERROR(COUNTIFS('2. Raw Votes by Country'!B:B,$A15,'2. Raw Votes by Country'!D:D,"AUS"),0) -> 0 | H15: =IFERROR(COUNTIFS('2. Raw Votes by Country'!B:B,$A15,'2. Raw Votes by Country'!D:D,"FRA"),0) -> 0 | I15: =IFERROR(COUNTIFS('2. Raw Votes by Country'!B:B,$A15,'2. Raw Votes by Country'!D:D,"NLD"),0) -> 0 | J15: =IFERROR(COUNTIFS('2. Raw Votes by Country'!B:B,$A15,'2. Raw Votes by Country'!D:D,"CAN"),0) -> 0 | K15: =IFERROR(COUNTIFS('2. Raw Votes by Country'!B:B,$A15,'2. Raw Votes by Country'!D:D,"KOR"),0) -> 0 | L15: =IFERROR(COUNTIFS('2. Raw Votes by Country'!B:B,$A15,'2. Raw Votes by Country'!D:D,"CHE"),0) -> 0 | M15: =IFERROR(COUNTIFS('2. Raw Votes by Country'!B:B,$A15,'2. Raw Votes by Country'!D:D,"SWE"),0) -> 0 | N15: =IFERROR(COUNTIFS('2. Raw Votes by Country'!B:B,$A15,'2. Raw Votes by Country'!D:D,"ITA"),0) -> 0 | O15: =IFERROR(COUNTIFS('2. Raw Votes by Country'!B:B,$A15,'2. Raw Votes by Country'!D:D,"ESP"),0) -> 0 | P15: =IFERROR(COUNTIFS('2. Raw Votes by Country'!B:B,$A15,'2. Raw Votes by Country'!D:D,"IND"),0) -> 0 | Q15: =IFERROR(COUNTIFS('2. Raw Votes by Country'!B:B,$A15,'2. Raw Votes by Country'!D:D,"BRA"),0) -> 0 | R15: =IFERROR(COUNTIFS('2. Raw Votes by Country'!B:B,$A15,'2. Raw Votes by Country'!D:D,"SGP"),0) -> 0 | S15: =IFERROR(COUNTIFS('2. Raw Votes by Country'!B:B,$A15,'2. Raw Votes by Country'!D:D,"HKG"),0) -> 0 | T15: =IFERROR(COUNTIFS('2. Raw Votes by Country'!B:B,$A15,'2. Raw Votes by Country'!D:D,"ZAF"),0) -> 0 | U15: =IFERROR(COUNTIFS('2. Raw Votes by Country'!B:B,$A15,'2. Raw Votes by Country'!D:D,"RUS"),0) -> 0 | V15: =SUM(B15:U15) -> 0 | W15: =COUNTIF(B15:U15,">0") -> 0 | X15: =IFERROR(MAX(B15:U15)/V15*100,0) -> 0
B16: =IFERROR(COUNTIFS('2. Raw Votes by Country'!B:B,$A16,'2. Raw Votes by Country'!D:D,"USA"),0) -> 0 | C16: =IFERROR(COUNTIFS('2. Raw Votes by Country'!B:B,$A16,'2. Raw Votes by Country'!D:D,"GBR"),0) -> 0 | D16: =IFERROR(COUNTIFS('2. Raw Votes by Country'!B:B,$A16,'2. Raw Votes by Country'!D:D,"CHN"),0) -> 0 | E16: =IFERROR(COUNTIFS('2. Raw Votes by Country'!B:B,$A16,'2. Raw Votes by Country'!D:D,"DEU"),0) -> 0 | F16: =IFERROR(COUNTIFS('2. Raw Votes by Country'!B:B,$A16,'2. Raw Votes by Country'!D:D,"JPN"),0) -> 0 | G16: =IFERROR(COUNTIFS('2. Raw Votes by Country'!B:B,$A16,'2. Raw Votes by Country'!D:D,"AUS"),0) -> 0 | H16: =IFERROR(COUNTIFS('2. Raw Votes by Country'!B:B,$A16,'2. Raw Votes by Country'!D:D,"FRA"),0) -> 0 | I16: =IFERROR(COUNTIFS('2. Raw Votes by Country'!B:B,$A16,'2. Raw Votes by Country'!D:D,"NLD"),0) -> 0 | J16: =IFERROR(COUNTIFS('2. Raw Votes by Country'!B:B,$A16,'2. Raw Votes by Country'!D:D,"CAN"),0) -> 0 | K16: =IFERROR(COUNTIFS('2. Raw Votes by Country'!B:B,$A16,'2. Raw Votes by Country'!D:D,"KOR"),0) -> 0 | L16: =IFERROR(COUNTIFS('2. Raw Votes by Country'!B:B,$A16,'2. Raw Votes by Country'!D:D,"CHE"),0) -> 0 | M16: =IFERROR(COUNTIFS('2. Raw Votes by Country'!B:B,$A16,'2. Raw Votes by Country'!D:D,"SWE"),0) -> 0 | N16: =IFERROR(COUNTIFS('2. Raw Votes by Country'!B:B,$A16,'2. Raw Votes by Country'!D:D,"ITA"),0) -> 0 | O16: =IFERROR(COUNTIFS('2. Raw Votes by Country'!B:B,$A16,'2. Raw Votes by Country'!D:D,"ESP"),0) -> 0 | P16: =IFERROR(COUNTIFS('2. Raw Votes by Country'!B:B,$A16,'2. Raw Votes by Country'!D:D,"IND"),0) -> 0 | Q16: =IFERROR(COUNTIFS('2. Raw Votes by Country'!B:B,$A16,'2. Raw Votes by Country'!D:D,"BRA"),0) -> 0 | R16: =IFERROR(COUNTIFS('2. Raw Votes by Country'!B:B,$A16,'2. Raw Votes by Country'!D:D,"SGP"),0) -> 0 | S16: =IFERROR(COUNTIFS('2. Raw Votes by Country'!B:B,$A16,'2. Raw Votes by Country'!D:D,"HKG"),0) -> 0 | T16: =IFERROR(COUNTIFS('2. Raw Votes by Country'!B:B,$A16,'2. Raw Votes by Country'!D:D,"ZAF"),0) -> 0 | U16: =IFERROR(COUNTIFS('2. Raw Votes by Country'!B:B,$A16,'2. Raw Votes by Country'!D:D,"RUS"),0) -> 0 | V16: =SUM(B16:U16) -> 0 | W16: =COUNTIF(B16:U16,">0") -> 0 | X16: =IFERROR(MAX(B16:U16)/V16*100,0) -> 0
... B44: =IFERROR(COUNTIFS('2. Raw Votes by Country'!B:B,$A44,'2. Raw Votes by Country'!D:D,"USA"),0) -> 0 | C44: =IFERROR(COUNTIFS('2. Raw Votes by Country'!B:B,$A44,'2. Raw Votes by Country'!D:D,"GBR"),0) -> 0 | D44: =IFERROR(COUNTIFS('2. Raw Votes by Country'!B:B,$A44,'2. Raw Votes by Country'!D:D,"CHN"),0) -> 0 | E44: =IFERROR(COUNTIFS('2. Raw Votes by Country'!B:B,$A44,'2. Raw Votes by Country'!D:D,"DEU"),0) -> 0 | F44: =IFERROR(COUNTIFS('2. Raw Votes by Country'!B:B,$A44,'2. Raw Votes by Country'!D:D,"JPN"),0) -> 0 | G44: =IFERROR(COUNTIFS('2. Raw Votes by Country'!B:B,$A44,'2. Raw Votes by Country'!D:D,"AUS"),0) -> 0 | H44: =IFERROR(COUNTIFS('2. Raw Votes by Country'!B:B,$A44,'2. Raw Votes by Country'!D:D,"FRA"),0) -> 0 | I44: =IFERROR(COUNTIFS('2. Raw Votes by Country'!B:B,$A44,'2. Raw Votes by Country'!D:D,"NLD"),0) -> 0 | J44: =IFERROR(COUNTIFS('2. Raw Votes by Country'!B:B,$A44,'2. Raw Votes by Country'!D:D,"CAN"),0) -> 0 | K44: =IFERROR(COUNTIFS('2. Raw Votes by Country'!B:B,$A44,'2. Raw Votes by Country'!D:D,"KOR"),0) -> 0 | L44: =IFERROR(COUNTIFS('2. Raw Votes by Country'!B:B,$A44,'2. Raw Votes by Country'!D:D,"CHE"),0) -> 0 | M44: =IFERROR(COUNTIFS('2. Raw Votes by Country'!B:B,$A44,'2. Raw Votes by Country'!D:D,"SWE"),0) -> 0 | N44: =IFERROR(COUNTIFS('2. Raw Votes by Country'!B:B,$A44,'2. Raw Votes by Country'!D:D,"ITA"),0) -> 0 | O44: =IFERROR(COUNTIFS('2. Raw Votes by Country'!B:B,$A44,'2. Raw Votes by Country'!D:D,"ESP"),0) -> 0 | P44: =IFERROR(COUNTIFS('2. Raw Votes by Country'!B:B,$A44,'2. Raw Votes by Country'!D:D,"IND"),0) -> 0 | Q44: =IFERROR(COUNTIFS('2. Raw Votes by Country'!B:B,$A44,'2. Raw Votes by Country'!D:D,"BRA"),0) -> 0 | R44: =IFERROR(COUNTIFS('2. Raw Votes by Country'!B:B,$A44,'2. Raw Votes by Country'!D:D,"SGP"),0) -> 0 | S44: =IFERROR(COUNTIFS('2. Raw Votes by Country'!B:B,$A44,'2. Raw Votes by Country'!D:D,"HKG"),0) -> 0 | T44: =IFERROR(COUNTIFS('2. Raw Votes by Country'!B:B,$A44,'2. Raw Votes by Country'!D:D,"ZAF"),0) -> 0 | U44: =IFERROR(COUNTIFS('2. Raw Votes by Country'!B:B,$A44,'2. Raw Votes by Country'!D:D,"RUS"),0) -> 0 | V44: =SUM(B44:U44) -> 0 | W44: =COUNTIF(B44:U44,">0") -> 0 | X44: =IFERROR(MAX(B44:U44)/V44*100,0) -> 0

Sheet 4. Univ × Continent Matrix
A1: Continental Distribution: University × Respondent Continent
A2: Aggregated view — reveals continental concentration patterns (Europe-heavy? Asia-heavy? Global?)
A4: University Name | B4: Europe | C4: Asia | D4: North America | E4: South America | F4: Oceania | G4: Africa | H4: Total Votes | I4: Unique Continents | J4: Dominant Continent | K4: HHI (Continent)
B5: =IFERROR(COUNTIFS('2. Raw Votes by Country'!B:B,$A5,'2. Raw Votes by Country'!G:G,"Europe"),0) -> 0 | C5: =IFERROR(COUNTIFS('2. Raw Votes by Country'!B:B,$A5,'2. Raw Votes by Country'!G:G,"Asia"),0) -> 0 | D5: =IFERROR(COUNTIFS('2. Raw Votes by Country'!B:B,$A5,'2. Raw Votes by Country'!G:G,"North America"),0) -> 0 | E5: =IFERROR(COUNTIFS('2. Raw Votes by Country'!B:B,$A5,'2. Raw Votes by Country'!G:G,"South America"),0) -> 0 | F5: =IFERROR(COUNTIFS('2. Raw Votes by Country'!B:B,$A5,'2. Raw Votes by Country'!G:G,"Oceania"),0) -> 0 | G5: =IFERROR(COUNTIFS('2. Raw Votes by Country'!B:B,$A5,'2. Raw Votes by Country'!G:G,"Africa"),0) -> 0 | H5: =SUM(B5:G5) -> 0 | I5: =COUNTIF(B5:G5,">0") -> 0 | J5: =IFERROR(INDEX($B$4:$G$4,MATCH(MAX(B5:G5),B5:G5,0)),"") -> Europe | K5: =IFERROR(SUMPRODUCT((B5:G5/H5)^2),0) -> 0
B6: =IFERROR(COUNTIFS('2. Raw Votes by Country'!B:B,$A6,'2. Raw Votes by Country'!G:G,"Europe"),0) -> 0 | C6: =IFERROR(COUNTIFS('2. Raw Votes by Country'!B:B,$A6,'2. Raw Votes by Country'!G:G,"Asia"),0) -> 0 | D6: =IFERROR(COUNTIFS('2. Raw Votes by Country'!B:B,$A6,'2. Raw Votes by Country'!G:G,"North America"),0) -> 0 | E6: =IFERROR(COUNTIFS('2. Raw Votes by Country'!B:B,$A6,'2. Raw Votes by Country'!G:G,"South America"),0) -> 0 | F6: =IFERROR(COUNTIFS('2. Raw Votes by Country'!B:B,$A6,'2. Raw Votes by Country'!G:G,"Oceania"),0) -> 0 | G6: =IFERROR(COUNTIFS('2. Raw Votes by Country'!B:B,$A6,'2. Raw Votes by Country'!G:G,"Africa"),0) -> 0 | H6: =SUM(B6:G6) -> 0 | I6: =COUNTIF(B6:G6,">0") -> 0 | J6: =IFERROR(INDEX($B$4:$G$4,MATCH(MAX(B6:G6),B6:G6,0)),"") -> Europe | K6: =IFERROR(SUMPRODUCT((B6:G6/H6)^2),0) -> 0
B7: =IFERROR(COUNTIFS('2. Raw Votes by Country'!B:B,$A7,'2. Raw Votes by Country'!G:G,"Europe"),0) -> 0 | C7: =IFERROR(COUNTIFS('2. Raw Votes by Country'!B:B,$A7,'2. Raw Votes by Country'!G:G,"Asia"),0) -> 0 | D7: =IFERROR(COUNTIFS('2. Raw Votes by Country'!B:B,$A7,'2. Raw Votes by Country'!G:G,"North America"),0) -> 0 | E7: =IFERROR(COUNTIFS('2. Raw Votes by Country'!B:B,$A7,'2. Raw Votes by Country'!G:G,"South America"),0) -> 0 | F7: =IFERROR(COUNTIFS('2. Raw Votes by Country'!B:B,$A7,'2. Raw Votes by Country'!G:G,"Oceania"),0) -> 0 | G7: =IFERROR(COUNTIFS('2. Raw Votes by Country'!B:B,$A7,'2. Raw Votes by Country'!G:G,"Africa"),0) -> 0 | H7: =SUM(B7:G7) -> 0 | I7: =COUNTIF(B7:G7,">0") -> 0 | J7: =IFERROR(INDEX($B$4:$G$4,MATCH(MAX(B7:G7),B7:G7,0)),"") -> Europe | K7: =IFERROR(SUMPRODUCT((B7:G7/H7)^2),0) -> 0
B8: =IFERROR(COUNTIFS('2. Raw Votes by Country'!B:B,$A8,'2. Raw Votes by Country'!G:G,"Europe"),0) -> 0 | C8: =IFERROR(COUNTIFS('2. Raw Votes by Country'!B:B,$A8,'2. Raw Votes by Country'!G:G,"Asia"),0) -> 0 | D8: =IFERROR(COUNTIFS('2. Raw Votes by Country'!B:B,$A8,'2. Raw Votes by Country'!G:G,"North America"),0) -> 0 | E8: =IFERROR(COUNTIFS('2. Raw Votes by Country'!B:B,$A8,'2. Raw Votes by Country'!G:G,"South America"),0) -> 0 | F8: =IFERROR(COUNTIFS('2. Raw Votes by Country'!B:B,$A8,'2. Raw Votes by Country'!G:G,"Oceania"),0) -> 0 | G8: =IFERROR(COUNTIFS('2. Raw Votes by Country'!B:B,$A8,'2. Raw Votes by Country'!G:G,"Africa"),0) -> 0 | H8: =SUM(B8:G8) -> 0 | I8: =COUNTIF(B8:G8,">0") -> 0 | J8: =IFERROR(INDEX($B$4:$G$4,MATCH(MAX(B8:G8),B8:G8,0)),"") -> Europe | K8: =IFERROR(SUMPRODUCT((B8:G8/H8)^2),0) -> 0
B9: =IFERROR(COUNTIFS('2. Raw Votes by Country'!B:B,$A9,'2. Raw Votes by Country'!G:G,"Europe"),0) -> 0 | C9: =IFERROR(COUNTIFS('2. Raw Votes by Country'!B:B,$A9,'2. Raw Votes by Country'!G:G,"Asia"),0) -> 0 | D9: =IFERROR(COUNTIFS('2. Raw Votes by Country'!B:B,$A9,'2. Raw Votes by Country'!G:G,"North America"),0) -> 0 | E9: =IFERROR(COUNTIFS('2. Raw Votes by Country'!B:B,$A9,'2. Raw Votes by Country'!G:G,"South America"),0) -> 0 | F9: =IFERROR(COUNTIFS('2. Raw Votes by Country'!B:B,$A9,'2. Raw Votes by Country'!G:G,"Oceania"),0) -> 0 | G9: =IFERROR(COUNTIFS('2. Raw Votes by Country'!B:B,$A9,'2. Raw Votes by Country'!G:G,"Africa"),0) -> 0 | H9: =SUM(B9:G9) -> 0 | I9: =COUNTIF(B9:G9,">0") -> 0 | J9: =IFERROR(INDEX($B$4:$G$4,MATCH(MAX(B9:G9),B9:G9,0)),"") -> Europe | K9: =IFERROR(SUMPRODUCT((B9:G9/H9)^2),0) -> 0
B10: =IFERROR(COUNTIFS('2. Raw Votes by Country'!B:B,$A10,'2. Raw Votes by Country'!G:G,"Europe"),0) -> 0 | C10: =IFERROR(COUNTIFS('2. Raw Votes by Country'!B:B,$A10,'2. Raw Votes by Country'!G:G,"Asia"),0) -> 0 | D10: =IFERROR(COUNTIFS('2. Raw Votes by Country'!B:B,$A10,'2. Raw Votes by Country'!G:G,"North America"),0) -> 0 | E10: =IFERROR(COUNTIFS('2. Raw Votes by Country'!B:B,$A10,'2. Raw Votes by Country'!G:G,"South America"),0) -> 0 | F10: =IFERROR(COUNTIFS('2. Raw Votes by Country'!B:B,$A10,'2. Raw Votes by Country'!G:G,"Oceania"),0) -> 0 | G10: =IFERROR(COUNTIFS('2. Raw Votes by Country'!B:B,$A10,'2. Raw Votes by Country'!G:G,"Africa"),0) -> 0 | H10: =SUM(B10:G10) -> 0 | I10: =COUNTIF(B10:G10,">0") -> 0 | J10: =IFERROR(INDEX($B$4:$G$4,MATCH(MAX(B10:G10),B10:G10,0)),"") -> Europe | K10: =IFERROR(SUMPRODUCT((B10:G10/H10)^2),0) -> 0
B11: =IFERROR(COUNTIFS('2. Raw Votes by Country'!B:B,$A11,'2. Raw Votes by Country'!G:G,"Europe"),0) -> 0 | C11: =IFERROR(COUNTIFS('2. Raw Votes by Country'!B:B,$A11,'2. Raw Votes by Country'!G:G,"Asia"),0) -> 0 | D11: =IFERROR(COUNTIFS('2. Raw Votes by Country'!B:B,$A11,'2. Raw Votes by Country'!G:G,"North America"),0) -> 0 | E11: =IFERROR(COUNTIFS('2. Raw Votes by Country'!B:B,$A11,'2. Raw Votes by Country'!G:G,"South America"),0) -> 0 | F11: =IFERROR(COUNTIFS('2. Raw Votes by Country'!B:B,$A11,'2. Raw Votes by Country'!G:G,"Oceania"),0) -> 0 | G11: =IFERROR(COUNTIFS('2. Raw Votes by Country'!B:B,$A11,'2. Raw Votes by Country'!G:G,"Africa"),0) -> 0 | H11: =SUM(B11:G11) -> 0 | I11: =COUNTIF(B11:G11,">0") -> 0 | J11: =IFERROR(INDEX($B$4:$G$4,MATCH(MAX(B11:G11),B11:G11,0)),"") -> Europe | K11: =IFERROR(SUMPRODUCT((B11:G11/H11)^2),0) -> 0
B12: =IFERROR(COUNTIFS('2. Raw Votes by Country'!B:B,$A12,'2. Raw Votes by Country'!G:G,"Europe"),0) -> 0 | C12: =IFERROR(COUNTIFS('2. Raw Votes by Country'!B:B,$A12,'2. Raw Votes by Country'!G:G,"Asia"),0) -> 0 | D12: =IFERROR(COUNTIFS('2. Raw Votes by Country'!B:B,$A12,'2. Raw Votes by Country'!G:G,"North America"),0) -> 0 | E12: =IFERROR(COUNTIFS('2. Raw Votes by Country'!B:B,$A12,'2. Raw Votes by Country'!G:G,"South America"),0) -> 0 | F12: =IFERROR(COUNTIFS('2. Raw Votes by Country'!B:B,$A12,'2. Raw Votes by Country'!G:G,"Oceania"),0) -> 0 | G12: =IFERROR(COUNTIFS('2. Raw Votes by Country'!B:B,$A12,'2. Raw Votes by Country'!G:G,"Africa"),0) -> 0 | H12: =SUM(B12:G12) -> 0 | I12: =COUNTIF(B12:G12,">0") -> 0 | J12: =IFERROR(INDEX($B$4:$G$4,MATCH(MAX(B12:G12),B12:G12,0)),"") -> Europe | K12: =IFERROR(SUMPRODUCT((B12:G12/H12)^2),0) -> 0
B13: =IFERROR(COUNTIFS('2. Raw Votes by Country'!B:B,$A13,'2. Raw Votes by Country'!G:G,"Europe"),0) -> 0 | C13: =IFERROR(COUNTIFS('2. Raw Votes by Country'!B:B,$A13,'2. Raw Votes by Country'!G:G,"Asia"),0) -> 0 | D13: =IFERROR(COUNTIFS('2. Raw Votes by Country'!B:B,$A13,'2. Raw Votes by Country'!G:G,"North America"),0) -> 0 | E13: =IFERROR(COUNTIFS('2. Raw Votes by Country'!B:B,$A13,'2. Raw Votes by Country'!G:G,"South America"),0) -> 0 | F13: =IFERROR(COUNTIFS('2. Raw Votes by Country'!B:B,$A13,'2. Raw Votes by Country'!G:G,"Oceania"),0) -> 0 | G13: =IFERROR(COUNTIFS('2. Raw Votes by Country'!B:B,$A13,'2. Raw Votes by Country'!G:G,"Africa"),0) -> 0 | H13: =SUM(B13:G13) -> 0 | I13: =COUNTIF(B13:G13,">0") -> 0 | J13: =IFERROR(INDEX($B$4:$G$4,MATCH(MAX(B13:G13),B13:G13,0)),"") -> Europe | K13: =IFERROR(SUMPRODUCT((B13:G13/H13)^2),0) -> 0
B14: =IFERROR(COUNTIFS('2. Raw Votes by Country'!B:B,$A14,'2. Raw Votes by Country'!G:G,"Europe"),0) -> 0 | C14: =IFERROR(COUNTIFS('2. Raw Votes by Country'!B:B,$A14,'2. Raw Votes by Country'!G:G,"Asia"),0) -> 0 | D14: =IFERROR(COUNTIFS('2. Raw Votes by Country'!B:B,$A14,'2. Raw Votes by Country'!G:G,"North America"),0) -> 0 | E14: =IFERROR(COUNTIFS('2. Raw Votes by Country'!B:B,$A14,'2. Raw Votes by Country'!G:G,"South America"),0) -> 0 | F14: =IFERROR(COUNTIFS('2. Raw Votes by Country'!B:B,$A14,'2. Raw Votes by Country'!G:G,"Oceania"),0) -> 0 | G14: =IFERROR(COUNTIFS('2. Raw Votes by Country'!B:B,$A14,'2. Raw Votes by Country'!G:G,"Africa"),0) -> 0 | H14: =SUM(B14:G14) -> 0 | I14: =COUNTIF(B14:G14,">0") -> 0 | J14: =IFERROR(INDEX($B$4:$G$4,MATCH(MAX(B14:G14),B14:G14,0)),"") -> Europe | K14: =IFERROR(SUMPRODUCT((B14:G14/H14)^2),0) -> 0
B15: =IFERROR(COUNTIFS('2. Raw Votes by Country'!B:B,$A15,'2. Raw Votes by Country'!G:G,"Europe"),0) -> 0 | C15: =IFERROR(COUNTIFS('2. Raw Votes by Country'!B:B,$A15,'2. Raw Votes by Country'!G:G,"Asia"),0) -> 0 | D15: =IFERROR(COUNTIFS('2. Raw Votes by Country'!B:B,$A15,'2. Raw Votes by Country'!G:G,"North America"),0) -> 0 | E15: =IFERROR(COUNTIFS('2. Raw Votes by Country'!B:B,$A15,'2. Raw Votes by Country'!G:G,"South America"),0) -> 0 | F15: =IFERROR(COUNTIFS('2. Raw Votes by Country'!B:B,$A15,'2. Raw Votes by Country'!G:G,"Oceania"),0) -> 0 | G15: =IFERROR(COUNTIFS('2. Raw Votes by Country'!B:B,$A15,'2. Raw Votes by Country'!G:G,"Africa"),0) -> 0 | H15: =SUM(B15:G15) -> 0 | I15: =COUNTIF(B15:G15,">0") -> 0 | J15: =IFERROR(INDEX($B$4:$G$4,MATCH(MAX(B15:G15),B15:G15,0)),"") -> Europe | K15: =IFERROR(SUMPRODUCT((B15:G15/H15)^2),0) -> 0
B16: =IFERROR(COUNTIFS('2. Raw Votes by Country'!B:B,$A16,'2. Raw Votes by Country'!G:G,"Europe"),0) -> 0 | C16: =IFERROR(COUNTIFS('2. Raw Votes by Country'!B:B,$A16,'2. Raw Votes by Country'!G:G,"Asia"),0) -> 0 | D16: =IFERROR(COUNTIFS('2. Raw Votes by Country'!B:B,$A16,'2. Raw Votes by Country'!G:G,"North America"),0) -> 0 | E16: =IFERROR(COUNTIFS('2. Raw Votes by Country'!B:B,$A16,'2. Raw Votes by Country'!G:G,"South America"),0) -> 0 | F16: =IFERROR(COUNTIFS('2. Raw Votes by Country'!B:B,$A16,'2. Raw Votes by Country'!G:G,"Oceania"),0) -> 0 | G16: =IFERROR(COUNTIFS('2. Raw Votes by Country'!B:B,$A16,'2. Raw Votes by Country'!G:G,"Africa"),0) -> 0 | H16: =SUM(B16:G16) -> 0 | I16: =COUNTIF(B16:G16,">0") -> 0 | J16: =IFERROR(INDEX($B$4:$G$4,MATCH(MAX(B16:G16),B16:G16,0)),"") -> Europe | K16: =IFERROR(SUMPRODUCT((B16:G16/H16)^2),0) -> 0
... B44: =IFERROR(COUNTIFS('2. Raw Votes by Country'!B:B,$A44,'2. Raw Votes by Country'!G:G,"Europe"),0) -> 0 | C44: =IFERROR(COUNTIFS('2. Raw Votes by Country'!B:B,$A44,'2. Raw Votes by Country'!G:G,"Asia"),0) -> 0 | D44: =IFERROR(COUNTIFS('2. Raw Votes by Country'!B:B,$A44,'2. Raw Votes by Country'!G:G,"North America"),0) -> 0 | E44: =IFERROR(COUNTIFS('2. Raw Votes by Country'!B:B,$A44,'2. Raw Votes by Country'!G:G,"South America"),0) -> 0 | F44: =IFERROR(COUNTIFS('2. Raw Votes by Country'!B:B,$A44,'2. Raw Votes by Country'!G:G,"Oceania"),0) -> 0 | G44: =IFERROR(COUNTIFS('2. Raw Votes by Country'!B:B,$A44,'2. Raw Votes by Country'!G:G,"Africa"),0) -> 0 | H44: =SUM(B44:G44) -> 0 | I44: =COUNTIF(B44:G44,">0") -> 0 | J44: =IFERROR(INDEX($B$4:$G$4,MATCH(MAX(B44:G44),B44:G44,0)),"") -> Europe | K44: =IFERROR(SUMPRODUCT((B44:G44/H44)^2),0) -> 0

Sheet 5. Univ × UN Region Matrix
A1: UN Region Distribution: University × Respondent UN Region
A2: World Bank / UN regional groupings — finer granularity than continent for policy alignment
A4: University Name | B4: Americas | C4: Europe & Central Asia | D4: East Asia & Pacific | E4: South Asia | F4: Middle East & North Africa | G4: Sub-Saharan Africa | H4: Total | I4: Unique Regions | J4: HHI (Region)
B5: =IFERROR(COUNTIFS('2. Raw Votes by Country'!B:B,$A5,'2. Raw Votes by Country'!F:F,"Americas"),0) -> 0 | C5: =IFERROR(COUNTIFS('2. Raw Votes by Country'!B:B,$A5,'2. Raw Votes by Country'!F:F,"Europe & Central Asia"),0) -> 0 | D5: =IFERROR(COUNTIFS('2. Raw Votes by Country'!B:B,$A5,'2. Raw Votes by Country'!F:F,"East Asia & Pacific"),0) -> 0 | E5: =IFERROR(COUNTIFS('2. Raw Votes by Country'!B:B,$A5,'2. Raw Votes by Country'!F:F,"South Asia"),0) -> 0 | F5: =IFERROR(COUNTIFS('2. Raw Votes by Country'!B:B,$A5,'2. Raw Votes by Country'!F:F,"Middle East & North Africa"),0) -> 0 | G5: =IFERROR(COUNTIFS('2. Raw Votes by Country'!B:B,$A5,'2. Raw Votes by Country'!F:F,"Sub-Saharan Africa"),0) -> 0 | H5: =SUM(B5:G5) -> 0 | I5: =COUNTIF(B5:G5,">0") -> 0 | J5: =IFERROR(SUMPRODUCT((B5:G5/H5)^2),0) -> 0
B6: =IFERROR(COUNTIFS('2. Raw Votes by Country'!B:B,$A6,'2. Raw Votes by Country'!F:F,"Americas"),0) -> 0 | C6: =IFERROR(COUNTIFS('2. Raw Votes by Country'!B:B,$A6,'2. Raw Votes by Country'!F:F,"Europe & Central Asia"),0) -> 0 | D6: =IFERROR(COUNTIFS('2. Raw Votes by Country'!B:B,$A6,'2. Raw Votes by Country'!F:F,"East Asia & Pacific"),0) -> 0 | E6: =IFERROR(COUNTIFS('2. Raw Votes by Country'!B:B,$A6,'2. Raw Votes by Country'!F:F,"South Asia"),0) -> 0 | F6: =IFERROR(COUNTIFS('2. Raw Votes by Country'!B:B,$A6,'2. Raw Votes by Country'!F:F,"Middle East & North Africa"),0) -> 0 | G6: =IFERROR(COUNTIFS('2. Raw Votes by Country'!B:B,$A6,'2. Raw Votes by Country'!F:F,"Sub-Saharan Africa"),0) -> 0 | H6: =SUM(B6:G6) -> 0 | I6: =COUNTIF(B6:G6,">0") -> 0 | J6: =IFERROR(SUMPRODUCT((B6:G6/H6)^2),0) -> 0
B7: =IFERROR(COUNTIFS('2. Raw Votes by Country'!B:B,$A7,'2. Raw Votes by Country'!F:F,"Americas"),0) -> 0 | C7: =IFERROR(COUNTIFS('2. Raw Votes by Country'!B:B,$A7,'2. Raw Votes by Country'!F:F,"Europe & Central Asia"),0) -> 0 | D7: =IFERROR(COUNTIFS('2. Raw Votes by Country'!B:B,$A7,'2. Raw Votes by Country'!F:F,"East Asia & Pacific"),0) -> 0 | E7: =IFERROR(COUNTIFS('2. Raw Votes by Country'!B:B,$A7,'2. Raw Votes by Country'!F:F,"South Asia"),0) -> 0 | F7: =IFERROR(COUNTIFS('2. Raw Votes by Country'!B:B,$A7,'2. Raw Votes by Country'!F:F,"Middle East & North Africa"),0) -> 0 | G7: =IFERROR(COUNTIFS('2. Raw Votes by Country'!B:B,$A7,'2. Raw Votes by Country'!F:F,"Sub-Saharan Africa"),0) -> 0 | H7: =SUM(B7:G7) -> 0 | I7: =COUNTIF(B7:G7,">0") -> 0 | J7: =IFERROR(SUMPRODUCT((B7:G7/H7)^2),0) -> 0
B8: =IFERROR(COUNTIFS('2. Raw Votes by Country'!B:B,$A8,'2. Raw Votes by Country'!F:F,"Americas"),0) -> 0 | C8: =IFERROR(COUNTIFS('2. Raw Votes by Country'!B:B,$A8,'2. Raw Votes by Country'!F:F,"Europe & Central Asia"),0) -> 0 | D8: =IFERROR(COUNTIFS('2. Raw Votes by Country'!B:B,$A8,'2. Raw Votes by Country'!F:F,"East Asia & Pacific"),0) -> 0 | E8: =IFERROR(COUNTIFS('2. Raw Votes by Country'!B:B,$A8,'2. Raw Votes by Country'!F:F,"South Asia"),0) -> 0 | F8: =IFERROR(COUNTIFS('2. Raw Votes by Country'!B:B,$A8,'2. Raw Votes by Country'!F:F,"Middle East & North Africa"),0) -> 0 | G8: =IFERROR(COUNTIFS('2. Raw Votes by Country'!B:B,$A8,'2. Raw Votes by Country'!F:F,"Sub-Saharan Africa"),0) -> 0 | H8: =SUM(B8:G8) -> 0 | I8: =COUNTIF(B8:G8,">0") -> 0 | J8: =IFERROR(SUMPRODUCT((B8:G8/H8)^2),0) -> 0
B9: =IFERROR(COUNTIFS('2. Raw Votes by Country'!B:B,$A9,'2. Raw Votes by Country'!F:F,"Americas"),0) -> 0 | C9: =IFERROR(COUNTIFS('2. Raw Votes by Country'!B:B,$A9,'2. Raw Votes by Country'!F:F,"Europe & Central Asia"),0) -> 0 | D9: =IFERROR(COUNTIFS('2. Raw Votes by Country'!B:B,$A9,'2. Raw Votes by Country'!F:F,"East Asia & Pacific"),0) -> 0 | E9: =IFERROR(COUNTIFS('2. Raw Votes by Country'!B:B,$A9,'2. Raw Votes by Country'!F:F,"South Asia"),0) -> 0 | F9: =IFERROR(COUNTIFS('2. Raw Votes by Country'!B:B,$A9,'2. Raw Votes by Country'!F:F,"Middle East & North Africa"),0) -> 0 | G9: =IFERROR(COUNTIFS('2. Raw Votes by Country'!B:B,$A9,'2. Raw Votes by Country'!F:F,"Sub-Saharan Africa"),0) -> 0 | H9: =SUM(B9:G9) -> 0 | I9: =COUNTIF(B9:G9,">0") -> 0 | J9: =IFERROR(SUMPRODUCT((B9:G9/H9)^2),0) -> 0
B10: =IFERROR(COUNTIFS('2. Raw Votes by Country'!B:B,$A10,'2. Raw Votes by Country'!F:F,"Americas"),0) -> 0 | C10: =IFERROR(COUNTIFS('2. Raw Votes by Country'!B:B,$A10,'2. Raw Votes by Country'!F:F,"Europe & Central Asia"),0) -> 0 | D10: =IFERROR(COUNTIFS('2. Raw Votes by Country'!B:B,$A10,'2. Raw Votes by Country'!F:F,"East Asia & Pacific"),0) -> 0 | E10: =IFERROR(COUNTIFS('2. Raw Votes by Country'!B:B,$A10,'2. Raw Votes by Country'!F:F,"South Asia"),0) -> 0 | F10: =IFERROR(COUNTIFS('2. Raw Votes by Country'!B:B,$A10,'2. Raw Votes by Country'!F:F,"Middle East & North Africa"),0) -> 0 | G10: =IFERROR(COUNTIFS('2. Raw Votes by Country'!B:B,$A10,'2. Raw Votes by Country'!F:F,"Sub-Saharan Africa"),0) -> 0 | H10: =SUM(B10:G10) -> 0 | I10: =COUNTIF(B10:G10,">0") -> 0 | J10: =IFERROR(SUMPRODUCT((B10:G10/H10)^2),0) -> 0
B11: =IFERROR(COUNTIFS('2. Raw Votes by Country'!B:B,$A11,'2. Raw Votes by Country'!F:F,"Americas"),0) -> 0 | C11: =IFERROR(COUNTIFS('2. Raw Votes by Country'!B:B,$A11,'2. Raw Votes by Country'!F:F,"Europe & Central Asia"),0) -> 0 | D11: =IFERROR(COUNTIFS('2. Raw Votes by Country'!B:B,$A11,'2. Raw Votes by Country'!F:F,"East Asia & Pacific"),0) -> 0 | E11: =IFERROR(COUNTIFS('2. Raw Votes by Country'!B:B,$A11,'2. Raw Votes by Country'!F:F,"South Asia"),0) -> 0 | F11: =IFERROR(COUNTIFS('2. Raw Votes by Country'!B:B,$A11,'2. Raw Votes by Country'!F:F,"Middle East & North Africa"),0) -> 0 | G11: =IFERROR(COUNTIFS('2. Raw Votes by Country'!B:B,$A11,'2. Raw Votes by Country'!F:F,"Sub-Saharan Africa"),0) -> 0 | H11: =SUM(B11:G11) -> 0 | I11: =COUNTIF(B11:G11,">0") -> 0 | J11: =IFERROR(SUMPRODUCT((B11:G11/H11)^2),0) -> 0
B12: =IFERROR(COUNTIFS('2. Raw Votes by Country'!B:B,$A12,'2. Raw Votes by Country'!F:F,"Americas"),0) -> 0 | C12: =IFERROR(COUNTIFS('2. Raw Votes by Country'!B:B,$A12,'2. Raw Votes by Country'!F:F,"Europe & Central Asia"),0) -> 0 | D12: =IFERROR(COUNTIFS('2. Raw Votes by Country'!B:B,$A12,'2. Raw Votes by Country'!F:F,"East Asia & Pacific"),0) -> 0 | E12: =IFERROR(COUNTIFS('2. Raw Votes by Country'!B:B,$A12,'2. Raw Votes by Country'!F:F,"South Asia"),0) -> 0 | F12: =IFERROR(COUNTIFS('2. Raw Votes by Country'!B:B,$A12,'2. Raw Votes by Country'!F:F,"Middle East & North Africa"),0) -> 0 | G12: =IFERROR(COUNTIFS('2. Raw Votes by Country'!B:B,$A12,'2. Raw Votes by Country'!F:F,"Sub-Saharan Africa"),0) -> 0 | H12: =SUM(B12:G12) -> 0 | I12: =COUNTIF(B12:G12,">0") -> 0 | J12: =IFERROR(SUMPRODUCT((B12:G12/H12)^2),0) -> 0
B13: =IFERROR(COUNTIFS('2. Raw Votes by Country'!B:B,$A13,'2. Raw Votes by Country'!F:F,"Americas"),0) -> 0 | C13: =IFERROR(COUNTIFS('2. Raw Votes by Country'!B:B,$A13,'2. Raw Votes by Country'!F:F,"Europe & Central Asia"),0) -> 0 | D13: =IFERROR(COUNTIFS('2. Raw Votes by Country'!B:B,$A13,'2. Raw Votes by Country'!F:F,"East Asia & Pacific"),0) -> 0 | E13: =IFERROR(COUNTIFS('2. Raw Votes by Country'!B:B,$A13,'2. Raw Votes by Country'!F:F,"South Asia"),0) -> 0 | F13: =IFERROR(COUNTIFS('2. Raw Votes by Country'!B:B,$A13,'2. Raw Votes by Country'!F:F,"Middle East & North Africa"),0) -> 0 | G13: =IFERROR(COUNTIFS('2. Raw Votes by Country'!B:B,$A13,'2. Raw Votes by Country'!F:F,"Sub-Saharan Africa"),0) -> 0 | H13: =SUM(B13:G13) -> 0 | I13: =COUNTIF(B13:G13,">0") -> 0 | J13: =IFERROR(SUMPRODUCT((B13:G13/H13)^2),0) -> 0
B14: =IFERROR(COUNTIFS('2. Raw Votes by Country'!B:B,$A14,'2. Raw Votes by Country'!F:F,"Americas"),0) -> 0 | C14: =IFERROR(COUNTIFS('2. Raw Votes by Country'!B:B,$A14,'2. Raw Votes by Country'!F:F,"Europe & Central Asia"),0) -> 0 | D14: =IFERROR(COUNTIFS('2. Raw Votes by Country'!B:B,$A14,'2. Raw Votes by Country'!F:F,"East Asia & Pacific"),0) -> 0 | E14: =IFERROR(COUNTIFS('2. Raw Votes by Country'!B:B,$A14,'2. Raw Votes by Country'!F:F,"South Asia"),0) -> 0 | F14: =IFERROR(COUNTIFS('2. Raw Votes by Country'!B:B,$A14,'2. Raw Votes by Country'!F:F,"Middle East & North Africa"),0) -> 0 | G14: =IFERROR(COUNTIFS('2. Raw Votes by Country'!B:B,$A14,'2. Raw Votes by Country'!F:F,"Sub-Saharan Africa"),0) -> 0 | H14: =SUM(B14:G14) -> 0 | I14: =COUNTIF(B14:G14,">0") -> 0 | J14: =IFERROR(SUMPRODUCT((B14:G14/H14)^2),0) -> 0
B15: =IFERROR(COUNTIFS('2. Raw Votes by Country'!B:B,$A15,'2. Raw Votes by Country'!F:F,"Americas"),0) -> 0 | C15: =IFERROR(COUNTIFS('2. Raw Votes by Country'!B:B,$A15,'2. Raw Votes by Country'!F:F,"Europe & Central Asia"),0) -> 0 | D15: =IFERROR(COUNTIFS('2. Raw Votes by Country'!B:B,$A15,'2. Raw Votes by Country'!F:F,"East Asia & Pacific"),0) -> 0 | E15: =IFERROR(COUNTIFS('2. Raw Votes by Country'!B:B,$A15,'2. Raw Votes by Country'!F:F,"South Asia"),0) -> 0 | F15: =IFERROR(COUNTIFS('2. Raw Votes by Country'!B:B,$A15,'2. Raw Votes by Country'!F:F,"Middle East & North Africa"),0) -> 0 | G15: =IFERROR(COUNTIFS('2. Raw Votes by Country'!B:B,$A15,'2. Raw Votes by Country'!F:F,"Sub-Saharan Africa"),0) -> 0 | H15: =SUM(B15:G15) -> 0 | I15: =COUNTIF(B15:G15,">0") -> 0 | J15: =IFERROR(SUMPRODUCT((B15:G15/H15)^2),0) -> 0
B16: =IFERROR(COUNTIFS('2. Raw Votes by Country'!B:B,$A16,'2. Raw Votes by Country'!F:F,"Americas"),0) -> 0 | C16: =IFERROR(COUNTIFS('2. Raw Votes by Country'!B:B,$A16,'2. Raw Votes by Country'!F:F,"Europe & Central Asia"),0) -> 0 | D16: =IFERROR(COUNTIFS('2. Raw Votes by Country'!B:B,$A16,'2. Raw Votes by Country'!F:F,"East Asia & Pacific"),0) -> 0 | E16: =IFERROR(COUNTIFS('2. Raw Votes by Country'!B:B,$A16,'2. Raw Votes by Country'!F:F,"South Asia"),0) -> 0 | F16: =IFERROR(COUNTIFS('2. Raw Votes by Country'!B:B,$A16,'2. Raw Votes by Country'!F:F,"Middle East & North Africa"),0) -> 0 | G16: =IFERROR(COUNTIFS('2. Raw Votes by Country'!B:B,$A16,'2. Raw Votes by Country'!F:F,"Sub-Saharan Africa"),0) -> 0 | H16: =SUM(B16:G16) -> 0 | I16: =COUNTIF(B16:G16,">0") -> 0 | J16: =IFERROR(SUMPRODUCT((B16:G16/H16)^2),0) -> 0
... B44: =IFERROR(COUNTIFS('2. Raw Votes by Country'!B:B,$A44,'2. Raw Votes by Country'!F:F,"Americas"),0) -> 0 | C44: =IFERROR(COUNTIFS('2. Raw Votes by Country'!B:B,$A44,'2. Raw Votes by Country'!F:F,"Europe & Central Asia"),0) -> 0 | D44: =IFERROR(COUNTIFS('2. Raw Votes by Country'!B:B,$A44,'2. Raw Votes by Country'!F:F,"East Asia & Pacific"),0) -> 0 | E44: =IFERROR(COUNTIFS('2. Raw Votes by Country'!B:B,$A44,'2. Raw Votes by Country'!F:F,"South Asia"),0) -> 0 | F44: =IFERROR(COUNTIFS('2. Raw Votes by Country'!B:B,$A44,'2. Raw Votes by Country'!F:F,"Middle East & North Africa"),0) -> 0 | G44: =IFERROR(COUNTIFS('2. Raw Votes by Country'!B:B,$A44,'2. Raw Votes by Country'!F:F,"Sub-Saharan Africa"),0) -> 0 | H44: =SUM(B44:G44) -> 0 | I44: =COUNTIF(B44:G44,">0") -> 0 | J44: =IFERROR(SUMPRODUCT((B44:G44/H44)^2),0) -> 0

Sheet 6. Geo Entropy Calc
A1: Geographic Entropy — Per-University H_geo Calculation
A2: H_geo = −Σ (nᵢ/N) × log₂(nᵢ/N) over country distribution | Higher H_geo = broader geographic reputation
A3: S.No. | B3: University Name | C3: Total Votes | D3: Unique Countries | E3: H_geo (Geographic Entropy) | F3: Max H_geo = log₂(K) | G3: Normalized H_geo (H/Hmax) | H3: Geo Diversity Score (0–100) | I3: Diversity Tier
A4: 1 | C4: =IFERROR(VLOOKUP(B4,'3. Univ × Country Matrix'!$A$5:$V$44,22,FALSE()),0) -> 0 | D4: =IFERROR(VLOOKUP(B4,'3. Univ × Country Matrix'!$A$5:$W$44,23,FALSE()),0) -> 0 | E4: =IFERROR(VLOOKUP(B4,'7. Entropy Helper'!$A$4:$C$43,3,FALSE()),0) -> 0 | F4: =IF(D4>1,LOG(D4,2),0) -> 0 | G4: =IFERROR(IF(F4>0,E4/F4,0),0) -> 0 | H4: =IFERROR(IF(MAX($E$4:$E$43)>0,E4/MAX($E$4:$E$43)*100,0),0) -> 0 | I4: =IF(H4>=80,"Very High",IF(H4>=60,"High",IF(H4>=40,"Medium",IF(H4>=20,"Low","Very Low")))) -> Very Low
