Workbook

Sheet Methodology Overview
A1: THE WUR — Teaching (29.5%) → Doctorates Awarded-to-Academic Staff Ratio (5.5%)
A2: Measures Doctoral Productivity & Supervision Capacity | Higher Ratio = Stronger Research-Led Teaching
A4: # | B4: Component | C4: Description & Methodology | D4: Weight
A5: 1 | B5: Doctorates Awarded-to-Staff Ratio | C5: Number of doctoral degrees (PhD) conferred in the most recent academic year, divided by academic staff FTE. Computed as: Doctorates Awarded (annual) ÷ Academic Staff FTE. Higher ratio = more productive doctoral supervision ecosystem. Signals that the institution's faculty are actively supervising and graduating PhD students, which enriches the overall teaching environment. | D5: 5.5% of WUR
A6: 2 | B6: Doctorates Awarded (Numerator) | C6: Count of doctoral degrees conferred (not enrolled — AWARDED/COMPLETED) in the most recent academic year or averaged over 3 years. Includes: PhD degrees, professional doctorates (EdD, DBA, MD-PhD) if thesis-based, and equivalent research doctorates. Excludes: honorary doctorates, MPhil/MRes, and degrees conferred but not yet formally gazetted. | D6: Numerator
A7: 3 | B7: Academic Staff FTE (Denominator) | C7: Same THE-compliant definition used in Staff-to-Student Ratio: full-time equivalent academic & research staff with teaching duties. Professors, associate professors, assistant professors, lecturers, research fellows WITH teaching. Excludes: admin, technical, support staff, research-only staff, visiting faculty below threshold. | D7: Denominator
A8: 4 | B8: Scoring Logic | C8: THE normalizes the raw ratio using z-scoring across all ranked universities. Higher ratio = higher z-score = better rank. Research-intensive universities with large, efficient doctoral programmes relative to faculty size score highest. This indicator rewards both SCALE (many doctorates) and EFFICIENCY (relative to staff size). | D8: Normalization
A9: 5 | B9: Context: Teaching Pillar | C9: Teaching (29.5%) = Teaching Reputation (15%) + Staff-to-Student Ratio (4.5%) + Doctorates Awarded per Staff (5.5%) + Doctorate-to-Bachelor's Ratio (2%) + Institutional Income (2.5%). At 5.5%, this is the SECOND-LARGEST sub-indicator in Teaching after reputation. Difficulty: 🟡 Moderate (1–3 years) — depends on PhD completion pipeline. | D9: 5.5% of 29.5%
A11: Improvement Strategies (from Strategic Roadmap)
A12: • Increase PhD completions — focus on reducing time-to-completion and attrition.
A13: • Strengthen supervisor training, doctoral review boards, and progress monitoring.
A14: • Establish seed funding for PhD support (stipends, conference travel, lab access).
A15: • Set up Centres of Excellence (CoEs) to attract and accelerate doctoral research.
A16: • Implement structured doctoral programmes with milestones and annual progress reviews.
A17: • Partner with industry for co-funded PhDs to increase capacity without full university funding.
A18: • Recruit postdoctoral fellows to assist with PhD supervision (increases throughput without new faculty).
A19: • Improve research infrastructure (labs, libraries, HPC) to reduce PhD duration.
A20: • Difficulty: 🟡 Moderate (1–3 years). Depends on PhD pipeline; completions lag enrolment by 3–5 years.

Sheet 1. Doctorates Awarded
A1: Doctorates Awarded — Annual Count by Discipline & Type
A2: PhD degrees CONFERRED (not enrolled) in academic year | Includes professional doctorates if thesis-based
A3: S.No. | B3: University Name | C3: Country | D3: PhD Awarded (Science/Engg) | E3: PhD Awarded (Arts/Humanities/SS) | F3: PhD Awarded (Health/Medical) | G3: PhD Awarded (Other Disciplines) | H3: Professional Doctorates (EdD/DBA/MD-PhD) | I3: Total Doctorates Awarded | J3: Reporting Year
A4: 1 | I4: =SUM(D4:H4) -> 0
A5: 2 | I5: =SUM(D5:H5) -> 0
A6: 3 | I6: =SUM(D6:H6) -> 0
A7: 4 | I7: =SUM(D7:H7) -> 0
A8: 5 | I8: =SUM(D8:H8) -> 0
A9: 6 | I9: =SUM(D9:H9) -> 0
A10: 7 | I10: =SUM(D10:H10) -> 0
A11: 8 | I11: =SUM(D11:H11) -> 0
A12: 9 | I12: =SUM(D12:H12) -> 0
A13: 10 | I13: =SUM(D13:H13) -> 0
A14: 11 | I14: =SUM(D14:H14) -> 0
A15: 12 | I15: =SUM(D15:H15) -> 0
... A33: 30 | I33: =SUM(D33:H33) -> 0
A35: 5-Year Doctoral Award History (Per University)
A36: S.No. | B36: University Name | C36: Country | D36: Year 1 Awards | E36: Year 2 Awards | F36: Year 3 Awards | G36: Year 4 Awards | H36: Year 5 Awards (Current) | I36: 5-Year Total | J36: 3-Year Average
A37: 1 | I37: =SUM(D37:H37) -> 0 | J37: =IF(COUNT(F37:H37)>0,AVERAGE(F37:H37),0) -> 0
A38: 2 | I38: =SUM(D38:H38) -> 0 | J38: =IF(COUNT(F38:H38)>0,AVERAGE(F38:H38),0) -> 0
A39: 3 | I39: =SUM(D39:H39) -> 0 | J39: =IF(COUNT(F39:H39)>0,AVERAGE(F39:H39),0) -> 0
A40: 4 | I40: =SUM(D40:H40) -> 0 | J40: =IF(COUNT(F40:H40)>0,AVERAGE(F40:H40),0) -> 0
A41: 5 | I41: =SUM(D41:H41) -> 0 | J41: =IF(COUNT(F41:H41)>0,AVERAGE(F41:H41),0) -> 0
A42: 6 | I42: =SUM(D42:H42) -> 0 | J42: =IF(COUNT(F42:H42)>0,AVERAGE(F42:H42),0) -> 0
A43: 7 | I43: =SUM(D43:H43) -> 0 | J43: =IF(COUNT(F43:H43)>0,AVERAGE(F43:H43),0) -> 0
A44: 8 | I44: =SUM(D44:H44) -> 0 | J44: =IF(COUNT(F44:H44)>0,AVERAGE(F44:H44),0) -> 0
A45: 9 | I45: =SUM(D45:H45) -> 0 | J45: =IF(COUNT(F45:H45)>0,AVERAGE(F45:H45),0) -> 0
A46: 10 | I46: =SUM(D46:H46) -> 0 | J46: =IF(COUNT(F46:H46)>0,AVERAGE(F46:H46),0) -> 0
A47: 11 | I47: =SUM(D47:H47) -> 0 | J47: =IF(COUNT(F47:H47)>0,AVERAGE(F47:H47),0) -> 0
A48: 12 | I48: =SUM(D48:H48) -> 0 | J48: =IF(COUNT(F48:H48)>0,AVERAGE(F48:H48),0) -> 0
... A56: 20 | I56: =SUM(D56:H56) -> 0 | J56: =IF(COUNT(F56:H56)>0,AVERAGE(F56:H56),0) -> 0
A59: Department-Level Doctoral Awards (Per University, Current Year)
A60: S.No. | B60: Department / School | C60: Faculty / College | D60: PhD Awards (Year) | E60: Prof. Doctorates | F60: Total Awards | G60: PhD Students Currently Enrolled | H60: Expected Awards Next Year | I60: Completion Rate (%) | J60: University Name
A61: 1 | F61: =D61+E61 -> 0 | I61: =IF(G61>0,F61/G61*100,0) -> 0
A62: 2 | F62: =D62+E62 -> 0 | I62: =IF(G62>0,F62/G62*100,0) -> 0
A63: 3 | F63: =D63+E63 -> 0 | I63: =IF(G63>0,F63/G63*100,0) -> 0
A64: 4 | F64: =D64+E64 -> 0 | I64: =IF(G64>0,F64/G64*100,0) -> 0
A65: 5 | F65: =D65+E65 -> 0 | I65: =IF(G65>0,F65/G65*100,0) -> 0
A66: 6 | F66: =D66+E66 -> 0 | I66: =IF(G66>0,F66/G66*100,0) -> 0
A67: 7 | F67: =D67+E67 -> 0 | I67: =IF(G67>0,F67/G67*100,0) -> 0
...

Sheet 2. Academic Staff FTE
A1: Academic Staff — Full-Time Equivalent (FTE) | Same Definition as Staff-to-Student Ratio
A2: THE-compliant: professors, assoc/asst professors, lecturers, research fellows with teaching | Excludes admin/support/research-only
A3: S.No. | B3: University Name | C3: Country | D3: Professors (FTE) | E3: Associate Prof. (FTE) | F3: Assistant Prof. (FTE) | G3: Lecturers (FTE) | H3: Research Fellows (Teaching) FTE | I3: Other Teaching Staff FTE | J3: Total Academic Staff FTE | K3: Reporting Year
A4: 1 | J4: =SUM(D4:I4) -> 0
A5: 2 | J5: =SUM(D5:I5) -> 0
A6: 3 | J6: =SUM(D6:I6) -> 0
A7: 4 | J7: =SUM(D7:I7) -> 0
A8: 5 | J8: =SUM(D8:I8) -> 0
A9: 6 | J9: =SUM(D9:I9) -> 0
A10: 7 | J10: =SUM(D10:I10) -> 0
A11: 8 | J11: =SUM(D11:I11) -> 0
A12: 9 | J12: =SUM(D12:I12) -> 0
A13: 10 | J13: =SUM(D13:I13) -> 0
A14: 11 | J14: =SUM(D14:I14) -> 0
A15: 12 | J15: =SUM(D15:I15) -> 0
... A33: 30 | J33: =SUM(D33:I33) -> 0
A35: Department-Level Academic Staff FTE
A36: S.No. | B36: Department / School | C36: Faculty / College | D36: Professors | E36: Assoc. Prof | F36: Asst. Prof | G36: Lecturers | H36: Res. Fellows (Teaching) | I36: Other | J36: Total FTE | K36: University Name
A37: 1 | J37: =SUM(D37:I37) -> 0
A38: 2 | J38: =SUM(D38:I38) -> 0
A39: 3 | J39: =SUM(D39:I39) -> 0
A40: 4 | J40: =SUM(D40:I40) -> 0
A41: 5 | J41: =SUM(D41:I41) -> 0
A42: 6 | J42: =SUM(D42:I42) -> 0
A43: 7 | J43: =SUM(D43:I43) -> 0
A44: 8 | J44: =SUM(D44:I44) -> 0
A45: 9 | J45: =SUM(D45:I45) -> 0
A46: 10 | J46: =SUM(D46:I46) -> 0
A47: 11 | J47: =SUM(D47:I47) -> 0
A48: 12 | J48: =SUM(D48:I48) -> 0
... A76: 40 | J76: =SUM(D76:I76) -> 0

Sheet 3. Ratio Calculation
A1: Doctorates Awarded-to-Staff Ratio — Calculation & Scoring
A2: Ratio = Doctorates Awarded ÷ Academic Staff FTE | Higher = better | Z-scored across all universities
A3: S.No. | B3: University Name | C3: Country | D3: Doctorates Awarded (Annual) | E3: Academic Staff FTE | F3: Doctorates-per-Staff Ratio | G3: Z-Score | H3: Normalized Score (0–100) | I3: Reporting Year
A4: 1 | D4: ='1. Doctorates Awarded'!I4 -> 0 | E4: ='2. Academic Staff FTE'!J4 -> 0 | F4: =IF(E4>0,D4/E4,0) -> 0 | G4: =IFERROR((F4-AVERAGE($F$4:$F$33))/STDEV($F$4:$F$33),0) -> 0 | H4: =IFERROR(IF(MAX($F$4:$F$33)-MIN($F$4:$F$33)>0,(F4-MIN($F$4:$F$33))/(MAX($F$4:$F$33)-MIN($F$4:$F$33))*100,0),0) -> 0
A5: 2 | D5: ='1. Doctorates Awarded'!I5 -> 0 | E5: ='2. Academic Staff FTE'!J5 -> 0 | F5: =IF(E5>0,D5/E5,0) -> 0 | G5: =IFERROR((F5-AVERAGE($F$4:$F$33))/STDEV($F$4:$F$33),0) -> 0 | H5: =IFERROR(IF(MAX($F$4:$F$33)-MIN($F$4:$F$33)>0,(F5-MIN($F$4:$F$33))/(MAX($F$4:$F$33)-MIN($F$4:$F$33))*100,0),0) -> 0
A6: 3 | D6: ='1. Doctorates Awarded'!I6 -> 0 | E6: ='2. Academic Staff FTE'!J6 -> 0 | F6: =IF(E6>0,D6/E6,0) -> 0 | G6: =IFERROR((F6-AVERAGE($F$4:$F$33))/STDEV($F$4:$F$33),0) -> 0 | H6: =IFERROR(IF(MAX($F$4:$F$33)-MIN($F$4:$F$33)>0,(F6-MIN($F$4:$F$33))/(MAX($F$4:$F$33)-MIN($F$4:$F$33))*100,0),0) -> 0
A7: 4 | D7: ='1. Doctorates Awarded'!I7 -> 0 | E7: ='2. Academic Staff FTE'!J7 -> 0 | F7: =IF(E7>0,D7/E7,0) -> 0 | G7: =IFERROR((F7-AVERAGE($F$4:$F$33))/STDEV($F$4:$F$33),0) -> 0 | H7: =IFERROR(IF(MAX($F$4:$F$33)-MIN($F$4:$F$33)>0,(F7-MIN($F$4:$F$33))/(MAX($F$4:$F$33)-MIN($F$4:$F$33))*100,0),0) -> 0
A8: 5 | D8: ='1. Doctorates Awarded'!I8 -> 0 | E8: ='2. Academic Staff FTE'!J8 -> 0 | F8: =IF(E8>0,D8/E8,0) -> 0 | G8: =IFERROR((F8-AVERAGE($F$4:$F$33))/STDEV($F$4:$F$33),0) -> 0 | H8: =IFERROR(IF(MAX($F$4:$F$33)-MIN($F$4:$F$33)>0,(F8-MIN($F$4:$F$33))/(MAX($F$4:$F$33)-MIN($F$4:$F$33))*100,0),0) -> 0
A9: 6 | D9: ='1. Doctorates Awarded'!I9 -> 0 | E9: ='2. Academic Staff FTE'!J9 -> 0 | F9: =IF(E9>0,D9/E9,0) -> 0 | G9: =IFERROR((F9-AVERAGE($F$4:$F$33))/STDEV($F$4:$F$33),0) -> 0 | H9: =IFERROR(IF(MAX($F$4:$F$33)-MIN($F$4:$F$33)>0,(F9-MIN($F$4:$F$33))/(MAX($F$4:$F$33)-MIN($F$4:$F$33))*100,0),0) -> 0
A10: 7 | D10: ='1. Doctorates Awarded'!I10 -> 0 | E10: ='2. Academic Staff FTE'!J10 -> 0 | F10: =IF(E10>0,D10/E10,0) -> 0 | G10: =IFERROR((F10-AVERAGE($F$4:$F$33))/STDEV($F$4:$F$33),0) -> 0 | H10: =IFERROR(IF(MAX($F$4:$F$33)-MIN($F$4:$F$33)>0,(F10-MIN($F$4:$F$33))/(MAX($F$4:$F$33)-MIN($F$4:$F$33))*100,0),0) -> 0
A11: 8 | D11: ='1. Doctorates Awarded'!I11 -> 0 | E11: ='2. Academic Staff FTE'!J11 -> 0 | F11: =IF(E11>0,D11/E11,0) -> 0 | G11: =IFERROR((F11-AVERAGE($F$4:$F$33))/STDEV($F$4:$F$33),0) -> 0 | H11: =IFERROR(IF(MAX($F$4:$F$33)-MIN($F$4:$F$33)>0,(F11-MIN($F$4:$F$33))/(MAX($F$4:$F$33)-MIN($F$4:$F$33))*100,0),0) -> 0
A12: 9 | D12: ='1. Doctorates Awarded'!I12 -> 0 | E12: ='2. Academic Staff FTE'!J12 -> 0 | F12: =IF(E12>0,D12/E12,0) -> 0 | G12: =IFERROR((F12-AVERAGE($F$4:$F$33))/STDEV($F$4:$F$33),0) -> 0 | H12: =IFERROR(IF(MAX($F$4:$F$33)-MIN($F$4:$F$33)>0,(F12-MIN($F$4:$F$33))/(MAX($F$4:$F$33)-MIN($F$4:$F$33))*100,0),0) -> 0
A13: 10 | D13: ='1. Doctorates Awarded'!I13 -> 0 | E13: ='2. Academic Staff FTE'!J13 -> 0 | F13: =IF(E13>0,D13/E13,0) -> 0 | G13: =IFERROR((F13-AVERAGE($F$4:$F$33))/STDEV($F$4:$F$33),0) -> 0 | H13: =IFERROR(IF(MAX($F$4:$F$33)-MIN($F$4:$F$33)>0,(F13-MIN($F$4:$F$33))/(MAX($F$4:$F$33)-MIN($F$4:$F$33))*100,0),0) -> 0
A14: 11 | D14: ='1. Doctorates Awarded'!I14 -> 0 | E14: ='2. Academic Staff FTE'!J14 -> 0 | F14: =IF(E14>0,D14/E14,0) -> 0 | G14: =IFERROR((F14-AVERAGE($F$4:$F$33))/STDEV($F$4:$F$33),0) -> 0 | H14: =IFERROR(IF(MAX($F$4:$F$33)-MIN($F$4:$F$33)>0,(F14-MIN($F$4:$F$33))/(MAX($F$4:$F$33)-MIN($F$4:$F$33))*100,0),0) -> 0
A15: 12 | D15: ='1. Doctorates Awarded'!I15 -> 0 | E15: ='2. Academic Staff FTE'!J15 -> 0 | F15: =IF(E15>0,D15/E15,0) -> 0 | G15: =IFERROR((F15-AVERAGE($F$4:$F$33))/STDEV($F$4:$F$33),0) -> 0 | H15: =IFERROR(IF(MAX($F$4:$F$33)-MIN($F$4:$F$33)>0,(F15-MIN($F$4:$F$33))/(MAX($F$4:$F$33)-MIN($F$4:$F$33))*100,0),0) -> 0
... A33: 30 | D33: ='1. Doctorates Awarded'!I33 -> 0 | E33: ='2. Academic Staff FTE'!J33 -> 0 | F33: =IF(E33>0,D33/E33,0) -> 0 | G33: =IFERROR((F33-AVERAGE($F$4:$F$33))/STDEV($F$4:$F$33),0) -> 0 | H33: =IFERROR(IF(MAX($F$4:$F$33)-MIN($F$4:$F$33)>0,(F33-MIN($F$4:$F$33))/(MAX($F$4:$F$33)-MIN($F$4:$F$33))*100,0),0) -> 0
A35: Summary Statistics
A36: Average Ratio | F36: =IF(COUNTA(F4:F33)>0,AVERAGE(F4:F33),0) -> 0
A37: Highest (Best) | F37: =MAX(F4:F33) -> 0
A38: Lowest | F38: =MIN(F4:F33) -> 0
A39: Median | F39: =MEDIAN(F4:F33) -> 0
A40: Total Doctorates (All Universities) | F40: =SUM(D4:D33) -> 0

Sheet 4. Dept-Level Ratios
A1: Department-Level Doctorates-per-Staff Ratios
A2: Identifies departments with strongest/weakest doctoral productivity per faculty member
A3: S.No. | B3: Department / School | C3: Faculty / College | D3: PhD Awards (Year) | E3: Staff FTE | F3: Ratio (Awards/Staff) | G3: Target Ratio | H3: Gap to Target | I3: Priority
A4: 1 | F4: =IF(E4>0,D4/E4,0) -> 0 | H4: =IF(AND(G4>0,F4<G4),G4-F4,0) -> 0 | I4: =IF(H4>0.1,"High",IF(H4>0.05,"Medium",IF(H4>0,"Low","On Target"))) -> On Target
A5: 2 | F5: =IF(E5>0,D5/E5,0) -> 0 | H5: =IF(AND(G5>0,F5<G5),G5-F5,0) -> 0 | I5: =IF(H5>0.1,"High",IF(H5>0.05,"Medium",IF(H5>0,"Low","On Target"))) -> On Target
A6: 3 | F6: =IF(E6>0,D6/E6,0) -> 0 | H6: =IF(AND(G6>0,F6<G6),G6-F6,0) -> 0 | I6: =IF(H6>0.1,"High",IF(H6>0.05,"Medium",IF(H6>0,"Low","On Target"))) -> On Target
A7: 4 | F7: =IF(E7>0,D7/E7,0) -> 0 | H7: =IF(AND(G7>0,F7<G7),G7-F7,0) -> 0 | I7: =IF(H7>0.1,"High",IF(H7>0.05,"Medium",IF(H7>0,"Low","On Target"))) -> On Target
A8: 5 | F8: =IF(E8>0,D8/E8,0) -> 0 | H8: =IF(AND(G8>0,F8<G8),G8-F8,0) -> 0 | I8: =IF(H8>0.1,"High",IF(H8>0.05,"Medium",IF(H8>0,"Low","On Target"))) -> On Target
A9: 6 | F9: =IF(E9>0,D9/E9,0) -> 0 | H9: =IF(AND(G9>0,F9<G9),G9-F9,0) -> 0 | I9: =IF(H9>0.1,"High",IF(H9>0.05,"Medium",IF(H9>0,"Low","On Target"))) -> On Target
A10: 7 | F10: =IF(E10>0,D10/E10,0) -> 0 | H10: =IF(AND(G10>0,F10<G10),G10-F10,0) -> 0 | I10: =IF(H10>0.1,"High",IF(H10>0.05,"Medium",IF(H10>0,"Low","On Target"))) -> On Target
A11: 8 | F11: =IF(E11>0,D11/E11,0) -> 0 | H11: =IF(AND(G11>0,F11<G11),G11-F11,0) -> 0 | I11: =IF(H11>0.1,"High",IF(H11>0.05,"Medium",IF(H11>0,"Low","On Target"))) -> On Target
A12: 9 | F12: =IF(E12>0,D12/E12,0) -> 0 | H12: =IF(AND(G12>0,F12<G12),G12-F12,0) -> 0 | I12: =IF(H12>0.1,"High",IF(H12>0.05,"Medium",IF(H12>0,"Low","On Target"))) -> On Target
A13: 10 | F13: =IF(E13>0,D13/E13,0) -> 0 | H13: =IF(AND(G13>0,F13<G13),G13-F13,0) -> 0 | I13: =IF(H13>0.1,"High",IF(H13>0.05,"Medium",IF(H13>0,"Low","On Target"))) -> On Target
A14: 11 | F14: =IF(E14>0,D14/E14,0) -> 0 | H14: =IF(AND(G14>0,F14<G14),G14-F14,0) -> 0 | I14: =IF(H14>0.1,"High",IF(H14>0.05,"Medium",IF(H14>0,"Low","On Target"))) -> On Target
A15: 12 | F15: =IF(E15>0,D15/E15,0) -> 0 | H15: =IF(AND(G15>0,F15<G15),G15-F15,0) -> 0 | I15: =IF(H15>0.1,"High",IF(H15>0.05,"Medium",IF(H15>0,"Low","On Target"))) -> On Target
... A43: 40 | F43: =IF(E43>0,D43/E43,0) -> 0 | H43: =IF(AND(G43>0,F43<G43),G43-F43,0) -> 0 | I43: =IF(H43>0.1,"High",IF(H43>0.05,"Medium",IF(H43>0,"Low","On Target"))) -> On Target

Sheet 5. YoY Trend
A1: Doctorates-per-Staff Ratio — 5-Year Trend
A2: Demonstrates sustained improvement in doctoral productivity
A3: S.No. | B3: University Name | C3: Country | D3: Year 1 Ratio | E3: Year 2 | F3: Year 3 | G3: Year 4 | H3: Year 5 (Current) | I3: 5-Year Change | J3: Growth Rate (%) | K3: Trend
A4: 1 | I4: =IF(AND(D4>0,H4>0),H4-D4,0) -> 0 | J4: =IFERROR(IF(D4>0,(H4-D4)/D4*100,0),0) -> 0 | K4: =IF(I4>0.02,"Improving",IF(I4>0,"Stable",IF(I4<-0.02,"Worsening","Flat"))) -> Flat
A5: 2 | I5: =IF(AND(D5>0,H5>0),H5-D5,0) -> 0 | J5: =IFERROR(IF(D5>0,(H5-D5)/D5*100,0),0) -> 0 | K5: =IF(I5>0.02,"Improving",IF(I5>0,"Stable",IF(I5<-0.02,"Worsening","Flat"))) -> Flat
A6: 3 | I6: =IF(AND(D6>0,H6>0),H6-D6,0) -> 0 | J6: =IFERROR(IF(D6>0,(H6-D6)/D6*100,0),0) -> 0 | K6: =IF(I6>0.02,"Improving",IF(I6>0,"Stable",IF(I6<-0.02,"Worsening","Flat"))) -> Flat
A7: 4 | I7: =IF(AND(D7>0,H7>0),H7-D7,0) -> 0 | J7: =IFERROR(IF(D7>0,(H7-D7)/D7*100,0),0) -> 0 | K7: =IF(I7>0.02,"Improving",IF(I7>0,"Stable",IF(I7<-0.02,"Worsening","Flat"))) -> Flat
A8: 5 | I8: =IF(AND(D8>0,H8>0),H8-D8,0) -> 0 | J8: =IFERROR(IF(D8>0,(H8-D8)/D8*100,0),0) -> 0 | K8: =IF(I8>0.02,"Improving",IF(I8>0,"Stable",IF(I8<-0.02,"Worsening","Flat"))) -> Flat
A9: 6 | I9: =IF(AND(D9>0,H9>0),H9-D9,0) -> 0 | J9: =IFERROR(IF(D9>0,(H9-D9)/D9*100,0),0) -> 0 | K9: =IF(I9>0.02,"Improving",IF(I9>0,"Stable",IF(I9<-0.02,"Worsening","Flat"))) -> Flat
A10: 7 | I10: =IF(AND(D10>0,H10>0),H10-D10,0) -> 0 | J10: =IFERROR(IF(D10>0,(H10-D10)/D10*100,0),0) -> 0 | K10: =IF(I10>0.02,"Improving",IF(I10>0,"Stable",IF(I10<-0.02,"Worsening","Flat"))) -> Flat
A11: 8 | I11: =IF(AND(D11>0,H11>0),H11-D11,0) -> 0 | J11: =IFERROR(IF(D11>0,(H11-D11)/D11*100,0),0) -> 0 | K11: =IF(I11>0.02,"Improving",IF(I11>0,"Stable",IF(I11<-0.02,"Worsening","Flat"))) -> Flat
A12: 9 | I12: =IF(AND(D12>0,H12>0),H12-D12,0) -> 0 | J12: =IFERROR(IF(D12>0,(H12-D12)/D12*100,0),0) -> 0 | K12: =IF(I12>0.02,"Improving",IF(I12>0,"Stable",IF(I12<-0.02,"Worsening","Flat"))) -> Flat
A13: 10 | I13: =IF(AND(D13>0,H13>0),H13-D13,0) -> 0 | J13: =IFERROR(IF(D13>0,(H13-D13)/D13*100,0),0) -> 0 | K13: =IF(I13>0.02,"Improving",IF(I13>0,"Stable",IF(I13<-0.02,"Worsening","Flat"))) -> Flat
A14: 11 | I14: =IF(AND(D14>0,H14>0),H14-D14,0) -> 0 | J14: =IFERROR(IF(D14>0,(H14-D14)/D14*100,0),0) -> 0 | K14: =IF(I14>0.02,"Improving",IF(I14>0,"Stable",IF(I14<-0.02,"Worsening","Flat"))) -> Flat
A15: 12 | I15: =IF(AND(D15>0,H15>0),H15-D15,0) -> 0 | J15: =IFERROR(IF(D15>0,(H15-D15)/D15*100,0),0) -> 0 | K15: =IF(I15>0.02,"Improving",IF(I15>0,"Stable",IF(I15<-0.02,"Worsening","Flat"))) -> Flat
... A33: 30 | I33: =IF(AND(D33>0,H33>0),H33-D33,0) -> 0 | J33: =IFERROR(IF(D33>0,(H33-D33)/D33*100,0),0) -> 0 | K33: =IF(I33>0.02,"Improving",IF(I33>0,"Stable",IF(I33<-0.02,"Worsening","Flat"))) -> Flat

Sheet 6. PhD Pipeline
A1: PhD Completion Pipeline — From Enrolment to Award
A2: Tracks pipeline: currently enrolled → expected completions → actual awards | Identifies bottlenecks
A3: S.No. | B3: University Name | C3: Country | D3: PhD Currently Enrolled (FTE) | E3: Expected Completions (Next 1yr) | F3: Expected Completions (Next 2yr) | G3: Actual Awards (Current Year) | H3: Completion Rate (%) | I3: Avg Time-to-Completion (Months) | J3: Reporting Year
A4: 1 | H4: =IF(D4>0,G4/D4*100,0) -> 0
A5: 2 | H5: =IF(D5>0,G5/D5*100,0) -> 0
A6: 3 | H6: =IF(D6>0,G6/D6*100,0) -> 0
A7: 4 | H7: =IF(D7>0,G7/D7*100,0) -> 0
A8: 5 | H8: =IF(D8>0,G8/D8*100,0) -> 0
A9: 6 | H9: =IF(D9>0,G9/D9*100,0) -> 0
A10: 7 | H10: =IF(D10>0,G10/D10*100,0) -> 0
A11: 8 | H11: =IF(D11>0,G11/D11*100,0) -> 0
A12: 9 | H12: =IF(D12>0,G12/D12*100,0) -> 0
A13: 10 | H13: =IF(D13>0,G13/D13*100,0) -> 0
A14: 11 | H14: =IF(D14>0,G14/D14*100,0) -> 0
A15: 12 | H15: =IF(D15>0,G15/D15*100,0) -> 0
... A33: 30 | H33: =IF(D33>0,G33/D33*100,0) -> 0
A35: PhD Completion Bottleneck Analysis
A36: S.No. | B36: Bottleneck / Risk Factor | C36: Severity (High/Med/Low) | D36: Departments Most Affected | E36: Root Cause | F36: Mitigation Action | G36: Status (Addressed/IP/Open) | H36: Timeline | I36: Owner | J36: University
A37: 1 | B37: Insufficient supervisor availability (high student:supervisor ratio)
A38: 2 | B38: Weak research infrastructure delaying experiments / data collection
A39: 3 | B39: Funding gaps — students taking longer due to lack of stipends
A40: 4 | B40: Poor progress monitoring — students drifting without milestones
A41: 5 | B41: External employment — part-time PhD students prioritizing jobs
A42: 6 | B42: Thesis examination delays — external examiner scheduling
A43: 7 | B43: Ethics approval delays for research involving human subjects / animals
A44: 8 | B44: Publication requirement delays — journal review timelines
A45: 9 | B45: Inadequate writing / methodological skills among candidates
A46: 10 | B46: Supervisor relocation / retirement during candidature

Sheet 7. Action Plan
A1: Doctoral Productivity Improvement — Strategic Action Plan
A2: 3-Year Roadmap actions to increase doctorates awarded per staff | Phase 1 → Phase 3
A3: # | B3: University Name | C3: Action Item | D3: Phase | E3: Status | F3: Target Date | G3: Remarks
A4: 1 | C4: Audit current PhD pipeline: enrolled, expected completions, bottlenecks | D4: 1 (0–6mo)
A5: 2 | C5: Implement structured doctoral programmes with annual milestone reviews | D5: 1 (0–6mo)
A6: 3 | C6: Provide seed funding for PhD stipends, lab consumables, conference travel | D6: 1 (0–6mo)
A7: 4 | C7: Train supervisors on effective PhD supervision and timely completion | D7: 1 (0–6mo)
A8: 5 | C8: Establish doctoral review boards for annual progress assessment | D8: 1 (0–6mo)
A9: 6 | C9: Set up Centres of Excellence attracting high-quality PhD candidates | D9: 2 (6–18mo)
A10: 7 | C10: Partner with industry for co-funded PhD studentships | D10: 2 (6–18mo)
A11: 8 | C11: Recruit postdoctoral fellows to assist with PhD supervision | D11: 2 (6–18mo)
A12: 9 | C12: Reduce average time-to-completion by 6–12 months through structured support | D12: 2 (6–18mo)
A13: 10 | C13: Establish writing workshops and methodological skills bootcamps for PhD students | D13: 2 (6–18mo)
A14: 11 | C14: Streamline thesis examination process (panel of approved examiners, timeline targets) | D14: 2 (6–18mo)
A15: 12 | C15: Launch international collaborative PhD programmes | D15: 2 (6–18mo)
... A19: 16 | C19: Embed doctoral productivity targets in departmental KPIs | D19: 3 (18–36mo)
A21: Progress Summary
A22: Actions Completed | D22: =COUNTIF(E4:E19,"Done") -> 0
A23: In Progress | D23: =COUNTIF(E4:E19,"IP") -> 0
A24: Completion Rate (%) | D24: =IFERROR(COUNTIF(E4:E19,"Done")/16*100,0) -> 0

Sheet 8. Benchmarking
A1: Benchmarking — Doctorates Awarded per Staff
A3: S.No. | B3: University / Benchmark | C3: Doctorates Awarded | D3: Staff FTE | E3: Ratio | F3: Score (0–100) | G3: Peer Group
A4: 1 | B4: Your Institution | G4: Target
A5: 2 | B5: Global Top 10 Average | G5: Aspirational
A6: 3 | B6: National Average | G6: National
A7: 4 | B7: Peer Group Average | G7: Peer
A8: 5 | B8: Research-Intensive Benchmark | G8: ~0.4–0.8 ratio
A9: 1
A10: 2
A11: 3
A12: 4
A13: 5
A14: 6
A15: 7
A16: 8
A17: 9
A18: 10
A19: 11
A20: 12
... A23: 15

Sheet 9. Risk Assessment
A1: Doctorates-per-Staff — Risk Assessment & Mitigation
A3: # | B3: Risk | C3: Level | D3: Impact | E3: Mitigation | F3: Owner
A4: 1 | B4: Low PhD completion rates | C4: 🟡 Medium | D4: Fewer awards despite enrolment; ratio stagnates | E4: Structured programmes, milestone reviews, stipends, supervisor training
A5: 2 | B5: High PhD attrition / dropout | C5: 🟡 Medium | D5: Enrolled students leave before completion | E5: Financial support, mentoring, wellness, progress tracking
A6: 3 | B6: Long time-to-completion (>5 years) | C6: 🟡 Medium | D6: Awards delayed; ratio lower than potential | E6: Structured timeline, writing support, examiner panel pre-approval
A7: 4 | B7: Insufficient supervisors for PhD load | C7: 🟡 Medium | D7: Supervision bottleneck limits completions | E7: Recruit faculty with PhD supervision experience; postdoc support
A8: 5 | B8: Counting honorary doctorates | C8: 🔴 High | D8: Inflated numerator; audit penalty | E8: Strictly count only earned research doctorates; separate honorary register
A9: 6 | B9: Counting MPhil / MRes as doctoral | C9: 🔴 High | D9: Inflated numerator; non-compliant | E9: Only PhD and equivalent research doctorates; verify degree classification
A10: 7 | B10: Staff FTE inconsistency with SSR | C10: 🔴 High | D10: Different staff FTE used across indicators; audit flag | E10: Use SAME Academic Staff FTE for both SSR (4.5%) and this ratio (5.5%)
A11: 8 | B11: Budget constraints for PhD support | C11: 🟡 Medium | D11: Cannot offer stipends/travel; low intake | E11: Government fellowships, industry co-funded PhDs, CSR, phased investment

Sheet 10. Data Quality Audit
A1: Doctorates Awarded per Staff — Data Quality & Audit Checklist
A2: Validation checks for this indicator (5.5% of total WUR score)
A3: # | B3: Quality Check | C3: Description | D3: Status (✓/✗/IP) | E3: Date | F3: Reviewer
A4: 1 | B4: Doctorate definition | C4: Only earned research doctorates counted: PhD, professional doctorates (thesis-based). Honorary doctorates excluded
A5: 2 | B5: Professional doctorate verification | C5: EdD/DBA/MD-PhD included only if programme involves original research thesis/dissertation
A6: 3 | B6: MPhil / MRes exclusion | C6: MPhil and MRes degrees NOT counted as doctorates unless formally classified as doctoral by the awarding body
A7: 4 | B7: Award vs enrolment distinction | C7: Count is degrees CONFERRED (awarded), not students currently enrolled in PhD programmes
A8: 5 | B8: Reporting year consistency | C8: Award count covers the same academic year as other indicators in the submission
A9: 6 | B9: 3-year average option | C9: If THE allows 3-year average (check cycle guidelines), method documented and consistently applied
A10: 7 | B10: Academic Staff FTE consistency | C10: SAME Academic Staff FTE used for this ratio AND Staff-to-Student Ratio (4.5%); values must match exactly
A11: 8 | B11: Staff FTE THE-compliant | C11: FTE follows THE definition: teaching academics only; research-only, admin, technical excluded
A12: 9 | B12: Registrar data cross-reference | C12: Doctorate awards verified against official graduation records / gazette notifications
A13: 10 | B13: Department-level reconciliation | C13: Sum of department-level awards equals university-level total
A14: 11 | B14: 5-year trend plausibility | C14: Year-on-year changes reviewed; anomalous jumps (>30%) documented with explanation
A15: 12 | B15: Pipeline consistency check | C15: Awards ≤ enrolled PhD students (cannot award more than are enrolled)
... A23: 20 | B23: Reproducibility test | C23: Ratio independently reproducible from registrar + HR records within ±2%
